Workbook

Sheet 안내
A1: TRACE 사업비 원인추적기 v0.5 (프로토타입)
A2: Excel 2016 호환 · 계산은 수식, 자동화는 VBA(modTrace.bas) · 예시 데이터는 가상 수치 (원본 단위: 원, 보고 단위: 백만원)
A4: 이름의 뜻
A5: 글자 | B5: 뜻 | C5: 도구에서 하는 일 (시트)
A6: T | B6: Trend 추이 | C6: 전월·전분기·전년동월 대비 변동 (변동분석 · 월별집계 · 계정변동)
A7: R | B7: Risk 예산 위험 | C7: 부서 × 계정 × 분기 한도 점검(변동분석 AJ~AO열)과 연간 전망(P~Y열)
A8: A | B8: Anomaly 이상치 | C8: 평소 변동폭을 벗어난 항목을 점수로 골라냄 (주의대상)
A9: C | B9: Cause 원인 | C9: 증가분을 거래처·전표로 쪼개 원인 후보와 근거 전표 제시 (원인분석 · 키워드사전)
A10: E | B10: Expense 사업비 | C10: 분석 대상: 사업비 계정 (계정매핑에서 사업비 여부 Y)
A12: 흐름 단계와 시트
A13: 단계 | B13: 하는 일 | C13: 시트
A14: ① 자료 넣기 | B14: SAP 예산판·TB·전표·BS·PL을 원본 시트 A열부터 붙여넣기 | C14: 예산판_원본 · TB_원본 · 전표_원본 · BS_원본 · PL_원본
A15: ② 불러오기·대사 | B15: 매핑 적용, 전표 = TB = 예산판 실적 대사, 데이터 점검 | C15: 자가진단 · 계정변동
A16: ③ 변동 분석 | B16: 전월·전분기·전년동월 대비 증감 (부서 × 계정) | C16: 변동분석 F~O열 · 월별집계 · 계정변동
A17: ④ 예산 점검 | B17: 분기 한도(배정+조정) 대비 분기 실적·분기말 예상 → 여유/주의/초과 예상/한도 초과, 연간 전망은 참고 | C17: 변동분석 AJ~AO열 · P~Y열
A18: ⑤ 주의 대상 | B18: 증가액·증가율·이상치·예산 점수 합산 → TOP 10 | C18: 주의대상 · 변동분석 AA열 이후
A19: ⑥ 원인 추정 | B19: 선택 항목을 거래처·전표로 분해, 8가지 패턴 판정, 근거 전표 | C19: 원인분석 · 키워드사전
A20: ⑦ 보고·확인 | B20: 보고서·대시보드, 확인된 원인을 코멘트로 누적 | C20: 리포트 · 대시보드 · 차트데이터 · 코멘트 · TRACE_대시보드.html
A21: ⑧ IFRS 17 연결 | B21: 계정대체(직접대체 → 재산관리비 → 부서별 비율) → 상품·포트폴리오 → 예정 대비 경험차이 → CSM(GMM)·당기손익, 계리 변동표와 대사 | C21: IFRS17_사업비 · 계정대체기준 · 계정매핑 · 예정사업비 · 부채변동표
A23: 매월 사용 순서
A24: 1. 설정 시트에서 기준연도·기준월 변경
A25: 2. [예산판·TB·전표·BS·PL 불러오기] 버튼으로 SAP에서 내려받은 파일 선택 (매크로 없이: 원본 시트 A열부터 붙여넣고 보조수식 끌어 채우기)
A26: 3. 자가진단이 '전체 정상'인지 확인
A27: 4. 주의대상 TOP 10 확인 → 원인분석 시트 C5에 순위 입력 (비교 기준은 C6) → 원인 후보와 근거 전표 확인
A28: 5. 담당 부서 확인 결과를 코멘트 시트에 입력 → 주의대상·리포트에 표시
A29: 6. 새로 알게 된 적요 표현은 키워드사전에 추가 → 다음 달 원인 추정에 반영
A30: 7. [예정사업비·부채변동표 불러오기] (분기·월 결산 후) → IFRS17_사업비 시트에서 CSM·손익 영향과 근거 전표 확인
A31: 8. [대시보드 내보내기] 버튼 → 같은 폴더에 data.js 생성 → TRACE_대시보드.html을 열면 최신 결과 표시
A33: 매크로 설치 (1회)
A34: 1. Alt+F11 → [파일] → [파일 가져오기] → modTrace.bas
A35: 2. Alt+F8 → SetupButtons 실행 → 설정 시트 오른쪽에 버튼 10개 생성
... A66: 포트폴리오: GMM(보장성·저축성)과 VFA(변액)는 신계약비 차이가 CSM을 조정하고 유지·수금비 차이는 당기손익, PAA(단체)는 손익 영향만 봅니다. 변액은 특별계정 구분계리 대상이지만 손익에 영향을 주므로 분석에 포함합니다.

Sheet 설정
A1: TRACE · 설정
A2: 노란 칸만 바꾸세요
B4: 항목 | C4: 값 | D4: 설명 | F4: 단위 | G4: 원 환산
B5: 회사명 | C5: 예시보험㈜ | F5: 원 | G5: 1
B6: 기준연도 | C6: 2026 | F6: 천원 | G6: 1000
B7: 기준월 | C7: 9 | D7: 1~12 | F7: 백만원 | G7: 1000000
B8: 원본 금액단위 | C8: 원 | D8: 예산판·TB·전표 공통
B9: 보고 단위 | C9: 백만원 | D9: 모든 분석 표시 단위
B10: 증감 기준금액 (보고단위) | C10: 10 | D10: 이 금액 미만의 작은 증감은 주의 점수를 30%로 낮춤 · 증가액 점수 만점 = 5배
B11: 예산 '주의' 기준 (예상 소진율) | C11: 0.9 | D11: 예상 연간 실적 ÷ 가용예산이 이 값 초과면 주의
B12: 예산 '부족 예상' 기준 | C12: 1 | D12: 이 값 초과면 부족 예상
B13: 이상치 기준 (z) | C13: 2 | D13: 직전 12개월 평균 대비 표준편차 배수
B14: 원인: 단건 비중 | C14: 0.5 | D14: 전표 1건이 증가분의 이 비율 이상이고, 그 거래처 평소 월평균의 3배 이상이면 '일회성 대형' (내부 거래처 제외)
B15: 원인: 신규 거래처 비중 | C15: 0.3 | D15: 최근 12개월 거래 없던 거래처의 증가분 비중
B16: 원인: SA 대체 비중 | C16: 0.3 | D16: 수기 대체전표(SA) 순증의 증가분 비중
B17: 원인: 키워드 비중 | C17: 0.3 | D17: 키워드사전 해당 전표의 증가분 비중
B18: 원인: 단가 상승률 | C18: 0.05 | D18: 같은 건수에서 이 비율 이상, 50% 이하로 오르면 '단가 인상'
B19: 고갈 추세 기울기 | C19: 연내누적 | D19: 연내누적(연초~기준월 누계에 맞춘 직선) / 최근월(당월 사용액) / 최근분기(최근 3개월 평균) / 전년추세(작년 같은 남은 기간의 월평균)
B20: (계산) 기준 기간번호 | C20: =C6*12+C7 | D20: 연도×12+월. 기간 비교에 사용
B21: (계산) 기준 분기 | C21: =ROUNDUP(C7/3,0)
B22: (계산) 분기 시작 기간번호 | C22: =C6*12+(C21-1)*3+1
B23: (계산) 금액 환산계수 | C23: =INDEX($G$5:$G$7,MATCH(C8,$F$5:$F$7,0))/INDEX($G$5:$G$7,MATCH(C9,$F$5:$F$7,0)) | D23: 원본 금액 × 계수 = 보고단위

Sheet 헤더설정
A1: TRACE · 헤더설정 (불러오기가 찾는 열 이름)
A2: 노란 칸만 고치세요 · SAP 화면에서 내려받은 파일의 머리글과 똑같이 적으면 그 열을 찾아 표준 위치에 넣습니다
B3: 찾는 순서: ① '찾을 헤더 이름' → ② '대체 이름'(쉼표로 여러 개) 중 먼저 맞는 열. 띄어쓰기·대소문자·줄바꿈은 무시합니다.
B4: 필수 열을 찾지 못하면 불러오기를 멈추고 어떤 열이 없는지 알려줍니다. 선택 열은 없으면 빈칸으로 두고 '없을 때'에 적힌 기능만 빠집니다.
B5: 수식은 표준 열 기준이라 이 표를 고쳐도 다른 시트는 건드릴 필요가 없습니다.
B7: 예산판_원본 (빈 행 판정 열: 부서코드)
B8: 표준 열 (원본 시트) | C8: 찾을 헤더 이름 | D8: 대체 이름 (쉼표로 구분) | E8: 필수 | F8: 없을 때
B9: A열 회계연도 | C9: 회계연도 | D9: 연도,년도,GJAHR | E9: 필수
B10: B열 부서코드 | C10: 부서코드 | D10: 부서,팀코드,조직코드 | E10: 필수
B11: C열 부서명 | C11: 부서명 | D11: 팀명,조직명 | E11: 선택 | F11: 부서매핑의 부서명 사용
B12: D열 G/L계정 | C12: G/L계정 | D12: 계정,계정코드,예산계정,G/L,RACCT,HKONT | E12: 필수
B13: E열 계정명 | C13: 계정명 | D13: 계정과목명,TXT50 | E13: 선택 | F13: 계정매핑의 계정명 사용
B14: F열 분기 | C14: 분기 | D14: 분기구분,QTR | E14: 필수 | F14: 1~4, Q1, 1분기 모두 가능
B15: G열 배정 | C15: 배정 | D15: 배정액,배정예산,예산 | E15: 필수
B16: H열 조정 | C16: 조정 | D16: 조정액,전용 | E16: 선택 | F16: 0으로 처리
B17: I열 실적 | C17: 실적 | D17: 집행,집행액,실적액 | E17: 선택 | F17: 예산판↔전표 대사 불가
B18: J열 잔여 | C18: 잔여 | D18: 잔액,잔여예산 | E18: 선택 | F18: 참고용
B21: TB_원본 (빈 행 판정 열: G/L계정)
B22: 표준 열 (원본 시트) | C22: 찾을 헤더 이름 | D22: 대체 이름 (쉼표로 구분) | E22: 필수 | F22: 없을 때
B23: A열 회계연도 | C23: 회계연도 | D23: 연도,GJAHR,RYEAR | E23: 필수
B24: B열 기간 | C24: 기간 | D24: 월,회계기간,POPER | E24: 필수 | F24: 1~12 또는 001~012
B25: C열 G/L계정 | C25: G/L계정 | D25: 계정,계정코드,G/L,RACCT | E25: 필수
B26: D열 계정명 | C26: 계정명 | D26: 계정과목명,TXT50 | E26: 선택
B27: E열 당기차변 | C27: 당기차변 | D27: 차변,당월차변,차변금액 | E27: 필수
B28: F열 당기대변 | C28: 당기대변 | D28: 대변,당월대변,대변금액 | E28: 필수
B29: G열 기말잔액 | C29: 기말잔액 | D29: 잔액,기말 | E29: 선택 | F29: 참고용
B32: 전표_원본 (빈 행 판정 열: G/L계정)
B33: 표준 열 (원본 시트) | C33: 찾을 헤더 이름 | D33: 대체 이름 (쉼표로 구분) | E33: 필수 | F33: 없을 때
B34: A열 회계연도 | C34: 회계연도 | D34: 연도,GJAHR | E34: 필수
B35: B열 기간 | C35: 기간 | D35: 월,회계기간,POPER | E35: 필수
B36: C열 전표번호 | C36: 전표번호 | D36: BELNR,문서번호 | E36: 선택 | F36: 근거 전표에 번호 없이 표시
B37: D열 전기일 | C37: 전기일 | D37: 전기일자,일자,BUDAT | E37: 선택
B38: E열 전표유형 | C38: 전표유형 | D38: 문서유형,BLART | E38: 선택 | F38: '재분류' 패턴 판정 불가
B39: F열 G/L계정 | C39: G/L계정 | D39: 계정,계정코드,HKONT,RACCT | E39: 필수
B40: G열 코스트센터 | C40: 코스트센터 | D40: 비용센터,KOSTL,CC | E40: 필수
B41: H열 금액 | C41: 금액 | D41: 금액(원),현지통화금액,DMBTR,HSL | E41: 필수 | F41: 차대구분 방식이면 양수 금액
B42: I열 적요 | C42: 적요 | D42: 텍스트,내역,SGTXT | E42: 선택 | F42: '적요 키워드' 패턴 판정 불가
B43: J열 거래처코드 | C43: 거래처코드 | D43: 거래처,공급업체,LIFNR | E43: 선택
B44: K열 거래처명 | C44: 거래처명 | D44: 거래처명칭,공급업체명,NAME1 | E44: 선택 | F44: 거래처코드로 대신 표시 (둘 다 없으면 거래처 분석 불가)
B47: BS_원본 (빈 행 판정 열: 항목코드)
...

Sheet 입력옵션
A1: TRACE · 입력옵션
A2: 노란 칸만 고치세요 · 불러오기 규칙과 BS·PL 항목 매핑
A4: 불러오기 규칙
B5: 제외할 행 키워드 | C5: 합계,소계,총계,Total | D5: 빈 행 판정 열에 이 단어가 있으면 불러오지 않음 (쉼표로 구분)
B6: 머리글 찾는 범위 (행) | C6: 20 | D6: 파일 위쪽 이 행 수 안에서 헤더 이름이 가장 많이 맞는 행을 머리글로 사용
B8: 전표 금액 방식 | C8: 부호 있는 금액 | D8: '부호 있는 금액' 또는 '차대구분+양수금액' (SAP 차대구분 S/H)
B9: 차대구분 헤더 이름 | C9: 차대구분 | D9: 차대구분+양수금액 방식일 때 찾을 열 이름 (예: SHKZG)
B10: 차변 표시 값 | C10: S
B11: 대변 표시 값 | C11: H | D11: 이 값인 행은 금액에 −를 붙여 불러옴
B13: BS·PL 양식 형태 | C13: 세로 (기간×항목) | D13: '감독원 (가로)'이면 항목이 행, 금액이 열인 양식을 기준월 한 달씩 불러와 기존 자료에 합침
B14: 가로: 당기 금액 헤더 | C14: 당기 | D14: BS 기말잔액 · PL 당월 금액 열 이름 (쉼표로 대체 이름)
B15: 가로: 전기 금액 헤더 | C15: 전기 | D15: BS 비교 열 (없으면 비워둠)
B16: 가로: PL 누계 헤더 | C16: 당기누계 | D16: PL 누계 금액 열
B17: 가로: 전기 열의 기간 | C17: 전년말 | D17: '전년말'(전년 12월) 또는 '전년동월'
A20: BS·PL 항목 매핑 — 회사 재무제표의 항목코드(없으면 항목명)를 표준 코드에 연결. 차트·KPI·검산은 표준 코드만 사용
B21: 구분 | C21: 표준 코드 | D21: 표준 항목명 | E21: 실제 항목코드 | F21: 실제 항목명
B22: BS | C22: A000 | D22: 자산총계 | E22: 10000 | F22: 자산총계
B23: BS | C23: A100 | D23: 운용자산 | E23: 11000 | F23: 운용자산
B24: BS | C24: A110 | D24: 현금및예치금 | E24: 11100 | F24: 현금및예치금
B25: BS | C25: A120 | D25: 유가증권 | E25: 11200 | F25: 유가증권
B26: BS | C26: A130 | D26: 대출채권 | E26: 11300 | F26: 대출채권
B27: BS | C27: A140 | D27: 투자부동산 | E27: 11400 | F27: 투자부동산
B28: BS | C28: A200 | D28: 보험계약자산 | E28: 12000 | F28: 보험계약자산
B29: BS | C29: A300 | D29: 재보험계약자산 | E29: 13000 | F29: 재보험계약자산
B30: BS | C30: A900 | D30: 기타자산 | E30: 19000 | F30: 기타자산
B31: BS | C31: L000 | D31: 부채총계 | E31: 20000 | F31: 부채총계
B32: BS | C32: L100 | D32: 보험계약부채 | E32: 21000 | F32: 보험계약부채
... B53: PL | C53: P600 | D53: 당기순이익 | E53: 90000 | F53: 당기순이익
A56: 부채변동표 변동요인 매핑 — 감독원 양식의 요인코드(없으면 요인명)를 TRACE 요인코드에 연결
B57: 구분 | C57: TRACE 요인코드 | D57: TRACE 요인명 | E57: 실제 요인코드 | F57: 실제 요인명
B58: 변동표 | C58: F00 | D58: 기초잔액 | E58: B00 | F58: 기초
B59: 변동표 | C59: F10 | D59: 신계약 효과 | E59: B10 | F59: 신계약
B60: 변동표 | C60: F21 | D60: 가정변경-사업비 | E60: B21 | F60: 추정변경(사업비)
B61: 변동표 | C61: F22 | D61: 가정변경-기타 | E61: B22 | F61: 추정변경(기타)
B62: 변동표 | C62: F31 | D62: 경험조정-취득현금흐름 | E62: B31 | F62: 경험조정(보험취득현금흐름)
B63: 변동표 | C63: F32 | D63: 경험조정-보험료 등 | E63: B32 | F63: 경험조정(기타)
B64: 변동표 | C64: F40 | D64: 보험금융비용(이자부리) | E64: B40 | F64: 보험금융비용
B65: 변동표 | C65: F51 | D65: CSM 상각 | E65: B51 | F65: 보험계약마진 상각
B66: 변동표 | C66: F52 | D66: RA 해제 | E66: B52 | F66: 위험조정 변동(당기)
B67: 변동표 | C67: F60 | D67: 현금흐름 및 기타 | E67: B60 | F67: 현금흐름 및 기타
...

Sheet 자가진단
A1: TRACE · 자가진단
A2: 외부망으로 오류를 알릴 때는 [점검 항목]과 [상태]만 전달하세요
A4: 종합 | B4: =IF(COUNTIF(D7:D39,"확인필요")=0,"전체 정상"&IF(COUNTIF(D7:D39,"참고")>0," (참고 "&COUNTIF(D7:D39,"참고")&"건)",""),"확인필요 "&COUNTIF(D7:D39,"확인필요")&"건")
A6: No | B6: 점검 항목 | C6: 결과 | D6: 상태 | E6: 조치 방법
A7: 1 | B7: 설정값 | C7: =IF(AND(ISNUMBER(설정!$C$7),설정!$C$7>=1,설정!$C$7<=12,ISNUMBER(설정!$C$23)),"정상","기준월 또는 단위 오류") | D7: =IF(C7="정상","OK","확인필요") | E7: 설정 시트 기준월(1~12)·단위 확인
A8: 2 | B8: 전표_원본 머리글 | C8: =IF(IF(전표_원본!A4<>"회계연도","A ","")&IF(전표_원본!B4<>"기간","B ","")&IF(전표_원본!C4<>"전표번호","C ","")&IF(전표_원본!D4<>"전기일","D ","")&IF(전표_원본!E4<>"전표유형","E ","")&IF(전표_원본!F4<>"G/L계정","F ","")&IF(전표_원본!G4<>"코스트센터","G ","")&IF(전표_원본!H4<>"금액","H ","")&IF(전표_원본!I4<>"적요","I ","")&IF(전표_원본!J4<>"거래처코드","J ","")&IF(전표_원본!K4<>"거래처명","K ","")="","일치","불일치 열: "&IF(전표_원본!A4<>"회계연도","A ","")&IF(전표_원본!B4<>"기간","B ","")&IF(전표_원본!C4<>"전표번호","C ","")&IF(전표_원본!D4<>"전기일","D ","")&IF(전표_원본!E4<>"전표유형","E ","")&IF(전표_원본!F4<>"G/L계정","F ","")&IF(전표_원본!G4<>"코스트센터","G ","")&IF(전표_원본!H4<>"금액","H ","")&IF(전표_원본!I4<>"적요","I ","")&IF(전표_원본!J4<>"거래처코드","J ","")&IF(전표_원본!K4<>"거래처명","K ","")) | D8: =IF(C8="일치","OK","확인필요") | E8: 4행 머리글을 표준 이름으로
A9: 3 | B9: TB_원본 머리글 | C9: =IF(IF(TB_원본!A4<>"회계연도","A ","")&IF(TB_원본!B4<>"기간","B ","")&IF(TB_원본!C4<>"G/L계정","C ","")&IF(TB_원본!D4<>"계정명","D ","")&IF(TB_원본!E4<>"당기차변","E ","")&IF(TB_원본!F4<>"당기대변","F ","")&IF(TB_원본!G4<>"기말잔액","G ","")="","일치","불일치 열: "&IF(TB_원본!A4<>"회계연도","A ","")&IF(TB_원본!B4<>"기간","B ","")&IF(TB_원본!C4<>"G/L계정","C ","")&IF(TB_원본!D4<>"계정명","D ","")&IF(TB_원본!E4<>"당기차변","E ","")&IF(TB_원본!F4<>"당기대변","F ","")&IF(TB_원본!G4<>"기말잔액","G ","")) | D9: =IF(C9="일치","OK","확인필요") | E9: 4행 머리글을 표준 이름으로
A10: 4 | B10: 예산판_원본 머리글 | C10: =IF(IF(예산판_원본!A4<>"회계연도","A ","")&IF(예산판_원본!B4<>"부서코드","B ","")&IF(예산판_원본!C4<>"부서명","C ","")&IF(예산판_원본!D4<>"G/L계정","D ","")&IF(예산판_원본!E4<>"계정명","E ","")&IF(예산판_원본!F4<>"분기","F ","")&IF(예산판_원본!G4<>"배정","G ","")&IF(예산판_원본!H4<>"조정","H ","")&IF(예산판_원본!I4<>"실적","I ","")&IF(예산판_원본!J4<>"잔여","J ","")="","일치","불일치 열: "&IF(예산판_원본!A4<>"회계연도","A ","")&IF(예산판_원본!B4<>"부서코드","B ","")&IF(예산판_원본!C4<>"부서명","C ","")&IF(예산판_원본!D4<>"G/L계정","D ","")&IF(예산판_원본!E4<>"계정명","E ","")&IF(예산판_원본!F4<>"분기","F ","")&IF(예산판_원본!G4<>"배정","G ","")&IF(예산판_원본!H4<>"조정","H ","")&IF(예산판_원본!I4<>"실적","I ","")&IF(예산판_원본!J4<>"잔여","J ","")) | D10: =IF(C10="일치","OK","확인필요") | E10: 4행 머리글을 표준 이름으로
A11: 5 | B11: 전표 보조수식 범위 | C11: =COUNTA(전표_원본!A5:A100000)&"행 / 보조 "&COUNTA(전표_원본!O5:O100000)&"행" | D11: =IF(COUNTA(전표_원본!O5:O100000)>=COUNTA(전표_원본!A5:A100000),"OK","확인필요") | E11: M~X열을 데이터 마지막 행까지 채우기
A12: 6 | B12: TB 보조수식 범위 | C12: =COUNTA(TB_원본!A5:A20000)&"행 / 보조 "&COUNTA(TB_원본!I5:I20000)&"행" | D12: =IF(COUNTA(TB_원본!I5:I20000)>=COUNTA(TB_원본!A5:A20000),"OK","확인필요") | E12: I~K열을 데이터 마지막 행까지 채우기
A13: 7 | B13: 예산판 보조수식 범위 | C13: =COUNTA(예산판_원본!A5:A5000)&"행 / 보조 "&COUNTA(예산판_원본!L5:L5000)&"행" | D13: =IF(COUNTA(예산판_원본!L5:L5000)>=COUNTA(예산판_원본!A5:A5000),"OK","확인필요") | E13: L~R열을 데이터 마지막 행까지 채우기
A14: 8 | B14: 기준월 전표 존재 | C14: =COUNTIF(전표_원본!$M$5:$M$100000,설정!$C$20)&"건" | D14: =IF(COUNTIF(전표_원본!$M$5:$M$100000,설정!$C$20)>0,"OK","확인필요") | E14: 기준월 전표가 들어 있는지 확인
A15: 9 | B15: 기준월 TB 존재 | C15: =COUNTIF(TB_원본!$I$5:$I$20000,설정!$C$20)&"행" | D15: =IF(COUNTIF(TB_원본!$I$5:$I$20000,설정!$C$20)>0,"OK","확인필요") | E15: 기준월 TB가 들어 있는지 확인
A16: 10 | B16: 전년 동월 전표 존재 | C16: =COUNTIF(전표_원본!$M$5:$M$100000,설정!$C$20-12)&"건" | D16: =IF(COUNTIF(전표_원본!$M$5:$M$100000,설정!$C$20-12)>0,"OK","참고") | E16: 전년동월 비교·이상치 판정에 필요 (최근 24개월 권장)
A17: 11 | B17: 미매핑 코스트센터 | C17: =COUNTIF(전표_원본!$N$5:$N$100000,"미매핑")&"건"&IF(COUNTIF(전표_원본!$N$5:$N$100000,"미매핑")>0," (예: "&INDEX(전표_원본!$G$5:$G$100000,MATCH("미매핑",전표_원본!$N$5:$N$100000,0))&")","") | D17: =IF(COUNTIF(전표_원본!$N$5:$N$100000,"미매핑")=0,"OK","확인필요") | E17: 부서매핑에 코스트센터 추가
A18: 12 | B18: 미매핑 G/L 계정 | C18: =COUNTIF(전표_원본!$W$5:$W$100000,"미매핑")&"건"&IF(COUNTIF(전표_원본!$W$5:$W$100000,"미매핑")>0," (예: "&INDEX(전표_원본!$F$5:$F$100000,MATCH("미매핑",전표_원본!$W$5:$W$100000,0))&")","") | D18: =IF(COUNTIF(전표_원본!$W$5:$W$100000,"미매핑")=0,"OK","확인필요") | E18: 계정매핑에 계정 추가
A19: 13 | B19: TB ↔ 전표 당월 대사 | C19: ="차이 "&TEXT(계정변동!L25,"#,##0.0") | D19: =IF(ABS(계정변동!L25)<0.05,"OK","확인필요") | E19: 계정변동 시트에서 차이 나는 계정 확인 (전표 추출 범위 누락 등)
A20: 14 | B20: 예산판 ↔ 전표 당분기 대사 | C20: ="차이 "&TEXT(계정변동!O25,"#,##0.0") | D20: =IF(ABS(계정변동!O25)<0.05,"OK","확인필요") | E20: 예산판 추출 시점과 전표 기간 일치 여부 확인
A21: 15 | B21: 변동분석에 없는 조합 (전표) | C21: =COUNTIFS(전표_원본!$V$5:$V$100000,"N",전표_원본!$A$5:$A$100000,설정!$C$6)&"건" | D21: =IF(COUNTIFS(전표_원본!$V$5:$V$100000,"N",전표_원본!$A$5:$A$100000,설정!$C$6)=0,"OK","확인필요") | E21: 변동분석에 부서코드·G/L 행 추가
A22: 16 | B22: 변동분석에 없는 조합 (예산판) | C22: =COUNTIFS(예산판_원본!$Q$5:$Q$5000,"N",예산판_원본!$M$5:$M$5000,설정!$C$6)&"행" | D22: =IF(COUNTIFS(예산판_원본!$Q$5:$Q$5000,"N",예산판_원본!$M$5:$M$5000,설정!$C$6)=0,"OK","확인필요") | E22: 변동분석에 부서코드·G/L 행 추가
A23: 17 | B23: 무예산 집행 | C23: =COUNTIF(변동분석!$AO$7:$AO$506,"무예산")&"건" | D23: =IF(COUNTIF(변동분석!$AO$7:$AO$506,"무예산")=0,"OK","참고") | E23: 업무상 예외 - 전용·추가 배정 여부 확인
A24: 18 | B24: 원인분석 선택 항목 | C24: =원인분석!$E$9&" · 당기 전표 "&COUNTIF(전표_원본!$Q$5:$Q$100000,"당기")&"건" | D24: =IF(COUNTIF(전표_원본!$Q$5:$Q$100000,"당기")>0,"OK","참고") | E24: 원인분석 C5~C8 선택값 확인
A25: 19 | B25: BS_원본 머리글 | C25: =IF(IF(BS_원본!A4<>"회계연도","A ","")&IF(BS_원본!B4<>"기간","B ","")&IF(BS_원본!C4<>"항목코드","C ","")&IF(BS_원본!D4<>"항목명","D ","")&IF(BS_원본!E4<>"구분","E ","")&IF(BS_원본!F4<>"레벨","F ","")&IF(BS_원본!G4<>"기말잔액","G ","")="","일치","불일치 열: "&IF(BS_원본!A4<>"회계연도","A ","")&IF(BS_원본!B4<>"기간","B ","")&IF(BS_원본!C4<>"항목코드","C ","")&IF(BS_원본!D4<>"항목명","D ","")&IF(BS_원본!E4<>"구분","E ","")&IF(BS_원본!F4<>"레벨","F ","")&IF(BS_원본!G4<>"기말잔액","G ","")) | D25: =IF(C25="일치","OK","확인필요") | E25: 4행 머리글을 표준 이름으로
A26: 20 | B26: PL_원본 머리글 | C26: =IF(IF(PL_원본!A4<>"회계연도","A ","")&IF(PL_원본!B4<>"기간","B ","")&IF(PL_원본!C4<>"항목코드","C ","")&IF(PL_원본!D4<>"항목명","D ","")&IF(PL_원본!E4<>"구분","E ","")&IF(PL_원본!F4<>"레벨","F ","")&IF(PL_원본!G4<>"당월금액","G ","")&IF(PL_원본!H4<>"누계금액","H ","")="","일치","불일치 열: "&IF(PL_원본!A4<>"회계연도","A ","")&IF(PL_원본!B4<>"기간","B ","")&IF(PL_원본!C4<>"항목코드","C ","")&IF(PL_원본!D4<>"항목명","D ","")&IF(PL_원본!E4<>"구분","E ","")&IF(PL_원본!F4<>"레벨","F ","")&IF(PL_원본!G4<>"당월금액","G ","")&IF(PL_원본!H4<>"누계금액","H ","")) | D26: =IF(C26="일치","OK","확인필요") | E26: 4행 머리글을 표준 이름으로
A27: 21 | B27: BS·PL 보조수식 범위 | C27: ="BS "&COUNTA(BS_원본!A5:A20000)&"/"&COUNTA(BS_원본!I5:I20000)&" · PL "&COUNTA(PL_원본!A5:A20000)&"/"&COUNTA(PL_원본!J5:J20000) | D27: =IF(AND(COUNTA(BS_원본!I5:I20000)>=COUNTA(BS_원본!A5:A20000),COUNTA(PL_원본!J5:J20000)>=COUNTA(PL_원본!A5:A20000)),"OK","확인필요") | E27: 보조수식을 데이터 마지막 행까지 채우기
A28: 22 | B28: 기준월 BS·PL 존재 | C28: ="BS "&COUNTIF(BS_원본!$I$5:$I$20000,설정!$C$20)&"행 · PL "&COUNTIF(PL_원본!$J$5:$J$20000,설정!$C$20)&"행" | D28: =IF(AND(COUNTIF(BS_원본!$I$5:$I$20000,설정!$C$20)>0,COUNTIF(PL_원본!$J$5:$J$20000,설정!$C$20)>0),"OK","확인필요") | E28: 기준월 BS·PL이 들어 있는지 확인
A29: 23 | B29: BS 대차 (자산 = 부채 + 자본) | C29: ="차이 "&TEXT(SUMIFS(BS_원본!$K$5:$K$20000,BS_원본!$J$5:$J$20000,"A000",BS_원본!$I$5:$I$20000,설정!$C$20)-SUMIFS(BS_원본!$K$5:$K$20000,BS_원본!$J$5:$J$20000,"L000",BS_원본!$I$5:$I$20000,설정!$C$20)-SUMIFS(BS_원본!$K$5:$K$20000,BS_원본!$J$5:$J$20000,"E000",BS_원본!$I$5:$I$20000,설정!$C$20),"#,##0") | D29: =IF(ABS(SUMIFS(BS_원본!$K$5:$K$20000,BS_원본!$J$5:$J$20000,"A000",BS_원본!$I$5:$I$20000,설정!$C$20)-SUMIFS(BS_원본!$K$5:$K$20000,BS_원본!$J$5:$J$20000,"L000",BS_원본!$I$5:$I$20000,설정!$C$20)-SUMIFS(BS_원본!$K$5:$K$20000,BS_원본!$J$5:$J$20000,"E000",BS_원본!$I$5:$I$20000,설정!$C$20))<1,"OK","확인필요") | E29: BS 합계 행(A000·L000·E000) 확인
A30: 24 | B30: PL 당기순이익 검산 | C30: ="차이 "&TEXT(SUMIFS(PL_원본!$L$5:$L$20000,PL_원본!$K$5:$K$20000,"P100",PL_원본!$J$5:$J$20000,설정!$C$20)+SUMIFS(PL_원본!$L$5:$L$20000,PL_원본!$K$5:$K$20000,"P200",PL_원본!$J$5:$J$20000,설정!$C$20)-SUMIFS(PL_원본!$L$5:$L$20000,PL_원본!$K$5:$K$20000,"P300",PL_원본!$J$5:$J$20000,설정!$C$20)-SUMIFS(PL_원본!$L$5:$L$20000,PL_원본!$K$5:$K$20000,"P500",PL_원본!$J$5:$J$20000,설정!$C$20)-SUMIFS(PL_원본!$L$5:$L$20000,PL_원본!$K$5:$K$20000,"P600",PL_원본!$J$5:$J$20000,설정!$C$20),"#,##0.0") | D30: =IF(ABS(SUMIFS(PL_원본!$L$5:$L$20000,PL_원본!$K$5:$K$20000,"P100",PL_원본!$J$5:$J$20000,설정!$C$20)+SUMIFS(PL_원본!$L$5:$L$20000,PL_원본!$K$5:$K$20000,"P200",PL_원본!$J$5:$J$20000,설정!$C$20)-SUMIFS(PL_원본!$L$5:$L$20000,PL_원본!$K$5:$K$20000,"P300",PL_원본!$J$5:$J$20000,설정!$C$20)-SUMIFS(PL_원본!$L$5:$L$20000,PL_원본!$K$5:$K$20000,"P500",PL_원본!$J$5:$J$20000,설정!$C$20)-SUMIFS(PL_원본!$L$5:$L$20000,PL_원본!$K$5:$K$20000,"P600",PL_원본!$J$5:$J$20000,설정!$C$20))<0.05,"OK","확인필요") | E30: 보험손익+투자손익−사업비−법인세 = 당기순이익
A31: 25 | B31: PL 기타사업비용 ↔ 비귀속 사업비 | C31: ="차이 "&TEXT(SUMIFS(PL_원본!$L$5:$L$20000,PL_원본!$K$5:$K$20000,"P300",PL_원본!$J$5:$J$20000,설정!$C$20)-SUMIFS(전표_원본!$Y$5:$Y$100000,전표_원본!$M$5:$M$100000,설정!$C$20),"#,##0.0") | D31: =IF(ABS(SUMIFS(PL_원본!$L$5:$L$20000,PL_원본!$K$5:$K$20000,"P300",PL_원본!$J$5:$J$20000,설정!$C$20)-SUMIFS(전표_원본!$Y$5:$Y$100000,전표_원본!$M$5:$M$100000,설정!$C$20))<0.5,"OK","확인필요") | E31: 직접대체·부서별 비율의 비귀속과 PL 기타사업비용 범위 확인
A32: 26 | B32: 대체비율 합계 100% | C32: ="부서 "&SUMPRODUCT((계정대체기준!$A$20:$A$49<>"")*(ABS(계정대체기준!$G$20:$G$49-1)>0.0001))&"행 · 포트폴리오 "&(ABS(계정대체기준!$D$64-1)+ABS(계정대체기준!$E$64-1)+ABS(계정대체기준!$F$64-1)>0.0001)*1 | D32: =IF(SUMPRODUCT((계정대체기준!$A$20:$A$49<>"")*(ABS(계정대체기준!$G$20:$G$49-1)>0.0001))+(ABS(계정대체기준!$D$64-1)+ABS(계정대체기준!$E$64-1)+ABS(계정대체기준!$F$64-1)>0.0001)=0,"OK","확인필요") | E32: 계정대체기준 시트에서 합계가 100%가 아닌 행 수정
A33: 27 | B33: 대체비율표에 없는 부서 (공통비) | C33: =SUMPRODUCT((전표_원본!$AE$5:$AE$100000="공통비")*(COUNTIF(계정대체기준!$A$20:$A$49,전표_원본!$N$5:$N$100000)=0))&"건 (전액 비귀속 처리)" | D33: =IF(SUMPRODUCT((전표_원본!$AE$5:$AE$100000="공통비")*(COUNTIF(계정대체기준!$A$20:$A$49,전표_원본!$N$5:$N$100000)=0))=0,"OK","확인필요") | E33: 계정대체기준 부서별 비율표에 부서 추가
A34: 28 | B34: 계정대체 전후 합계 | C34: ="차이 "&TEXT(SUMIFS(전표_원본!$P$5:$P$100000,전표_원본!$M$5:$M$100000,설정!$C$20)-SUMIFS(전표_원본!$Y$5:$Y$100000,전표_원본!$M$5:$M$100000,설정!$C$20)-SUMIFS(전표_원본!$Z$5:$Z$100000,전표_원본!$M$5:$M$100000,설정!$C$20)-SUMIFS(전표_원본!$AA$5:$AA$100000,전표_원본!$M$5:$M$100000,설정!$C$20)-SUMIFS(전표_원본!$AB$5:$AB$100000,전표_원본!$M$5:$M$100000,설정!$C$20)-SUMIFS(전표_원본!$AD$5:$AD$100000,전표_원본!$M$5:$M$100000,설정!$C$20),"#,##0.0") | D34: =IF(ABS(SUMIFS(전표_원본!$P$5:$P$100000,전표_원본!$M$5:$M$100000,설정!$C$20)-SUMIFS(전표_원본!$Y$5:$Y$100000,전표_원본!$M$5:$M$100000,설정!$C$20)-SUMIFS(전표_원본!$Z$5:$Z$100000,전표_원본!$M$5:$M$100000,설정!$C$20)-SUMIFS(전표_원본!$AA$5:$AA$100000,전표_원본!$M$5:$M$100000,설정!$C$20)-SUMIFS(전표_원본!$AB$5:$AB$100000,전표_원본!$M$5:$M$100000,설정!$C$20)-SUMIFS(전표_원본!$AD$5:$AD$100000,전표_원본!$M$5:$M$100000,설정!$C$20))<0.05,"OK","확인필요") | E34: 직접대체 계정 지정, 부서별 비율 합계 확인
A35: 29 | B35: PL 재산관리비 ↔ 재산관리비 대체액 | C35: ="차이 "&TEXT(SUMIFS(PL_원본!$L$5:$L$20000,PL_원본!$K$5:$K$20000,"P230",PL_원본!$J$5:$J$20000,설정!$C$20)-SUMIFS(전표_원본!$AD$5:$AD$100000,전표_원본!$M$5:$M$100000,설정!$C$20),"#,##0.0") | D35: =IF(ABS(SUMIFS(PL_원본!$L$5:$L$20000,PL_원본!$K$5:$K$20000,"P230",PL_원본!$J$5:$J$20000,설정!$C$20)-SUMIFS(전표_원본!$AD$5:$AD$100000,전표_원본!$M$5:$M$100000,설정!$C$20))<0.5,"OK","확인필요") | E35: 투자관련부서 목록·재산관리비 비율, PL 재산관리비 범위 확인
A36: 30 | B36: 기준월 예정사업비 존재 | C36: =COUNTIF(예정사업비!$I$5:$I$20000,설정!$C$20)&"행" | D36: =IF(COUNTIF(예정사업비!$I$5:$I$20000,설정!$C$20)>0,"OK","확인필요") | E36: 계리 예정사업비 기준월 자료 확인
A37: 31 | B37: 부채변동표 롤포워드 | C37: ="차이 "&TEXT(SUMIFS(부채변동표!$M$5:$M$20000,부채변동표!$L$5:$L$20000,설정!$C$20,부채변동표!$P$5:$P$20000,"<>F99")-SUMIFS(부채변동표!$M$5:$M$20000,부채변동표!$L$5:$L$20000,설정!$C$20,부채변동표!$P$5:$P$20000,"F99"),"#,##0.0")&" / "&TEXT(SUMIFS(부채변동표!$O$5:$O$20000,부채변동표!$L$5:$L$20000,설정!$C$20,부채변동표!$P$5:$P$20000,"<>F99")-SUMIFS(부채변동표!$O$5:$O$20000,부채변동표!$L$5:$L$20000,설정!$C$20,부채변동표!$P$5:$P$20000,"F99"),"#,##0.0") | D37: =IF(ABS(SUMIFS(부채변동표!$M$5:$M$20000,부채변동표!$L$5:$L$20000,설정!$C$20,부채변동표!$P$5:$P$20000,"<>F99")-SUMIFS(부채변동표!$M$5:$M$20000,부채변동표!$L$5:$L$20000,설정!$C$20,부채변동표!$P$5:$P$20000,"F99"))+ABS(SUMIFS(부채변동표!$N$5:$N$20000,부채변동표!$L$5:$L$20000,설정!$C$20,부채변동표!$P$5:$P$20000,"<>F99")-SUMIFS(부채변동표!$N$5:$N$20000,부채변동표!$L$5:$L$20000,설정!$C$20,부채변동표!$P$5:$P$20000,"F99"))+ABS(SUMIFS(부채변동표!$O$5:$O$20000,부채변동표!$L$5:$L$20000,설정!$C$20,부채변동표!$P$5:$P$20000,"<>F99")-SUMIFS(부채변동표!$O$5:$O$20000,부채변동표!$L$5:$L$20000,설정!$C$20,부채변동표!$P$5:$P$20000,"F99"))<1,"OK","확인필요") | E37: 기초 + 요인 합계 = 기말인지, 변동요인 매핑(입력옵션) 누락 확인
A38: 32 | B38: 변동표 기말 ↔ BS (BEL·RA·CSM) | C38: ="차이 "&TEXT(SUMIFS(부채변동표!$M$5:$M$20000,부채변동표!$L$5:$L$20000,설정!$C$20,부채변동표!$P$5:$P$20000,"F99")-SUMIFS(BS_원본!$K$5:$K$20000,BS_원본!$J$5:$J$20000,"L110",BS_원본!$I$5:$I$20000,설정!$C$20),"#,##0")&" / "&TEXT(SUMIFS(부채변동표!$N$5:$N$20000,부채변동표!$L$5:$L$20000,설정!$C$20,부채변동표!$P$5:$P$20000,"F99")-SUMIFS(BS_원본!$K$5:$K$20000,BS_원본!$J$5:$J$20000,"L120",BS_원본!$I$5:$I$20000,설정!$C$20),"#,##0")&" / "&TEXT(SUMIFS(부채변동표!$O$5:$O$20000,부채변동표!$L$5:$L$20000,설정!$C$20,부채변동표!$P$5:$P$20000,"F99")-SUMIFS(BS_원본!$K$5:$K$20000,BS_원본!$J$5:$J$20000,"L130",BS_원본!$I$5:$I$20000,설정!$C$20),"#,##0") | D38: =IF(ABS(SUMIFS(부채변동표!$M$5:$M$20000,부채변동표!$L$5:$L$20000,설정!$C$20,부채변동표!$P$5:$P$20000,"F99")-SUMIFS(BS_원본!$K$5:$K$20000,BS_원본!$J$5:$J$20000,"L110",BS_원본!$I$5:$I$20000,설정!$C$20))+ABS(SUMIFS(부채변동표!$N$5:$N$20000,부채변동표!$L$5:$L$20000,설정!$C$20,부채변동표!$P$5:$P$20000,"F99")-SUMIFS(BS_원본!$K$5:$K$20000,BS_원본!$J$5:$J$20000,"L120",BS_원본!$I$5:$I$20000,설정!$C$20))+ABS(SUMIFS(부채변동표!$O$5:$O$20000,부채변동표!$L$5:$L$20000,설정!$C$20,부채변동표!$P$5:$P$20000,"F99")-SUMIFS(BS_원본!$K$5:$K$20000,BS_원본!$J$5:$J$20000,"L130",BS_원본!$I$5:$I$20000,설정!$C$20))<1,"OK","확인필요") | E38: BS 항목 매핑(L110·L120·L130)과 변동표 포트폴리오 범위 확인
A39: 33 | B39: 변동표 F31 ↔ TRACE 신계약비 경험차이 | C39: =COUNTIF(IFRS17_사업비!$F$39:$F$42,"차이 확인")&"개 포트폴리오 차이" | D39: =IF(COUNTIF(IFRS17_사업비!$F$39:$F$42,"차이 확인")=0,"OK","참고") | E39: 배분 드라이버·예정사업비 기준이 계리와 같은지 확인 (차이는 정보성)

Sheet 대시보드
A1: =설정!$C$5&" TRACE 대시보드 ("&INT((설정!$C$20-1)/12)&"-"&TEXT(MOD(설정!$C$20-1,12)+1,"00")&")"
A2: ="단위: "&설정!$C$9&" · 자가진단: "&자가진단!$B$4&" · 3자 대사: "&계정변동!$P$25
A4: 총자산 | C4: 자본총계 | E4: CSM | G4: 당기순이익 누계 | I4: 사업비 누계 | K4: 분기 한도 초과(예상)
A5: =차트데이터!B91 | C5: =차트데이터!B92 | E5: =차트데이터!B93 | G5: =차트데이터!B94 | I5: =차트데이터!B95 | K5: =차트데이터!B97
A6: =차트데이터!E91&" 대비 "&TEXT(차트데이터!D91,"+0.0%;-0.0%;0.0%") | C6: =차트데이터!E92&" 대비 "&TEXT(차트데이터!D92,"+0.0%;-0.0%;0.0%") | E6: =차트데이터!E93&" 대비 "&TEXT(차트데이터!D93,"+0.0%;-0.0%;0.0%") | G6: =차트데이터!E94&" 대비 "&TEXT(차트데이터!D94,"+0.0%;-0.0%;0.0%") | I6: =차트데이터!E95&" 대비 "&TEXT(차트데이터!D95,"+0.0%;-0.0%;0.0%") | K6: ="주의 "&차트데이터!C97&"건"
A58: 주의 대상 TOP 10
A59: 순위 | B59: 부서 | C59: 계정 | D59: 당월 | E59: 전월대비 | F59: 예산 | G59: 신호
A60: =주의대상!A6 | B60: =주의대상!B6 | C60: =주의대상!C6 | D60: =주의대상!D6 | E60: =주의대상!E6 | F60: =주의대상!G6 | G60: =주의대상!J6
A61: =주의대상!A7 | B61: =주의대상!B7 | C61: =주의대상!C7 | D61: =주의대상!D7 | E61: =주의대상!E7 | F61: =주의대상!G7 | G61: =주의대상!J7
A62: =주의대상!A8 | B62: =주의대상!B8 | C62: =주의대상!C8 | D62: =주의대상!D8 | E62: =주의대상!E8 | F62: =주의대상!G8 | G62: =주의대상!J8
A63: =주의대상!A9 | B63: =주의대상!B9 | C63: =주의대상!C9 | D63: =주의대상!D9 | E63: =주의대상!E9 | F63: =주의대상!G9 | G63: =주의대상!J9
A64: =주의대상!A10 | B64: =주의대상!B10 | C64: =주의대상!C10 | D64: =주의대상!D10 | E64: =주의대상!E10 | F64: =주의대상!G10 | G64: =주의대상!J10
A65: =주의대상!A11 | B65: =주의대상!B11 | C65: =주의대상!C11 | D65: =주의대상!D11 | E65: =주의대상!E11 | F65: =주의대상!G11 | G65: =주의대상!J11
A66: =주의대상!A12 | B66: =주의대상!B12 | C66: =주의대상!C12 | D66: =주의대상!D12 | E66: =주의대상!E12 | F66: =주의대상!G12 | G66: =주의대상!J12
A67: =주의대상!A13 | B67: =주의대상!B13 | C67: =주의대상!C13 | D67: =주의대상!D13 | E67: =주의대상!E13 | F67: =주의대상!G13 | G67: =주의대상!J13
A68: =주의대상!A14 | B68: =주의대상!B14 | C68: =주의대상!C14 | D68: =주의대상!D14 | E68: =주의대상!E14 | F68: =주의대상!G14 | G68: =주의대상!J14
A69: =주의대상!A15 | B69: =주의대상!B15 | C69: =주의대상!C15 | D69: =주의대상!D15 | E69: =주의대상!E15 | F69: =주의대상!G15 | G69: =주의대상!J15
A71: 선택 항목 원인 (원인분석 시트)
A72: =원인분석!A18
A75: IFRS 17 사업비 영향 (GMM · VFA)
A76: =IFRS17_사업비!A5

Sheet IFRS17_사업비
A1: TRACE · IFRS 17 사업비 영향 (GMM · VFA · PAA)
A2: 사업비 전표 → 계정대체 → 포트폴리오 → 예정 대비 경험차이 → CSM(GMM·VFA)·당기손익 · 금액: 보고단위
A3: ="기준: "&INT((설정!$C$20-1)/12)&"-"&TEXT(MOD(설정!$C$20-1,12)+1,"00")&" · 단위: "&설정!$C$9
A5: ="GMM CSM 당월 변동 "&TEXT(E57,"+#,##0;-#,##0;0")&" 중 사업비 관련 "&TEXT(E58,"+#,##0.0;-#,##0.0;0")&" (취득현금흐름 경험조정 "&TEXT(E50,"+#,##0.0;-#,##0.0;0")&", 사업비 가정변경 "&TEXT(E48,"+#,##0.0;-#,##0.0;0")&"). "&"신계약비 실제가 예정보다 "&TEXT(ABS(SUMIFS($G$20:$G$31,$D$20:$D$31,"신계약비")),"#,##0.0")&IF(SUMIFS($G$20:$G$31,$D$20:$D$31,"신계약비")<0," 많았고"," 적었고")&IF(B79="","",", 증가 기여 1위는 "&B79&" "&C79&" ("&TEXT(F79,"+#,##0.0;-#,##0.0;0")&")")&IF(B87="","",", 대표 전표는 "&E87&" '"&F87&"' "&TEXT(H87,"#,##0.0"))&". "&"당기손익 반영 경험차이 "&TEXT(G34,"+#,##0.0;-#,##0.0;0")&". "&"VFA(변액) CSM 당월 변동 "&TEXT(E74,"+#,##0;-#,##0;0")&" 중 사업비 관련 "&TEXT(E75,"+#,##0.0;-#,##0.0;0")&"."
L6: 키 | M6: 당월 신계약 | N6: 전월 신계약 | O6: 증감 | P6: 정렬키
L7: =IF(변동분석!$A7="","",변동분석!$E7) | M7: =IF(L7="",0,SUMIFS(전표_원본!$Z$5:$Z$100000,전표_원본!$O$5:$O$100000,L7,전표_원본!$M$5:$M$100000,설정!$C$20)) | N7: =IF(L7="",0,SUMIFS(전표_원본!$Z$5:$Z$100000,전표_원본!$O$5:$O$100000,L7,전표_원본!$M$5:$M$100000,설정!$C$20-1)) | O7: =M7-N7 | P7: =IF(L7="","",O7+ROW()/1000000)
A8: 1. 계정대체 결과 요약 (전표 기준) | L8: =IF(변동분석!$A8="","",변동분석!$E8) | M8: =IF(L8="",0,SUMIFS(전표_원본!$Z$5:$Z$100000,전표_원본!$O$5:$O$100000,L8,전표_원본!$M$5:$M$100000,설정!$C$20)) | N8: =IF(L8="",0,SUMIFS(전표_원본!$Z$5:$Z$100000,전표_원본!$O$5:$O$100000,L8,전표_원본!$M$5:$M$100000,설정!$C$20-1)) | O8: =M8-N8 | P8: =IF(L8="","",O8+ROW()/1000000)
A9: 구분 | B9: 당월 | C9: 전월 | D9: 누계 | E9: 당월 비중 | L9: =IF(변동분석!$A9="","",변동분석!$E9) | M9: =IF(L9="",0,SUMIFS(전표_원본!$Z$5:$Z$100000,전표_원본!$O$5:$O$100000,L9,전표_원본!$M$5:$M$100000,설정!$C$20)) | N9: =IF(L9="",0,SUMIFS(전표_원본!$Z$5:$Z$100000,전표_원본!$O$5:$O$100000,L9,전표_원본!$M$5:$M$100000,설정!$C$20-1)) | O9: =M9-N9 | P9: =IF(L9="","",O9+ROW()/1000000)
A10: 비귀속 | B10: =SUMIFS(전표_원본!$Y$5:$Y$100000,전표_원본!$M$5:$M$100000,설정!$C$20) | C10: =SUMIFS(전표_원본!$Y$5:$Y$100000,전표_원본!$M$5:$M$100000,설정!$C$20-1) | D10: =SUMIFS(전표_원본!$Y$5:$Y$100000,전표_원본!$M$5:$M$100000,">="&(설정!$C$6*12+1),전표_원본!$M$5:$M$100000,"<="&설정!$C$20) | E10: =IF($B$15=0,0,B10/$B$15) | L10: =IF(변동분석!$A10="","",변동분석!$E10) | M10: =IF(L10="",0,SUMIFS(전표_원본!$Z$5:$Z$100000,전표_원본!$O$5:$O$100000,L10,전표_원본!$M$5:$M$100000,설정!$C$20)) | N10: =IF(L10="",0,SUMIFS(전표_원본!$Z$5:$Z$100000,전표_원본!$O$5:$O$100000,L10,전표_원본!$M$5:$M$100000,설정!$C$20-1)) | O10: =M10-N10 | P10: =IF(L10="","",O10+ROW()/1000000)
A11: 신계약비 | B11: =SUMIFS(전표_원본!$Z$5:$Z$100000,전표_원본!$M$5:$M$100000,설정!$C$20) | C11: =SUMIFS(전표_원본!$Z$5:$Z$100000,전표_원본!$M$5:$M$100000,설정!$C$20-1) | D11: =SUMIFS(전표_원본!$Z$5:$Z$100000,전표_원본!$M$5:$M$100000,">="&(설정!$C$6*12+1),전표_원본!$M$5:$M$100000,"<="&설정!$C$20) | E11: =IF($B$15=0,0,B11/$B$15) | L11: =IF(변동분석!$A11="","",변동분석!$E11) | M11: =IF(L11="",0,SUMIFS(전표_원본!$Z$5:$Z$100000,전표_원본!$O$5:$O$100000,L11,전표_원본!$M$5:$M$100000,설정!$C$20)) | N11: =IF(L11="",0,SUMIFS(전표_원본!$Z$5:$Z$100000,전표_원본!$O$5:$O$100000,L11,전표_원본!$M$5:$M$100000,설정!$C$20-1)) | O11: =M11-N11 | P11: =IF(L11="","",O11+ROW()/1000000)
A12: 유지비 | B12: =SUMIFS(전표_원본!$AA$5:$AA$100000,전표_원본!$M$5:$M$100000,설정!$C$20) | C12: =SUMIFS(전표_원본!$AA$5:$AA$100000,전표_원본!$M$5:$M$100000,설정!$C$20-1) | D12: =SUMIFS(전표_원본!$AA$5:$AA$100000,전표_원본!$M$5:$M$100000,">="&(설정!$C$6*12+1),전표_원본!$M$5:$M$100000,"<="&설정!$C$20) | E12: =IF($B$15=0,0,B12/$B$15) | L12: =IF(변동분석!$A12="","",변동분석!$E12) | M12: =IF(L12="",0,SUMIFS(전표_원본!$Z$5:$Z$100000,전표_원본!$O$5:$O$100000,L12,전표_원본!$M$5:$M$100000,설정!$C$20)) | N12: =IF(L12="",0,SUMIFS(전표_원본!$Z$5:$Z$100000,전표_원본!$O$5:$O$100000,L12,전표_원본!$M$5:$M$100000,설정!$C$20-1)) | O12: =M12-N12 | P12: =IF(L12="","",O12+ROW()/1000000)
A13: 수금비 | B13: =SUMIFS(전표_원본!$AB$5:$AB$100000,전표_원본!$M$5:$M$100000,설정!$C$20) | C13: =SUMIFS(전표_원본!$AB$5:$AB$100000,전표_원본!$M$5:$M$100000,설정!$C$20-1) | D13: =SUMIFS(전표_원본!$AB$5:$AB$100000,전표_원본!$M$5:$M$100000,">="&(설정!$C$6*12+1),전표_원본!$M$5:$M$100000,"<="&설정!$C$20) | E13: =IF($B$15=0,0,B13/$B$15) | L13: =IF(변동분석!$A13="","",변동분석!$E13) | M13: =IF(L13="",0,SUMIFS(전표_원본!$Z$5:$Z$100000,전표_원본!$O$5:$O$100000,L13,전표_원본!$M$5:$M$100000,설정!$C$20)) | N13: =IF(L13="",0,SUMIFS(전표_원본!$Z$5:$Z$100000,전표_원본!$O$5:$O$100000,L13,전표_원본!$M$5:$M$100000,설정!$C$20-1)) | O13: =M13-N13 | P13: =IF(L13="","",O13+ROW()/1000000)
A14: 재산관리비 | B14: =SUMIFS(전표_원본!$AD$5:$AD$100000,전표_원본!$M$5:$M$100000,설정!$C$20) | C14: =SUMIFS(전표_원본!$AD$5:$AD$100000,전표_원본!$M$5:$M$100000,설정!$C$20-1) | D14: =SUMIFS(전표_원본!$AD$5:$AD$100000,전표_원본!$M$5:$M$100000,">="&(설정!$C$6*12+1),전표_원본!$M$5:$M$100000,"<="&설정!$C$20) | E14: =IF($B$15=0,0,B14/$B$15) | L14: =IF(변동분석!$A14="","",변동분석!$E14) | M14: =IF(L14="",0,SUMIFS(전표_원본!$Z$5:$Z$100000,전표_원본!$O$5:$O$100000,L14,전표_원본!$M$5:$M$100000,설정!$C$20)) | N14: =IF(L14="",0,SUMIFS(전표_원본!$Z$5:$Z$100000,전표_원본!$O$5:$O$100000,L14,전표_원본!$M$5:$M$100000,설정!$C$20-1)) | O14: =M14-N14 | P14: =IF(L14="","",O14+ROW()/1000000)
A15: 합계 (= 전표 사업비) | B15: =SUM(B10:B14) | C15: =SUM(C10:C14) | D15: =SUM(D10:D14) | E15: =SUM(E10:E14) | L15: =IF(변동분석!$A15="","",변동분석!$E15) | M15: =IF(L15="",0,SUMIFS(전표_원본!$Z$5:$Z$100000,전표_원본!$O$5:$O$100000,L15,전표_원본!$M$5:$M$100000,설정!$C$20)) | N15: =IF(L15="",0,SUMIFS(전표_원본!$Z$5:$Z$100000,전표_원본!$O$5:$O$100000,L15,전표_원본!$M$5:$M$100000,설정!$C$20-1)) | O15: =M15-N15 | P15: =IF(L15="","",O15+ROW()/1000000)
A16: 재산관리비는 IFRS 17 이행현금흐름 밖 (PL 투자손익에서 차감) · 비귀속은 기타사업비용 | L16: =IF(변동분석!$A16="","",변동분석!$E16) | M16: =IF(L16="",0,SUMIFS(전표_원본!$Z$5:$Z$100000,전표_원본!$O$5:$O$100000,L16,전표_원본!$M$5:$M$100000,설정!$C$20)) | N16: =IF(L16="",0,SUMIFS(전표_원본!$Z$5:$Z$100000,전표_원본!$O$5:$O$100000,L16,전표_원본!$M$5:$M$100000,설정!$C$20-1)) | O16: =M16-N16 | P16: =IF(L16="","",O16+ROW()/1000000)
L17: =IF(변동분석!$A17="","",변동분석!$E17) | M17: =IF(L17="",0,SUMIFS(전표_원본!$Z$5:$Z$100000,전표_원본!$O$5:$O$100000,L17,전표_원본!$M$5:$M$100000,설정!$C$20)) | N17: =IF(L17="",0,SUMIFS(전표_원본!$Z$5:$Z$100000,전표_원본!$O$5:$O$100000,L17,전표_원본!$M$5:$M$100000,설정!$C$20-1)) | O17: =M17-N17 | P17: =IF(L17="","",O17+ROW()/1000000)
A18: 2. 포트폴리오별 경험차이 (당월, 예정 − 실제 · 음수 = 불리) | L18: =IF(변동분석!$A18="","",변동분석!$E18) | M18: =IF(L18="",0,SUMIFS(전표_원본!$Z$5:$Z$100000,전표_원본!$O$5:$O$100000,L18,전표_원본!$M$5:$M$100000,설정!$C$20)) | N18: =IF(L18="",0,SUMIFS(전표_원본!$Z$5:$Z$100000,전표_원본!$O$5:$O$100000,L18,전표_원본!$M$5:$M$100000,설정!$C$20-1)) | O18: =M18-N18 | P18: =IF(L18="","",O18+ROW()/1000000)
A19: 포트폴리오 | B19: 포트폴리오명 | C19: 측정모형 | D19: 구분 | E19: 실제 | F19: 예정 | G19: 경험차이 | H19: 반영처 | I19: CSM 반영 | J19: 당기손익 반영 | L19: =IF(변동분석!$A19="","",변동분석!$E19) | M19: =IF(L19="",0,SUMIFS(전표_원본!$Z$5:$Z$100000,전표_원본!$O$5:$O$100000,L19,전표_원본!$M$5:$M$100000,설정!$C$20)) | N19: =IF(L19="",0,SUMIFS(전표_원본!$Z$5:$Z$100000,전표_원본!$O$5:$O$100000,L19,전표_원본!$M$5:$M$100000,설정!$C$20-1)) | O19: =M19-N19 | P19: =IF(L19="","",O19+ROW()/1000000)
A20: PF01 | B20: =IFERROR(INDEX(계정대체기준!$B$54:$B$63,MATCH($A20,계정대체기준!$A$54:$A$63,0)),"") | C20: =IFERROR(INDEX(계정대체기준!$C$54:$C$63,MATCH($A20,계정대체기준!$A$54:$A$63,0)),"") | D20: 신계약비 | E20: =$B$11*IFERROR(INDEX(계정대체기준!$D$54:$D$63,MATCH($A20,계정대체기준!$A$54:$A$63,0)),0) | F20: =SUMIFS(예정사업비!$J$5:$J$20000,예정사업비!$I$5:$I$20000,설정!$C$20,예정사업비!$C$5:$C$20000,$A20) | G20: =F20-E20 | H20: =IF(D20<>"신계약비","당기손익(보험서비스결과)",IF(C20="PAA",IF(계정대체기준!$C$68="이연 후 상각","잔여보장부채 이연(상각)","당기손익"),IF((IFERROR(INDEX(계정대체기준!$I$54:$I$63,MATCH($A20,계정대체기준!$A$54:$A$63,0)),"N")="Y"),"당기손익(손실요소)",IF(IF(계정대체기준!$C$67="전액 CSM",1,IF(계정대체기준!$C$67="전액 당기손익",0,IFERROR(INDEX(계정대체기준!$H$54:$H$63,MATCH($A20,계정대체기준!$A$54:$A$63,0)),0)))>=1,"CSM 조정 ("&C20&")",IF(IF(계정대체기준!$C$67="전액 CSM",1,IF(계정대체기준!$C$67="전액 당기손익",0,IFERROR(INDEX(계정대체기준!$H$54:$H$63,MATCH($A20,계정대체기준!$A$54:$A$63,0)),0)))<=0,"당기손익","CSM "&TEXT(IF(계정대체기준!$C$67="전액 CSM",1,IF(계정대체기준!$C$67="전액 당기손익",0,IFERROR(INDEX(계정대체기준!$H$54:$H$63,MATCH($A20,계정대체기준!$A$54:$A$63,0)),0))),"0%")&" ("&C20&") · 나머지 손익"))))) | I20: =IF(AND(D20="신계약비",OR(C20="GMM",C20="VFA"),NOT((IFERROR(INDEX(계정대체기준!$I$54:$I$63,MATCH($A20,계정대체기준!$A$54:$A$63,0)),"N")="Y"))),G20*IF(계정대체기준!$C$67="전액 CSM",1,IF(계정대체기준!$C$67="전액 당기손익",0,IFERROR(INDEX(계정대체기준!$H$54:$H$63,MATCH($A20,계정대체기준!$A$54:$A$63,0)),0))),0) | J20: =IF(AND(D20="신계약비",C20="PAA",계정대체기준!$C$68="이연 후 상각"),0,G20-I20) | L20: =IF(변동분석!$A20="","",변동분석!$E20) | M20: =IF(L20="",0,SUMIFS(전표_원본!$Z$5:$Z$100000,전표_원본!$O$5:$O$100000,L20,전표_원본!$M$5:$M$100000,설정!$C$20)) | N20: =IF(L20="",0,SUMIFS(전표_원본!$Z$5:$Z$100000,전표_원본!$O$5:$O$100000,L20,전표_원본!$M$5:$M$100000,설정!$C$20-1)) | O20: =M20-N20 | P20: =IF(L20="","",O20+ROW()/1000000)
A21: PF01 | B21: =IFERROR(INDEX(계정대체기준!$B$54:$B$63,MATCH($A21,계정대체기준!$A$54:$A$63,0)),"") | C21: =IFERROR(INDEX(계정대체기준!$C$54:$C$63,MATCH($A21,계정대체기준!$A$54:$A$63,0)),"") | D21: 유지비 | E21: =$B$12*IFERROR(INDEX(계정대체기준!$E$54:$E$63,MATCH($A21,계정대체기준!$A$54:$A$63,0)),0) | F21: =SUMIFS(예정사업비!$K$5:$K$20000,예정사업비!$I$5:$I$20000,설정!$C$20,예정사업비!$C$5:$C$20000,$A21) | G21: =F21-E21 | H21: =IF(D21<>"신계약비","당기손익(보험서비스결과)",IF(C21="PAA",IF(계정대체기준!$C$68="이연 후 상각","잔여보장부채 이연(상각)","당기손익"),IF((IFERROR(INDEX(계정대체기준!$I$54:$I$63,MATCH($A21,계정대체기준!$A$54:$A$63,0)),"N")="Y"),"당기손익(손실요소)",IF(IF(계정대체기준!$C$67="전액 CSM",1,IF(계정대체기준!$C$67="전액 당기손익",0,IFERROR(INDEX(계정대체기준!$H$54:$H$63,MATCH($A21,계정대체기준!$A$54:$A$63,0)),0)))>=1,"CSM 조정 ("&C21&")",IF(IF(계정대체기준!$C$67="전액 CSM",1,IF(계정대체기준!$C$67="전액 당기손익",0,IFERROR(INDEX(계정대체기준!$H$54:$H$63,MATCH($A21,계정대체기준!$A$54:$A$63,0)),0)))<=0,"당기손익","CSM "&TEXT(IF(계정대체기준!$C$67="전액 CSM",1,IF(계정대체기준!$C$67="전액 당기손익",0,IFERROR(INDEX(계정대체기준!$H$54:$H$63,MATCH($A21,계정대체기준!$A$54:$A$63,0)),0))),"0%")&" ("&C21&") · 나머지 손익"))))) | I21: =IF(AND(D21="신계약비",OR(C21="GMM",C21="VFA"),NOT((IFERROR(INDEX(계정대체기준!$I$54:$I$63,MATCH($A21,계정대체기준!$A$54:$A$63,0)),"N")="Y"))),G21*IF(계정대체기준!$C$67="전액 CSM",1,IF(계정대체기준!$C$67="전액 당기손익",0,IFERROR(INDEX(계정대체기준!$H$54:$H$63,MATCH($A21,계정대체기준!$A$54:$A$63,0)),0))),0) | J21: =IF(AND(D21="신계약비",C21="PAA",계정대체기준!$C$68="이연 후 상각"),0,G21-I21) | L21: =IF(변동분석!$A21="","",변동분석!$E21) | M21: =IF(L21="",0,SUMIFS(전표_원본!$Z$5:$Z$100000,전표_원본!$O$5:$O$100000,L21,전표_원본!$M$5:$M$100000,설정!$C$20)) | N21: =IF(L21="",0,SUMIFS(전표_원본!$Z$5:$Z$100000,전표_원본!$O$5:$O$100000,L21,전표_원본!$M$5:$M$100000,설정!$C$20-1)) | O21: =M21-N21 | P21: =IF(L21="","",O21+ROW()/1000000)
A22: PF01 | B22: =IFERROR(INDEX(계정대체기준!$B$54:$B$63,MATCH($A22,계정대체기준!$A$54:$A$63,0)),"") | C22: =IFERROR(INDEX(계정대체기준!$C$54:$C$63,MATCH($A22,계정대체기준!$A$54:$A$63,0)),"") | D22: 수금비 | E22: =$B$13*IFERROR(INDEX(계정대체기준!$F$54:$F$63,MATCH($A22,계정대체기준!$A$54:$A$63,0)),0) | F22: =SUMIFS(예정사업비!$L$5:$L$20000,예정사업비!$I$5:$I$20000,설정!$C$20,예정사업비!$C$5:$C$20000,$A22) | G22: =F22-E22 | H22: =IF(D22<>"신계약비","당기손익(보험서비스결과)",IF(C22="PAA",IF(계정대체기준!$C$68="이연 후 상각","잔여보장부채 이연(상각)","당기손익"),IF((IFERROR(INDEX(계정대체기준!$I$54:$I$63,MATCH($A22,계정대체기준!$A$54:$A$63,0)),"N")="Y"),"당기손익(손실요소)",IF(IF(계정대체기준!$C$67="전액 CSM",1,IF(계정대체기준!$C$67="전액 당기손익",0,IFERROR(INDEX(계정대체기준!$H$54:$H$63,MATCH($A22,계정대체기준!$A$54:$A$63,0)),0)))>=1,"CSM 조정 ("&C22&")",IF(IF(계정대체기준!$C$67="전액 CSM",1,IF(계정대체기준!$C$67="전액 당기손익",0,IFERROR(INDEX(계정대체기준!$H$54:$H$63,MATCH($A22,계정대체기준!$A$54:$A$63,0)),0)))<=0,"당기손익","CSM "&TEXT(IF(계정대체기준!$C$67="전액 CSM",1,IF(계정대체기준!$C$67="전액 당기손익",0,IFERROR(INDEX(계정대체기준!$H$54:$H$63,MATCH($A22,계정대체기준!$A$54:$A$63,0)),0))),"0%")&" ("&C22&") · 나머지 손익"))))) | I22: =IF(AND(D22="신계약비",OR(C22="GMM",C22="VFA"),NOT((IFERROR(INDEX(계정대체기준!$I$54:$I$63,MATCH($A22,계정대체기준!$A$54:$A$63,0)),"N")="Y"))),G22*IF(계정대체기준!$C$67="전액 CSM",1,IF(계정대체기준!$C$67="전액 당기손익",0,IFERROR(INDEX(계정대체기준!$H$54:$H$63,MATCH($A22,계정대체기준!$A$54:$A$63,0)),0))),0) | J22: =IF(AND(D22="신계약비",C22="PAA",계정대체기준!$C$68="이연 후 상각"),0,G22-I22) | L22: =IF(변동분석!$A22="","",변동분석!$E22) | M22: =IF(L22="",0,SUMIFS(전표_원본!$Z$5:$Z$100000,전표_원본!$O$5:$O$100000,L22,전표_원본!$M$5:$M$100000,설정!$C$20)) | N22: =IF(L22="",0,SUMIFS(전표_원본!$Z$5:$Z$100000,전표_원본!$O$5:$O$100000,L22,전표_원본!$M$5:$M$100000,설정!$C$20-1)) | O22: =M22-N22 | P22: =IF(L22="","",O22+ROW()/1000000)
A23: PF02 | B23: =IFERROR(INDEX(계정대체기준!$B$54:$B$63,MATCH($A23,계정대체기준!$A$54:$A$63,0)),"") | C23: =IFERROR(INDEX(계정대체기준!$C$54:$C$63,MATCH($A23,계정대체기준!$A$54:$A$63,0)),"") | D23: 신계약비 | E23: =$B$11*IFERROR(INDEX(계정대체기준!$D$54:$D$63,MATCH($A23,계정대체기준!$A$54:$A$63,0)),0) | F23: =SUMIFS(예정사업비!$J$5:$J$20000,예정사업비!$I$5:$I$20000,설정!$C$20,예정사업비!$C$5:$C$20000,$A23) | G23: =F23-E23 | H23: =IF(D23<>"신계약비","당기손익(보험서비스결과)",IF(C23="PAA",IF(계정대체기준!$C$68="이연 후 상각","잔여보장부채 이연(상각)","당기손익"),IF((IFERROR(INDEX(계정대체기준!$I$54:$I$63,MATCH($A23,계정대체기준!$A$54:$A$63,0)),"N")="Y"),"당기손익(손실요소)",IF(IF(계정대체기준!$C$67="전액 CSM",1,IF(계정대체기준!$C$67="전액 당기손익",0,IFERROR(INDEX(계정대체기준!$H$54:$H$63,MATCH($A23,계정대체기준!$A$54:$A$63,0)),0)))>=1,"CSM 조정 ("&C23&")",IF(IF(계정대체기준!$C$67="전액 CSM",1,IF(계정대체기준!$C$67="전액 당기손익",0,IFERROR(INDEX(계정대체기준!$H$54:$H$63,MATCH($A23,계정대체기준!$A$54:$A$63,0)),0)))<=0,"당기손익","CSM "&TEXT(IF(계정대체기준!$C$67="전액 CSM",1,IF(계정대체기준!$C$67="전액 당기손익",0,IFERROR(INDEX(계정대체기준!$H$54:$H$63,MATCH($A23,계정대체기준!$A$54:$A$63,0)),0))),"0%")&" ("&C23&") · 나머지 손익"))))) | I23: =IF(AND(D23="신계약비",OR(C23="GMM",C23="VFA"),NOT((IFERROR(INDEX(계정대체기준!$I$54:$I$63,MATCH($A23,계정대체기준!$A$54:$A$63,0)),"N")="Y"))),G23*IF(계정대체기준!$C$67="전액 CSM",1,IF(계정대체기준!$C$67="전액 당기손익",0,IFERROR(INDEX(계정대체기준!$H$54:$H$63,MATCH($A23,계정대체기준!$A$54:$A$63,0)),0))),0) | J23: =IF(AND(D23="신계약비",C23="PAA",계정대체기준!$C$68="이연 후 상각"),0,G23-I23) | L23: =IF(변동분석!$A23="","",변동분석!$E23) | M23: =IF(L23="",0,SUMIFS(전표_원본!$Z$5:$Z$100000,전표_원본!$O$5:$O$100000,L23,전표_원본!$M$5:$M$100000,설정!$C$20)) | N23: =IF(L23="",0,SUMIFS(전표_원본!$Z$5:$Z$100000,전표_원본!$O$5:$O$100000,L23,전표_원본!$M$5:$M$100000,설정!$C$20-1)) | O23: =M23-N23 | P23: =IF(L23="","",O23+ROW()/1000000)
A24: PF02 | B24: =IFERROR(INDEX(계정대체기준!$B$54:$B$63,MATCH($A24,계정대체기준!$A$54:$A$63,0)),"") | C24: =IFERROR(INDEX(계정대체기준!$C$54:$C$63,MATCH($A24,계정대체기준!$A$54:$A$63,0)),"") | D24: 유지비 | E24: =$B$12*IFERROR(INDEX(계정대체기준!$E$54:$E$63,MATCH($A24,계정대체기준!$A$54:$A$63,0)),0) | F24: =SUMIFS(예정사업비!$K$5:$K$20000,예정사업비!$I$5:$I$20000,설정!$C$20,예정사업비!$C$5:$C$20000,$A24) | G24: =F24-E24 | H24: =IF(D24<>"신계약비","당기손익(보험서비스결과)",IF(C24="PAA",IF(계정대체기준!$C$68="이연 후 상각","잔여보장부채 이연(상각)","당기손익"),IF((IFERROR(INDEX(계정대체기준!$I$54:$I$63,MATCH($A24,계정대체기준!$A$54:$A$63,0)),"N")="Y"),"당기손익(손실요소)",IF(IF(계정대체기준!$C$67="전액 CSM",1,IF(계정대체기준!$C$67="전액 당기손익",0,IFERROR(INDEX(계정대체기준!$H$54:$H$63,MATCH($A24,계정대체기준!$A$54:$A$63,0)),0)))>=1,"CSM 조정 ("&C24&")",IF(IF(계정대체기준!$C$67="전액 CSM",1,IF(계정대체기준!$C$67="전액 당기손익",0,IFERROR(INDEX(계정대체기준!$H$54:$H$63,MATCH($A24,계정대체기준!$A$54:$A$63,0)),0)))<=0,"당기손익","CSM "&TEXT(IF(계정대체기준!$C$67="전액 CSM",1,IF(계정대체기준!$C$67="전액 당기손익",0,IFERROR(INDEX(계정대체기준!$H$54:$H$63,MATCH($A24,계정대체기준!$A$54:$A$63,0)),0))),"0%")&" ("&C24&") · 나머지 손익"))))) | I24: =IF(AND(D24="신계약비",OR(C24="GMM",C24="VFA"),NOT((IFERROR(INDEX(계정대체기준!$I$54:$I$63,MATCH($A24,계정대체기준!$A$54:$A$63,0)),"N")="Y"))),G24*IF(계정대체기준!$C$67="전액 CSM",1,IF(계정대체기준!$C$67="전액 당기손익",0,IFERROR(INDEX(계정대체기준!$H$54:$H$63,MATCH($A24,계정대체기준!$A$54:$A$63,0)),0))),0) | J24: =IF(AND(D24="신계약비",C24="PAA",계정대체기준!$C$68="이연 후 상각"),0,G24-I24) | L24: =IF(변동분석!$A24="","",변동분석!$E24) | M24: =IF(L24="",0,SUMIFS(전표_원본!$Z$5:$Z$100000,전표_원본!$O$5:$O$100000,L24,전표_원본!$M$5:$M$100000,설정!$C$20)) | N24: =IF(L24="",0,SUMIFS(전표_원본!$Z$5:$Z$100000,전표_원본!$O$5:$O$100000,L24,전표_원본!$M$5:$M$100000,설정!$C$20-1)) | O24: =M24-N24 | P24: =IF(L24="","",O24+ROW()/1000000)
A25: PF02 | B25: =IFERROR(INDEX(계정대체기준!$B$54:$B$63,MATCH($A25,계정대체기준!$A$54:$A$63,0)),"") | C25: =IFERROR(INDEX(계정대체기준!$C$54:$C$63,MATCH($A25,계정대체기준!$A$54:$A$63,0)),"") | D25: 수금비 | E25: =$B$13*IFERROR(INDEX(계정대체기준!$F$54:$F$63,MATCH($A25,계정대체기준!$A$54:$A$63,0)),0) | F25: =SUMIFS(예정사업비!$L$5:$L$20000,예정사업비!$I$5:$I$20000,설정!$C$20,예정사업비!$C$5:$C$20000,$A25) | G25: =F25-E25 | H25: =IF(D25<>"신계약비","당기손익(보험서비스결과)",IF(C25="PAA",IF(계정대체기준!$C$68="이연 후 상각","잔여보장부채 이연(상각)","당기손익"),IF((IFERROR(INDEX(계정대체기준!$I$54:$I$63,MATCH($A25,계정대체기준!$A$54:$A$63,0)),"N")="Y"),"당기손익(손실요소)",IF(IF(계정대체기준!$C$67="전액 CSM",1,IF(계정대체기준!$C$67="전액 당기손익",0,IFERROR(INDEX(계정대체기준!$H$54:$H$63,MATCH($A25,계정대체기준!$A$54:$A$63,0)),0)))>=1,"CSM 조정 ("&C25&")",IF(IF(계정대체기준!$C$67="전액 CSM",1,IF(계정대체기준!$C$67="전액 당기손익",0,IFERROR(INDEX(계정대체기준!$H$54:$H$63,MATCH($A25,계정대체기준!$A$54:$A$63,0)),0)))<=0,"당기손익","CSM "&TEXT(IF(계정대체기준!$C$67="전액 CSM",1,IF(계정대체기준!$C$67="전액 당기손익",0,IFERROR(INDEX(계정대체기준!$H$54:$H$63,MATCH($A25,계정대체기준!$A$54:$A$63,0)),0))),"0%")&" ("&C25&") · 나머지 손익"))))) | I25: =IF(AND(D25="신계약비",OR(C25="GMM",C25="VFA"),NOT((IFERROR(INDEX(계정대체기준!$I$54:$I$63,MATCH($A25,계정대체기준!$A$54:$A$63,0)),"N")="Y"))),G25*IF(계정대체기준!$C$67="전액 CSM",1,IF(계정대체기준!$C$67="전액 당기손익",0,IFERROR(INDEX(계정대체기준!$H$54:$H$63,MATCH($A25,계정대체기준!$A$54:$A$63,0)),0))),0) | J25: =IF(AND(D25="신계약비",C25="PAA",계정대체기준!$C$68="이연 후 상각"),0,G25-I25) | L25: =IF(변동분석!$A25="","",변동분석!$E25) | M25: =IF(L25="",0,SUMIFS(전표_원본!$Z$5:$Z$100000,전표_원본!$O$5:$O$100000,L25,전표_원본!$M$5:$M$100000,설정!$C$20)) | N25: =IF(L25="",0,SUMIFS(전표_원본!$Z$5:$Z$100000,전표_원본!$O$5:$O$100000,L25,전표_원본!$M$5:$M$100000,설정!$C$20-1)) | O25: =M25-N25 | P25: =IF(L25="","",O25+ROW()/1000000)
A26: PF03 | B26: =IFERROR(INDEX(계정대체기준!$B$54:$B$63,MATCH($A26,계정대체기준!$A$54:$A$63,0)),"") | C26: =IFERROR(INDEX(계정대체기준!$C$54:$C$63,MATCH($A26,계정대체기준!$A$54:$A$63,0)),"") | D26: 신계약비 | E26: =$B$11*IFERROR(INDEX(계정대체기준!$D$54:$D$63,MATCH($A26,계정대체기준!$A$54:$A$63,0)),0) | F26: =SUMIFS(예정사업비!$J$5:$J$20000,예정사업비!$I$5:$I$20000,설정!$C$20,예정사업비!$C$5:$C$20000,$A26) | G26: =F26-E26 | H26: =IF(D26<>"신계약비","당기손익(보험서비스결과)",IF(C26="PAA",IF(계정대체기준!$C$68="이연 후 상각","잔여보장부채 이연(상각)","당기손익"),IF((IFERROR(INDEX(계정대체기준!$I$54:$I$63,MATCH($A26,계정대체기준!$A$54:$A$63,0)),"N")="Y"),"당기손익(손실요소)",IF(IF(계정대체기준!$C$67="전액 CSM",1,IF(계정대체기준!$C$67="전액 당기손익",0,IFERROR(INDEX(계정대체기준!$H$54:$H$63,MATCH($A26,계정대체기준!$A$54:$A$63,0)),0)))>=1,"CSM 조정 ("&C26&")",IF(IF(계정대체기준!$C$67="전액 CSM",1,IF(계정대체기준!$C$67="전액 당기손익",0,IFERROR(INDEX(계정대체기준!$H$54:$H$63,MATCH($A26,계정대체기준!$A$54:$A$63,0)),0)))<=0,"당기손익","CSM "&TEXT(IF(계정대체기준!$C$67="전액 CSM",1,IF(계정대체기준!$C$67="전액 당기손익",0,IFERROR(INDEX(계정대체기준!$H$54:$H$63,MATCH($A26,계정대체기준!$A$54:$A$63,0)),0))),"0%")&" ("&C26&") · 나머지 손익"))))) | I26: =IF(AND(D26="신계약비",OR(C26="GMM",C26="VFA"),NOT((IFERROR(INDEX(계정대체기준!$I$54:$I$63,MATCH($A26,계정대체기준!$A$54:$A$63,0)),"N")="Y"))),G26*IF(계정대체기준!$C$67="전액 CSM",1,IF(계정대체기준!$C$67="전액 당기손익",0,IFERROR(INDEX(계정대체기준!$H$54:$H$63,MATCH($A26,계정대체기준!$A$54:$A$63,0)),0))),0) | J26: =IF(AND(D26="신계약비",C26="PAA",계정대체기준!$C$68="이연 후 상각"),0,G26-I26) | L26: =IF(변동분석!$A26="","",변동분석!$E26) | M26: =IF(L26="",0,SUMIFS(전표_원본!$Z$5:$Z$100000,전표_원본!$O$5:$O$100000,L26,전표_원본!$M$5:$M$100000,설정!$C$20)) | N26: =IF(L26="",0,SUMIFS(전표_원본!$Z$5:$Z$100000,전표_원본!$O$5:$O$100000,L26,전표_원본!$M$5:$M$100000,설정!$C$20-1)) | O26: =M26-N26 | P26: =IF(L26="","",O26+ROW()/1000000)
A27: PF03 | B27: =IFERROR(INDEX(계정대체기준!$B$54:$B$63,MATCH($A27,계정대체기준!$A$54:$A$63,0)),"") | C27: =IFERROR(INDEX(계정대체기준!$C$54:$C$63,MATCH($A27,계정대체기준!$A$54:$A$63,0)),"") | D27: 유지비 | E27: =$B$12*IFERROR(INDEX(계정대체기준!$E$54:$E$63,MATCH($A27,계정대체기준!$A$54:$A$63,0)),0) | F27: =SUMIFS(예정사업비!$K$5:$K$20000,예정사업비!$I$5:$I$20000,설정!$C$20,예정사업비!$C$5:$C$20000,$A27) | G27: =F27-E27 | H27: =IF(D27<>"신계약비","당기손익(보험서비스결과)",IF(C27="PAA",IF(계정대체기준!$C$68="이연 후 상각","잔여보장부채 이연(상각)","당기손익"),IF((IFERROR(INDEX(계정대체기준!$I$54:$I$63,MATCH($A27,계정대체기준!$A$54:$A$63,0)),"N")="Y"),"당기손익(손실요소)",IF(IF(계정대체기준!$C$67="전액 CSM",1,IF(계정대체기준!$C$67="전액 당기손익",0,IFERROR(INDEX(계정대체기준!$H$54:$H$63,MATCH($A27,계정대체기준!$A$54:$A$63,0)),0)))>=1,"CSM 조정 ("&C27&")",IF(IF(계정대체기준!$C$67="전액 CSM",1,IF(계정대체기준!$C$67="전액 당기손익",0,IFERROR(INDEX(계정대체기준!$H$54:$H$63,MATCH($A27,계정대체기준!$A$54:$A$63,0)),0)))<=0,"당기손익","CSM "&TEXT(IF(계정대체기준!$C$67="전액 CSM",1,IF(계정대체기준!$C$67="전액 당기손익",0,IFERROR(INDEX(계정대체기준!$H$54:$H$63,MATCH($A27,계정대체기준!$A$54:$A$63,0)),0))),"0%")&" ("&C27&") · 나머지 손익"))))) | I27: =IF(AND(D27="신계약비",OR(C27="GMM",C27="VFA"),NOT((IFERROR(INDEX(계정대체기준!$I$54:$I$63,MATCH($A27,계정대체기준!$A$54:$A$63,0)),"N")="Y"))),G27*IF(계정대체기준!$C$67="전액 CSM",1,IF(계정대체기준!$C$67="전액 당기손익",0,IFERROR(INDEX(계정대체기준!$H$54:$H$63,MATCH($A27,계정대체기준!$A$54:$A$63,0)),0))),0) | J27: =IF(AND(D27="신계약비",C27="PAA",계정대체기준!$C$68="이연 후 상각"),0,G27-I27) | L27: =IF(변동분석!$A27="","",변동분석!$E27) | M27: =IF(L27="",0,SUMIFS(전표_원본!$Z$5:$Z$100000,전표_원본!$O$5:$O$100000,L27,전표_원본!$M$5:$M$100000,설정!$C$20)) | N27: =IF(L27="",0,SUMIFS(전표_원본!$Z$5:$Z$100000,전표_원본!$O$5:$O$100000,L27,전표_원본!$M$5:$M$100000,설정!$C$20-1)) | O27: =M27-N27 | P27: =IF(L27="","",O27+ROW()/1000000)
A28: PF03 | B28: =IFERROR(INDEX(계정대체기준!$B$54:$B$63,MATCH($A28,계정대체기준!$A$54:$A$63,0)),"") | C28: =IFERROR(INDEX(계정대체기준!$C$54:$C$63,MATCH($A28,계정대체기준!$A$54:$A$63,0)),"") | D28: 수금비 | E28: =$B$13*IFERROR(INDEX(계정대체기준!$F$54:$F$63,MATCH($A28,계정대체기준!$A$54:$A$63,0)),0) | F28: =SUMIFS(예정사업비!$L$5:$L$20000,예정사업비!$I$5:$I$20000,설정!$C$20,예정사업비!$C$5:$C$20000,$A28) | G28: =F28-E28 | H28: =IF(D28<>"신계약비","당기손익(보험서비스결과)",IF(C28="PAA",IF(계정대체기준!$C$68="이연 후 상각","잔여보장부채 이연(상각)","당기손익"),IF((IFERROR(INDEX(계정대체기준!$I$54:$I$63,MATCH($A28,계정대체기준!$A$54:$A$63,0)),"N")="Y"),"당기손익(손실요소)",IF(IF(계정대체기준!$C$67="전액 CSM",1,IF(계정대체기준!$C$67="전액 당기손익",0,IFERROR(INDEX(계정대체기준!$H$54:$H$63,MATCH($A28,계정대체기준!$A$54:$A$63,0)),0)))>=1,"CSM 조정 ("&C28&")",IF(IF(계정대체기준!$C$67="전액 CSM",1,IF(계정대체기준!$C$67="전액 당기손익",0,IFERROR(INDEX(계정대체기준!$H$54:$H$63,MATCH($A28,계정대체기준!$A$54:$A$63,0)),0)))<=0,"당기손익","CSM "&TEXT(IF(계정대체기준!$C$67="전액 CSM",1,IF(계정대체기준!$C$67="전액 당기손익",0,IFERROR(INDEX(계정대체기준!$H$54:$H$63,MATCH($A28,계정대체기준!$A$54:$A$63,0)),0))),"0%")&" ("&C28&") · 나머지 손익"))))) | I28: =IF(AND(D28="신계약비",OR(C28="GMM",C28="VFA"),NOT((IFERROR(INDEX(계정대체기준!$I$54:$I$63,MATCH($A28,계정대체기준!$A$54:$A$63,0)),"N")="Y"))),G28*IF(계정대체기준!$C$67="전액 CSM",1,IF(계정대체기준!$C$67="전액 당기손익",0,IFERROR(INDEX(계정대체기준!$H$54:$H$63,MATCH($A28,계정대체기준!$A$54:$A$63,0)),0))),0) | J28: =IF(AND(D28="신계약비",C28="PAA",계정대체기준!$C$68="이연 후 상각"),0,G28-I28) | L28: =IF(변동분석!$A28="","",변동분석!$E28) | M28: =IF(L28="",0,SUMIFS(전표_원본!$Z$5:$Z$100000,전표_원본!$O$5:$O$100000,L28,전표_원본!$M$5:$M$100000,설정!$C$20)) | N28: =IF(L28="",0,SUMIFS(전표_원본!$Z$5:$Z$100000,전표_원본!$O$5:$O$100000,L28,전표_원본!$M$5:$M$100000,설정!$C$20-1)) | O28: =M28-N28 | P28: =IF(L28="","",O28+ROW()/1000000)
A29: PF04 | B29: =IFERROR(INDEX(계정대체기준!$B$54:$B$63,MATCH($A29,계정대체기준!$A$54:$A$63,0)),"") | C29: =IFERROR(INDEX(계정대체기준!$C$54:$C$63,MATCH($A29,계정대체기준!$A$54:$A$63,0)),"") | D29: 신계약비 | E29: =$B$11*IFERROR(INDEX(계정대체기준!$D$54:$D$63,MATCH($A29,계정대체기준!$A$54:$A$63,0)),0) | F29: =SUMIFS(예정사업비!$J$5:$J$20000,예정사업비!$I$5:$I$20000,설정!$C$20,예정사업비!$C$5:$C$20000,$A29) | G29: =F29-E29 | H29: =IF(D29<>"신계약비","당기손익(보험서비스결과)",IF(C29="PAA",IF(계정대체기준!$C$68="이연 후 상각","잔여보장부채 이연(상각)","당기손익"),IF((IFERROR(INDEX(계정대체기준!$I$54:$I$63,MATCH($A29,계정대체기준!$A$54:$A$63,0)),"N")="Y"),"당기손익(손실요소)",IF(IF(계정대체기준!$C$67="전액 CSM",1,IF(계정대체기준!$C$67="전액 당기손익",0,IFERROR(INDEX(계정대체기준!$H$54:$H$63,MATCH($A29,계정대체기준!$A$54:$A$63,0)),0)))>=1,"CSM 조정 ("&C29&")",IF(IF(계정대체기준!$C$67="전액 CSM",1,IF(계정대체기준!$C$67="전액 당기손익",0,IFERROR(INDEX(계정대체기준!$H$54:$H$63,MATCH($A29,계정대체기준!$A$54:$A$63,0)),0)))<=0,"당기손익","CSM "&TEXT(IF(계정대체기준!$C$67="전액 CSM",1,IF(계정대체기준!$C$67="전액 당기손익",0,IFERROR(INDEX(계정대체기준!$H$54:$H$63,MATCH($A29,계정대체기준!$A$54:$A$63,0)),0))),"0%")&" ("&C29&") · 나머지 손익"))))) | I29: =IF(AND(D29="신계약비",OR(C29="GMM",C29="VFA"),NOT((IFERROR(INDEX(계정대체기준!$I$54:$I$63,MATCH($A29,계정대체기준!$A$54:$A$63,0)),"N")="Y"))),G29*IF(계정대체기준!$C$67="전액 CSM",1,IF(계정대체기준!$C$67="전액 당기손익",0,IFERROR(INDEX(계정대체기준!$H$54:$H$63,MATCH($A29,계정대체기준!$A$54:$A$63,0)),0))),0) | J29: =IF(AND(D29="신계약비",C29="PAA",계정대체기준!$C$68="이연 후 상각"),0,G29-I29) | L29: =IF(변동분석!$A29="","",변동분석!$E29) | M29: =IF(L29="",0,SUMIFS(전표_원본!$Z$5:$Z$100000,전표_원본!$O$5:$O$100000,L29,전표_원본!$M$5:$M$100000,설정!$C$20)) | N29: =IF(L29="",0,SUMIFS(전표_원본!$Z$5:$Z$100000,전표_원본!$O$5:$O$100000,L29,전표_원본!$M$5:$M$100000,설정!$C$20-1)) | O29: =M29-N29 | P29: =IF(L29="","",O29+ROW()/1000000)
A30: PF04 | B30: =IFERROR(INDEX(계정대체기준!$B$54:$B$63,MATCH($A30,계정대체기준!$A$54:$A$63,0)),"") | C30: =IFERROR(INDEX(계정대체기준!$C$54:$C$63,MATCH($A30,계정대체기준!$A$54:$A$63,0)),"") | D30: 유지비 | E30: =$B$12*IFERROR(INDEX(계정대체기준!$E$54:$E$63,MATCH($A30,계정대체기준!$A$54:$A$63,0)),0) | F30: =SUMIFS(예정사업비!$K$5:$K$20000,예정사업비!$I$5:$I$20000,설정!$C$20,예정사업비!$C$5:$C$20000,$A30) | G30: =F30-E30 | H30: =IF(D30<>"신계약비","당기손익(보험서비스결과)",IF(C30="PAA",IF(계정대체기준!$C$68="이연 후 상각","잔여보장부채 이연(상각)","당기손익"),IF((IFERROR(INDEX(계정대체기준!$I$54:$I$63,MATCH($A30,계정대체기준!$A$54:$A$63,0)),"N")="Y"),"당기손익(손실요소)",IF(IF(계정대체기준!$C$67="전액 CSM",1,IF(계정대체기준!$C$67="전액 당기손익",0,IFERROR(INDEX(계정대체기준!$H$54:$H$63,MATCH($A30,계정대체기준!$A$54:$A$63,0)),0)))>=1,"CSM 조정 ("&C30&")",IF(IF(계정대체기준!$C$67="전액 CSM",1,IF(계정대체기준!$C$67="전액 당기손익",0,IFERROR(INDEX(계정대체기준!$H$54:$H$63,MATCH($A30,계정대체기준!$A$54:$A$63,0)),0)))<=0,"당기손익","CSM "&TEXT(IF(계정대체기준!$C$67="전액 CSM",1,IF(계정대체기준!$C$67="전액 당기손익",0,IFERROR(INDEX(계정대체기준!$H$54:$H$63,MATCH($A30,계정대체기준!$A$54:$A$63,0)),0))),"0%")&" ("&C30&") · 나머지 손익"))))) | I30: =IF(AND(D30="신계약비",OR(C30="GMM",C30="VFA"),NOT((IFERROR(INDEX(계정대체기준!$I$54:$I$63,MATCH($A30,계정대체기준!$A$54:$A$63,0)),"N")="Y"))),G30*IF(계정대체기준!$C$67="전액 CSM",1,IF(계정대체기준!$C$67="전액 당기손익",0,IFERROR(INDEX(계정대체기준!$H$54:$H$63,MATCH($A30,계정대체기준!$A$54:$A$63,0)),0))),0) | J30: =IF(AND(D30="신계약비",C30="PAA",계정대체기준!$C$68="이연 후 상각"),0,G30-I30) | L30: =IF(변동분석!$A30="","",변동분석!$E30) | M30: =IF(L30="",0,SUMIFS(전표_원본!$Z$5:$Z$100000,전표_원본!$O$5:$O$100000,L30,전표_원본!$M$5:$M$100000,설정!$C$20)) | N30: =IF(L30="",0,SUMIFS(전표_원본!$Z$5:$Z$100000,전표_원본!$O$5:$O$100000,L30,전표_원본!$M$5:$M$100000,설정!$C$20-1)) | O30: =M30-N30 | P30: =IF(L30="","",O30+ROW()/1000000)
A31: PF04 | B31: =IFERROR(INDEX(계정대체기준!$B$54:$B$63,MATCH($A31,계정대체기준!$A$54:$A$63,0)),"") | C31: =IFERROR(INDEX(계정대체기준!$C$54:$C$63,MATCH($A31,계정대체기준!$A$54:$A$63,0)),"") | D31: 수금비 | E31: =$B$13*IFERROR(INDEX(계정대체기준!$F$54:$F$63,MATCH($A31,계정대체기준!$A$54:$A$63,0)),0) | F31: =SUMIFS(예정사업비!$L$5:$L$20000,예정사업비!$I$5:$I$20000,설정!$C$20,예정사업비!$C$5:$C$20000,$A31) | G31: =F31-E31 | H31: =IF(D31<>"신계약비","당기손익(보험서비스결과)",IF(C31="PAA",IF(계정대체기준!$C$68="이연 후 상각","잔여보장부채 이연(상각)","당기손익"),IF((IFERROR(INDEX(계정대체기준!$I$54:$I$63,MATCH($A31,계정대체기준!$A$54:$A$63,0)),"N")="Y"),"당기손익(손실요소)",IF(IF(계정대체기준!$C$67="전액 CSM",1,IF(계정대체기준!$C$67="전액 당기손익",0,IFERROR(INDEX(계정대체기준!$H$54:$H$63,MATCH($A31,계정대체기준!$A$54:$A$63,0)),0)))>=1,"CSM 조정 ("&C31&")",IF(IF(계정대체기준!$C$67="전액 CSM",1,IF(계정대체기준!$C$67="전액 당기손익",0,IFERROR(INDEX(계정대체기준!$H$54:$H$63,MATCH($A31,계정대체기준!$A$54:$A$63,0)),0)))<=0,"당기손익","CSM "&TEXT(IF(계정대체기준!$C$67="전액 CSM",1,IF(계정대체기준!$C$67="전액 당기손익",0,IFERROR(INDEX(계정대체기준!$H$54:$H$63,MATCH($A31,계정대체기준!$A$54:$A$63,0)),0))),"0%")&" ("&C31&") · 나머지 손익"))))) | I31: =IF(AND(D31="신계약비",OR(C31="GMM",C31="VFA"),NOT((IFERROR(INDEX(계정대체기준!$I$54:$I$63,MATCH($A31,계정대체기준!$A$54:$A$63,0)),"N")="Y"))),G31*IF(계정대체기준!$C$67="전액 CSM",1,IF(계정대체기준!$C$67="전액 당기손익",0,IFERROR(INDEX(계정대체기준!$H$54:$H$63,MATCH($A31,계정대체기준!$A$54:$A$63,0)),0))),0) | J31: =IF(AND(D31="신계약비",C31="PAA",계정대체기준!$C$68="이연 후 상각"),0,G31-I31) | L31: =IF(변동분석!$A31="","",변동분석!$E31) | M31: =IF(L31="",0,SUMIFS(전표_원본!$Z$5:$Z$100000,전표_원본!$O$5:$O$100000,L31,전표_원본!$M$5:$M$100000,설정!$C$20)) | N31: =IF(L31="",0,SUMIFS(전표_원본!$Z$5:$Z$100000,전표_원본!$O$5:$O$100000,L31,전표_원본!$M$5:$M$100000,설정!$C$20-1)) | O31: =M31-N31 | P31: =IF(L31="","",O31+ROW()/1000000)
A32: CSM 조정 (GMM 취득현금흐름 예실차) | G32: =SUMIFS($I$20:$I$31,$C$20:$C$31,"GMM") | L32: =IF(변동분석!$A32="","",변동분석!$E32) | M32: =IF(L32="",0,SUMIFS(전표_원본!$Z$5:$Z$100000,전표_원본!$O$5:$O$100000,L32,전표_원본!$M$5:$M$100000,설정!$C$20)) | N32: =IF(L32="",0,SUMIFS(전표_원본!$Z$5:$Z$100000,전표_원본!$O$5:$O$100000,L32,전표_원본!$M$5:$M$100000,설정!$C$20-1)) | O32: =M32-N32 | P32: =IF(L32="","",O32+ROW()/1000000)
A33: CSM 조정 (VFA 취득현금흐름 예실차) | G33: =SUMIFS($I$20:$I$31,$C$20:$C$31,"VFA") | L33: =IF(변동분석!$A33="","",변동분석!$E33) | M33: =IF(L33="",0,SUMIFS(전표_원본!$Z$5:$Z$100000,전표_원본!$O$5:$O$100000,L33,전표_원본!$M$5:$M$100000,설정!$C$20)) | N33: =IF(L33="",0,SUMIFS(전표_원본!$Z$5:$Z$100000,전표_원본!$O$5:$O$100000,L33,전표_원본!$M$5:$M$100000,설정!$C$20-1)) | O33: =M33-N33 | P33: =IF(L33="","",O33+ROW()/1000000)
A34: 당기손익 (유지·수금, 연동 외 신계약비, PAA) | G34: =SUM($J$20:$J$31) | L34: =IF(변동분석!$A34="","",변동분석!$E34) | M34: =IF(L34="",0,SUMIFS(전표_원본!$Z$5:$Z$100000,전표_원본!$O$5:$O$100000,L34,전표_원본!$M$5:$M$100000,설정!$C$20)) | N34: =IF(L34="",0,SUMIFS(전표_원본!$Z$5:$Z$100000,전표_원본!$O$5:$O$100000,L34,전표_원본!$M$5:$M$100000,설정!$C$20-1)) | O34: =M34-N34 | P34: =IF(L34="","",O34+ROW()/1000000)
L35: =IF(변동분석!$A35="","",변동분석!$E35) | M35: =IF(L35="",0,SUMIFS(전표_원본!$Z$5:$Z$100000,전표_원본!$O$5:$O$100000,L35,전표_원본!$M$5:$M$100000,설정!$C$20)) | N35: =IF(L35="",0,SUMIFS(전표_원본!$Z$5:$Z$100000,전표_원본!$O$5:$O$100000,L35,전표_원본!$M$5:$M$100000,설정!$C$20-1)) | O35: =M35-N35 | P35: =IF(L35="","",O35+ROW()/1000000)
L36: =IF(변동분석!$A36="","",변동분석!$E36) | M36: =IF(L36="",0,SUMIFS(전표_원본!$Z$5:$Z$100000,전표_원본!$O$5:$O$100000,L36,전표_원본!$M$5:$M$100000,설정!$C$20)) | N36: =IF(L36="",0,SUMIFS(전표_원본!$Z$5:$Z$100000,전표_원본!$O$5:$O$100000,L36,전표_원본!$M$5:$M$100000,설정!$C$20-1)) | O36: =M36-N36 | P36: =IF(L36="","",O36+ROW()/1000000)
A37: 3. 변동표 대사 (계리 결과 '경험조정-취득현금흐름' CSM vs TRACE CSM 반영분) | L37: =IF(변동분석!$A37="","",변동분석!$E37) | M37: =IF(L37="",0,SUMIFS(전표_원본!$Z$5:$Z$100000,전표_원본!$O$5:$O$100000,L37,전표_원본!$M$5:$M$100000,설정!$C$20)) | N37: =IF(L37="",0,SUMIFS(전표_원본!$Z$5:$Z$100000,전표_원본!$O$5:$O$100000,L37,전표_원본!$M$5:$M$100000,설정!$C$20-1)) | O37: =M37-N37 | P37: =IF(L37="","",O37+ROW()/1000000)
A38: 포트폴리오 | B38: 측정모형 | C38: 계리 F31 (CSM) | D38: TRACE 추정 (CSM 반영분) | E38: 차이 | F38: 판정 | L38: =IF(변동분석!$A38="","",변동분석!$E38) | M38: =IF(L38="",0,SUMIFS(전표_원본!$Z$5:$Z$100000,전표_원본!$O$5:$O$100000,L38,전표_원본!$M$5:$M$100000,설정!$C$20)) | N38: =IF(L38="",0,SUMIFS(전표_원본!$Z$5:$Z$100000,전표_원본!$O$5:$O$100000,L38,전표_원본!$M$5:$M$100000,설정!$C$20-1)) | O38: =M38-N38 | P38: =IF(L38="","",O38+ROW()/1000000)
A39: PF01 | B39: =IFERROR(INDEX(계정대체기준!$C$54:$C$63,MATCH($A39,계정대체기준!$A$54:$A$63,0)),"") | C39: =SUMIFS(부채변동표!$O$5:$O$20000,부채변동표!$L$5:$L$20000,설정!$C$20,부채변동표!$C$5:$C$20000,$A39,부채변동표!$P$5:$P$20000,"F31") | D39: =IF(B39="PAA",0,SUMIFS($I$20:$I$31,$A$20:$A$31,$A39,$D$20:$D$31,"신계약비")) | E39: =C39-D39 | F39: =IF(B39="PAA","해당없음 (CSM 없음)",IF(ABS(E39)<0.5,"일치","차이 확인")) | L39: =IF(변동분석!$A39="","",변동분석!$E39) | M39: =IF(L39="",0,SUMIFS(전표_원본!$Z$5:$Z$100000,전표_원본!$O$5:$O$100000,L39,전표_원본!$M$5:$M$100000,설정!$C$20)) | N39: =IF(L39="",0,SUMIFS(전표_원본!$Z$5:$Z$100000,전표_원본!$O$5:$O$100000,L39,전표_원본!$M$5:$M$100000,설정!$C$20-1)) | O39: =M39-N39 | P39: =IF(L39="","",O39+ROW()/1000000)
A40: PF02 | B40: =IFERROR(INDEX(계정대체기준!$C$54:$C$63,MATCH($A40,계정대체기준!$A$54:$A$63,0)),"") | C40: =SUMIFS(부채변동표!$O$5:$O$20000,부채변동표!$L$5:$L$20000,설정!$C$20,부채변동표!$C$5:$C$20000,$A40,부채변동표!$P$5:$P$20000,"F31") | D40: =IF(B40="PAA",0,SUMIFS($I$20:$I$31,$A$20:$A$31,$A40,$D$20:$D$31,"신계약비")) | E40: =C40-D40 | F40: =IF(B40="PAA","해당없음 (CSM 없음)",IF(ABS(E40)<0.5,"일치","차이 확인")) | L40: =IF(변동분석!$A40="","",변동분석!$E40) | M40: =IF(L40="",0,SUMIFS(전표_원본!$Z$5:$Z$100000,전표_원본!$O$5:$O$100000,L40,전표_원본!$M$5:$M$100000,설정!$C$20)) | N40: =IF(L40="",0,SUMIFS(전표_원본!$Z$5:$Z$100000,전표_원본!$O$5:$O$100000,L40,전표_원본!$M$5:$M$100000,설정!$C$20-1)) | O40: =M40-N40 | P40: =IF(L40="","",O40+ROW()/1000000)
A41: PF03 | B41: =IFERROR(INDEX(계정대체기준!$C$54:$C$63,MATCH($A41,계정대체기준!$A$54:$A$63,0)),"") | C41: =SUMIFS(부채변동표!$O$5:$O$20000,부채변동표!$L$5:$L$20000,설정!$C$20,부채변동표!$C$5:$C$20000,$A41,부채변동표!$P$5:$P$20000,"F31") | D41: =IF(B41="PAA",0,SUMIFS($I$20:$I$31,$A$20:$A$31,$A41,$D$20:$D$31,"신계약비")) | E41: =C41-D41 | F41: =IF(B41="PAA","해당없음 (CSM 없음)",IF(ABS(E41)<0.5,"일치","차이 확인")) | L41: =IF(변동분석!$A41="","",변동분석!$E41) | M41: =IF(L41="",0,SUMIFS(전표_원본!$Z$5:$Z$100000,전표_원본!$O$5:$O$100000,L41,전표_원본!$M$5:$M$100000,설정!$C$20)) | N41: =IF(L41="",0,SUMIFS(전표_원본!$Z$5:$Z$100000,전표_원본!$O$5:$O$100000,L41,전표_원본!$M$5:$M$100000,설정!$C$20-1)) | O41: =M41-N41 | P41: =IF(L41="","",O41+ROW()/1000000)
...

Sheet 리포트
A1: =설정!$C$5&" TRACE 사업비 변동 점검 ("&INT((설정!$C$20-1)/12)&"-"&TEXT(MOD(설정!$C$20-1,12)+1,"00")&")"
A2: ="단위: "&설정!$C$9&" · 전표·TB·예산판 대사: "&계정변동!$P$25&" · 자가진단: "&자가진단!$B$4
A4: 사업비 당월 | B4: 전월 대비 | C4: 전년동월 대비 | D4: 분기 한도 초과(예상) | E4: 분기 한도 주의 | F4: 무예산 집행
A5: =월별집계!Z6 | B5: =IF(월별집계!Y6<=0,0,월별집계!Z6/월별집계!Y6-1) | C5: =IF(월별집계!N6<=0,0,월별집계!Z6/월별집계!N6-1) | D5: =COUNTIF(변동분석!$AO$7:$AO$506,"한도 초과")+COUNTIF(변동분석!$AO$7:$AO$506,"초과 예상") | E5: =COUNTIF(변동분석!$AO$7:$AO$506,"주의") | F5: =COUNTIF(변동분석!$AO$7:$AO$506,"무예산")
A7: 1. 주의 대상 TOP 10
A8: 순위 | B8: 부서 | C8: 계정 | D8: 당월 | E8: 전월대비 | F8: 예산 | G8: 빠른 신호 | H8: 확인된 원인
A9: =주의대상!A6 | B9: =주의대상!B6 | C9: =주의대상!C6 | D9: =주의대상!D6 | E9: =주의대상!E6 | F9: =주의대상!G6 | G9: =주의대상!J6 | H9: =주의대상!M6
A10: =주의대상!A7 | B10: =주의대상!B7 | C10: =주의대상!C7 | D10: =주의대상!D7 | E10: =주의대상!E7 | F10: =주의대상!G7 | G10: =주의대상!J7 | H10: =주의대상!M7
A11: =주의대상!A8 | B11: =주의대상!B8 | C11: =주의대상!C8 | D11: =주의대상!D8 | E11: =주의대상!E8 | F11: =주의대상!G8 | G11: =주의대상!J8 | H11: =주의대상!M8
A12: =주의대상!A9 | B12: =주의대상!B9 | C12: =주의대상!C9 | D12: =주의대상!D9 | E12: =주의대상!E9 | F12: =주의대상!G9 | G12: =주의대상!J9 | H12: =주의대상!M9
A13: =주의대상!A10 | B13: =주의대상!B10 | C13: =주의대상!C10 | D13: =주의대상!D10 | E13: =주의대상!E10 | F13: =주의대상!G10 | G13: =주의대상!J10 | H13: =주의대상!M10
A14: =주의대상!A11 | B14: =주의대상!B11 | C14: =주의대상!C11 | D14: =주의대상!D11 | E14: =주의대상!E11 | F14: =주의대상!G11 | G14: =주의대상!J11 | H14: =주의대상!M11
A15: =주의대상!A12 | B15: =주의대상!B12 | C15: =주의대상!C12 | D15: =주의대상!D12 | E15: =주의대상!E12 | F15: =주의대상!G12 | G15: =주의대상!J12 | H15: =주의대상!M12
A16: =주의대상!A13 | B16: =주의대상!B13 | C16: =주의대상!C13 | D16: =주의대상!D13 | E16: =주의대상!E13 | F16: =주의대상!G13 | G16: =주의대상!J13 | H16: =주의대상!M13
A17: =주의대상!A14 | B17: =주의대상!B14 | C17: =주의대상!C14 | D17: =주의대상!D14 | E17: =주의대상!E14 | F17: =주의대상!G14 | G17: =주의대상!J14 | H17: =주의대상!M14
A18: =주의대상!A15 | B18: =주의대상!B15 | C18: =주의대상!C15 | D18: =주의대상!D15 | E18: =주의대상!E15 | F18: =주의대상!G15 | G18: =주의대상!J15 | H18: =주의대상!M15
A20: 2. 원인 분석 (원인분석 시트에서 선택한 항목)
A21: =원인분석!A18
A22: 순위 | B22: 패턴 | C22: 근거 강도 | D22: 설명
A23: =원인분석!A21 | B23: =원인분석!B21 | C23: =원인분석!C21 | D23: =원인분석!D21
A24: =원인분석!A22 | B24: =원인분석!B22 | C24: =원인분석!C22 | D24: =원인분석!D22
A25: =원인분석!A23 | B25: =원인분석!B23 | C25: =원인분석!C23 | D25: =원인분석!D23
A26: =원인분석!A24 | B26: =원인분석!B24 | C26: =원인분석!C24 | D26: =원인분석!D24
A28: 3. 월별 사업비 (전사, 당해 vs 전년)
K29: 월 | L29: =설정!$C$6&"년" | M29: =설정!$C$6-1&"년"
K30: 1월 | L30: =IF(1>설정!$C$7,0,SUMIFS(전표_원본!$P$5:$P$100000,전표_원본!$M$5:$M$100000,설정!$C$6*12+1)) | M30: =SUMIFS(전표_원본!$P$5:$P$100000,전표_원본!$M$5:$M$100000,(설정!$C$6-1)*12+1)
K31: 2월 | L31: =IF(2>설정!$C$7,0,SUMIFS(전표_원본!$P$5:$P$100000,전표_원본!$M$5:$M$100000,설정!$C$6*12+2)) | M31: =SUMIFS(전표_원본!$P$5:$P$100000,전표_원본!$M$5:$M$100000,(설정!$C$6-1)*12+2)
K32: 3월 | L32: =IF(3>설정!$C$7,0,SUMIFS(전표_원본!$P$5:$P$100000,전표_원본!$M$5:$M$100000,설정!$C$6*12+3)) | M32: =SUMIFS(전표_원본!$P$5:$P$100000,전표_원본!$M$5:$M$100000,(설정!$C$6-1)*12+3)
K33: 4월 | L33: =IF(4>설정!$C$7,0,SUMIFS(전표_원본!$P$5:$P$100000,전표_원본!$M$5:$M$100000,설정!$C$6*12+4)) | M33: =SUMIFS(전표_원본!$P$5:$P$100000,전표_원본!$M$5:$M$100000,(설정!$C$6-1)*12+4)
K34: 5월 | L34: =IF(5>설정!$C$7,0,SUMIFS(전표_원본!$P$5:$P$100000,전표_원본!$M$5:$M$100000,설정!$C$6*12+5)) | M34: =SUMIFS(전표_원본!$P$5:$P$100000,전표_원본!$M$5:$M$100000,(설정!$C$6-1)*12+5)
K35: 6월 | L35: =IF(6>설정!$C$7,0,SUMIFS(전표_원본!$P$5:$P$100000,전표_원본!$M$5:$M$100000,설정!$C$6*12+6)) | M35: =SUMIFS(전표_원본!$P$5:$P$100000,전표_원본!$M$5:$M$100000,(설정!$C$6-1)*12+6)
K36: 7월 | L36: =IF(7>설정!$C$7,0,SUMIFS(전표_원본!$P$5:$P$100000,전표_원본!$M$5:$M$100000,설정!$C$6*12+7)) | M36: =SUMIFS(전표_원본!$P$5:$P$100000,전표_원본!$M$5:$M$100000,(설정!$C$6-1)*12+7)
K37: 8월 | L37: =IF(8>설정!$C$7,0,SUMIFS(전표_원본!$P$5:$P$100000,전표_원본!$M$5:$M$100000,설정!$C$6*12+8)) | M37: =SUMIFS(전표_원본!$P$5:$P$100000,전표_원본!$M$5:$M$100000,(설정!$C$6-1)*12+8)
K38: 9월 | L38: =IF(9>설정!$C$7,0,SUMIFS(전표_원본!$P$5:$P$100000,전표_원본!$M$5:$M$100000,설정!$C$6*12+9)) | M38: =SUMIFS(전표_원본!$P$5:$P$100000,전표_원본!$M$5:$M$100000,(설정!$C$6-1)*12+9)
K39: 10월 | L39: =IF(10>설정!$C$7,0,SUMIFS(전표_원본!$P$5:$P$100000,전표_원본!$M$5:$M$100000,설정!$C$6*12+10)) | M39: =SUMIFS(전표_원본!$P$5:$P$100000,전표_원본!$M$5:$M$100000,(설정!$C$6-1)*12+10)
K40: 11월 | L40: =IF(11>설정!$C$7,0,SUMIFS(전표_원본!$P$5:$P$100000,전표_원본!$M$5:$M$100000,설정!$C$6*12+11)) | M40: =SUMIFS(전표_원본!$P$5:$P$100000,전표_원본!$M$5:$M$100000,(설정!$C$6-1)*12+11)
K41: 12월 | L41: =IF(12>설정!$C$7,0,SUMIFS(전표_원본!$P$5:$P$100000,전표_원본!$M$5:$M$100000,설정!$C$6*12+12)) | M41: =SUMIFS(전표_원본!$P$5:$P$100000,전표_원본!$M$5:$M$100000,(설정!$C$6-1)*12+12)

Sheet 주의대상
A1: TRACE · 주의 대상 TOP 10
A2: 점수 = 증가액(30) + 증가율(20) + 이상치(25) + 예산(25), 작은 금액은 30%로 낮춤 · 원인은 원인분석 시트 C5에 순위 입력
A3: ="기준: "&INT((설정!$C$20-1)/12)&"-"&TEXT(MOD(설정!$C$20-1,12)+1,"00")&" · 단위: "&설정!$C$9&" · 분기 한도 초과 "&COUNTIF(변동분석!$AO$7:$AO$506,"한도 초과")&"건 · 초과 예상 "&COUNTIF(변동분석!$AO$7:$AO$506,"초과 예상")&"건 · 주의 "&COUNTIF(변동분석!$AO$7:$AO$506,"주의")&"건 · 무예산 "&COUNTIF(변동분석!$AO$7:$AO$506,"무예산")&"건"
S4: 고갈 추세 (대시보드 주의 대상 상세 그래프용)
