Workbook

Sheet 안내
A1: TRACE 사업비 원인추적기 v0.2 (프로토타입)
A2: Excel 2016 호환 · 수식만으로 동작 · 예시 데이터는 가상 수치 (원본 단위: 원, 보고 단위: 백만원)
A4: 이름의 뜻
A5: 글자 | B5: 뜻 | C5: 도구에서 하는 일 (시트)
A6: T | B6: Trend 추이 | C6: 전월·전분기·전년동월 대비 변동 (변동분석 · 월별집계 · 계정변동)
A7: R | B7: Risk 예산 위험 | C7: 예상 연간 실적으로 여유/주의/부족 예상 판정 (변동분석 P~Y열)
A8: A | B8: Anomaly 이상치 | C8: 평소 변동폭을 벗어난 항목을 점수로 골라냄 (주의대상)
A9: C | B9: Cause 원인 | C9: 증가분을 거래처·전표로 쪼개 원인 후보와 근거 전표 제시 (원인분석 · 키워드사전)
A10: E | B10: Expense 사업비 | C10: 분석 대상: 사업비 계정 (계정매핑에서 사업비 여부 Y)
A12: 흐름 단계와 시트
A13: 단계 | B13: 하는 일 | C13: 시트
A14: ① 세 파일 넣기 | B14: SAP 예산판·TB·전표를 원본 시트 A열부터 붙여넣기 | C14: 예산판_원본 · TB_원본 · 전표_원본
A15: ② 불러오기·대사 | B15: 매핑 적용, 전표 = TB = 예산판 실적 대사, 데이터 점검 | C15: 자가진단 · 계정변동
A16: ③ 변동 분석 | B16: 전월·전분기·전년동월 대비 증감 (부서 × 계정) | C16: 변동분석 F~O열 · 월별집계 · 계정변동
A17: ④ 예산 점검 | B17: 배정+조정 대비 예상 연간 실적 → 여유/주의/부족 예상 | C17: 변동분석 P~Y열
A18: ⑤ 주의 대상 | B18: 증가액·증가율·이상치·예산 점수 합산 → TOP 10 | C18: 주의대상 · 변동분석 AA열 이후
A19: ⑥ 원인 추정 | B19: 선택 항목을 거래처·전표로 분해, 8가지 패턴 판정, 근거 전표 | C19: 원인분석 · 키워드사전
A20: ⑦ 보고·확인 | B20: 보고서, 확인된 원인을 코멘트로 누적 | C20: 리포트 · 코멘트
A22: 매월 사용 순서
A23: 1. 설정 시트에서 기준연도·기준월 변경
A24: 2. 원본 시트 3개에 새 데이터 붙여넣기 (회색 머리글 보조수식 열은 데이터 마지막 행까지 끌어 채우기)
A25: 3. 자가진단이 '전체 정상'인지 확인
A26: 4. 주의대상 TOP 10 확인 → 원인분석 시트 C5에 순위 입력 (비교 기준은 C6) → 원인 후보와 근거 전표 확인
A27: 5. 담당 부서 확인 결과를 코멘트 시트에 입력 → 주의대상·리포트에 표시
A28: 6. 새로 알게 된 적요 표현은 키워드사전에 추가 → 다음 달 원인 추정에 반영
A30: 원본 데이터 기준
A31: 예산판: 부서 × G/L × 분기 한 행 (배정·조정·실적·잔여). 화면이 분기를 옆으로 펼치는 형태면 알려주세요. 양식을 맞추겠습니다.
A32: TB: G/L × 월 한 행 (당기차변·당기대변·기말잔액). 당해와 전년을 함께 넣어야 전년동월 비교가 됩니다.
A33: 전표: 사업비 계정 전표 라인 (최근 24개월 권장). 적요·거래처가 있어야 원인 추정이 됩니다.
A34: 거래처명이 '('로 시작하면 내부 거래(법인카드·내부대체 등)로 보고 신규 거래처 판정에서 뺍니다.
... A42: 원인 후보는 규칙 기반 가설입니다. 반드시 근거 전표와 담당 부서 확인으로 확정하세요.

Sheet 설정
A1: TRACE · 설정
A2: 노란 칸만 바꾸세요
B4: 항목 | C4: 값 | D4: 설명 | F4: 단위 | G4: 원 환산
B5: 회사명 | C5: 예시보험㈜ | F5: 원 | G5: 1
B6: 기준연도 | C6: 2026 | F6: 천원 | G6: 1000
B7: 기준월 | C7: 9 | D7: 1~12 | F7: 백만원 | G7: 1000000
B8: 원본 금액단위 | C8: 원 | D8: 예산판·TB·전표 공통
B9: 보고 단위 | C9: 백만원 | D9: 모든 분석 표시 단위
B10: 증감 기준금액 (보고단위) | C10: 10 | D10: 이 금액 미만의 작은 증감은 주의 점수를 30%로 낮춤 · 증가액 점수 만점 = 5배
B11: 예산 '주의' 기준 (예상 소진율) | C11: 0.9 | D11: 예상 연간 실적 ÷ 가용예산이 이 값 초과면 주의
B12: 예산 '부족 예상' 기준 | C12: 1 | D12: 이 값 초과면 부족 예상
B13: 이상치 기준 (z) | C13: 2 | D13: 직전 12개월 평균 대비 표준편차 배수
B14: 원인: 단건 비중 | C14: 0.5 | D14: 전표 1건이 증가분의 이 비율 이상이면 '일회성 대형'
B15: 원인: 신규 거래처 비중 | C15: 0.3 | D15: 최근 12개월 거래 없던 거래처의 증가분 비중
B16: 원인: SA 대체 비중 | C16: 0.3 | D16: 수기 대체전표(SA) 순증의 증가분 비중
B17: 원인: 키워드 비중 | C17: 0.3 | D17: 키워드사전 해당 전표의 증가분 비중
B18: 원인: 단가 상승률 | C18: 0.05 | D18: 같은 건수에서 이 비율 이상 오르면 '단가 인상'
B20: (계산) 기준 기간번호 | C20: =C6*12+C7 | D20: 연도×12+월. 기간 비교에 사용
B21: (계산) 기준 분기 | C21: =ROUNDUP(C7/3,0)
B22: (계산) 분기 시작 기간번호 | C22: =C6*12+(C21-1)*3+1
B23: (계산) 금액 환산계수 | C23: =INDEX($G$5:$G$7,MATCH(C8,$F$5:$F$7,0))/INDEX($G$5:$G$7,MATCH(C9,$F$5:$F$7,0)) | D23: 원본 금액 × 계수 = 보고단위

Sheet 자가진단
A1: TRACE · 자가진단
A2: 외부망으로 오류를 알릴 때는 [점검 항목]과 [상태]만 전달하세요
A4: 종합 | B4: =IF(COUNTIF(D7:D24,"확인필요")=0,"전체 정상"&IF(COUNTIF(D7:D24,"참고")>0," (참고 "&COUNTIF(D7:D24,"참고")&"건)",""),"확인필요 "&COUNTIF(D7:D24,"확인필요")&"건")
A6: No | B6: 점검 항목 | C6: 결과 | D6: 상태 | E6: 조치 방법
A7: 1 | B7: 설정값 | C7: =IF(AND(ISNUMBER(설정!$C$7),설정!$C$7>=1,설정!$C$7<=12,ISNUMBER(설정!$C$23)),"정상","기준월 또는 단위 오류") | D7: =IF(C7="정상","OK","확인필요") | E7: 설정 시트 기준월(1~12)·단위 확인
A8: 2 | B8: 전표_원본 머리글 | C8: =IF(IF(전표_원본!A4<>"회계연도","A ","")&IF(전표_원본!B4<>"기간","B ","")&IF(전표_원본!C4<>"전표번호","C ","")&IF(전표_원본!D4<>"전기일","D ","")&IF(전표_원본!E4<>"전표유형","E ","")&IF(전표_원본!F4<>"G/L계정","F ","")&IF(전표_원본!G4<>"코스트센터","G ","")&IF(전표_원본!H4<>"금액","H ","")&IF(전표_원본!I4<>"적요","I ","")&IF(전표_원본!J4<>"거래처코드","J ","")&IF(전표_원본!K4<>"거래처명","K ","")="","일치","불일치 열: "&IF(전표_원본!A4<>"회계연도","A ","")&IF(전표_원본!B4<>"기간","B ","")&IF(전표_원본!C4<>"전표번호","C ","")&IF(전표_원본!D4<>"전기일","D ","")&IF(전표_원본!E4<>"전표유형","E ","")&IF(전표_원본!F4<>"G/L계정","F ","")&IF(전표_원본!G4<>"코스트센터","G ","")&IF(전표_원본!H4<>"금액","H ","")&IF(전표_원본!I4<>"적요","I ","")&IF(전표_원본!J4<>"거래처코드","J ","")&IF(전표_원본!K4<>"거래처명","K ","")) | D8: =IF(C8="일치","OK","확인필요") | E8: 4행 머리글을 표준 이름으로
A9: 3 | B9: TB_원본 머리글 | C9: =IF(IF(TB_원본!A4<>"회계연도","A ","")&IF(TB_원본!B4<>"기간","B ","")&IF(TB_원본!C4<>"G/L계정","C ","")&IF(TB_원본!D4<>"계정명","D ","")&IF(TB_원본!E4<>"당기차변","E ","")&IF(TB_원본!F4<>"당기대변","F ","")&IF(TB_원본!G4<>"기말잔액","G ","")="","일치","불일치 열: "&IF(TB_원본!A4<>"회계연도","A ","")&IF(TB_원본!B4<>"기간","B ","")&IF(TB_원본!C4<>"G/L계정","C ","")&IF(TB_원본!D4<>"계정명","D ","")&IF(TB_원본!E4<>"당기차변","E ","")&IF(TB_원본!F4<>"당기대변","F ","")&IF(TB_원본!G4<>"기말잔액","G ","")) | D9: =IF(C9="일치","OK","확인필요") | E9: 4행 머리글을 표준 이름으로
A10: 4 | B10: 예산판_원본 머리글 | C10: =IF(IF(예산판_원본!A4<>"회계연도","A ","")&IF(예산판_원본!B4<>"부서코드","B ","")&IF(예산판_원본!C4<>"부서명","C ","")&IF(예산판_원본!D4<>"G/L계정","D ","")&IF(예산판_원본!E4<>"계정명","E ","")&IF(예산판_원본!F4<>"분기","F ","")&IF(예산판_원본!G4<>"배정","G ","")&IF(예산판_원본!H4<>"조정","H ","")&IF(예산판_원본!I4<>"실적","I ","")&IF(예산판_원본!J4<>"잔여","J ","")="","일치","불일치 열: "&IF(예산판_원본!A4<>"회계연도","A ","")&IF(예산판_원본!B4<>"부서코드","B ","")&IF(예산판_원본!C4<>"부서명","C ","")&IF(예산판_원본!D4<>"G/L계정","D ","")&IF(예산판_원본!E4<>"계정명","E ","")&IF(예산판_원본!F4<>"분기","F ","")&IF(예산판_원본!G4<>"배정","G ","")&IF(예산판_원본!H4<>"조정","H ","")&IF(예산판_원본!I4<>"실적","I ","")&IF(예산판_원본!J4<>"잔여","J ","")) | D10: =IF(C10="일치","OK","확인필요") | E10: 4행 머리글을 표준 이름으로
A11: 5 | B11: 전표 보조수식 범위 | C11: =COUNTA(전표_원본!A5:A100000)&"행 / 보조 "&COUNTA(전표_원본!O5:O100000)&"행" | D11: =IF(COUNTA(전표_원본!O5:O100000)>=COUNTA(전표_원본!A5:A100000),"OK","확인필요") | E11: M~X열을 데이터 마지막 행까지 채우기
A12: 6 | B12: TB 보조수식 범위 | C12: =COUNTA(TB_원본!A5:A20000)&"행 / 보조 "&COUNTA(TB_원본!I5:I20000)&"행" | D12: =IF(COUNTA(TB_원본!I5:I20000)>=COUNTA(TB_원본!A5:A20000),"OK","확인필요") | E12: I~K열을 데이터 마지막 행까지 채우기
A13: 7 | B13: 예산판 보조수식 범위 | C13: =COUNTA(예산판_원본!A5:A5000)&"행 / 보조 "&COUNTA(예산판_원본!L5:L5000)&"행" | D13: =IF(COUNTA(예산판_원본!L5:L5000)>=COUNTA(예산판_원본!A5:A5000),"OK","확인필요") | E13: L~R열을 데이터 마지막 행까지 채우기
A14: 8 | B14: 기준월 전표 존재 | C14: =COUNTIF(전표_원본!$M$5:$M$100000,설정!$C$20)&"건" | D14: =IF(COUNTIF(전표_원본!$M$5:$M$100000,설정!$C$20)>0,"OK","확인필요") | E14: 기준월 전표가 들어 있는지 확인
A15: 9 | B15: 기준월 TB 존재 | C15: =COUNTIF(TB_원본!$I$5:$I$20000,설정!$C$20)&"행" | D15: =IF(COUNTIF(TB_원본!$I$5:$I$20000,설정!$C$20)>0,"OK","확인필요") | E15: 기준월 TB가 들어 있는지 확인
A16: 10 | B16: 전년 동월 전표 존재 | C16: =COUNTIF(전표_원본!$M$5:$M$100000,설정!$C$20-12)&"건" | D16: =IF(COUNTIF(전표_원본!$M$5:$M$100000,설정!$C$20-12)>0,"OK","참고") | E16: 전년동월 비교·이상치 판정에 필요 (최근 24개월 권장)
A17: 11 | B17: 미매핑 코스트센터 | C17: =COUNTIF(전표_원본!$N$5:$N$100000,"미매핑")&"건"&IF(COUNTIF(전표_원본!$N$5:$N$100000,"미매핑")>0," (예: "&INDEX(전표_원본!$G$5:$G$100000,MATCH("미매핑",전표_원본!$N$5:$N$100000,0))&")","") | D17: =IF(COUNTIF(전표_원본!$N$5:$N$100000,"미매핑")=0,"OK","확인필요") | E17: 부서매핑에 코스트센터 추가
A18: 12 | B18: 미매핑 G/L 계정 | C18: =COUNTIF(전표_원본!$W$5:$W$100000,"미매핑")&"건"&IF(COUNTIF(전표_원본!$W$5:$W$100000,"미매핑")>0," (예: "&INDEX(전표_원본!$F$5:$F$100000,MATCH("미매핑",전표_원본!$W$5:$W$100000,0))&")","") | D18: =IF(COUNTIF(전표_원본!$W$5:$W$100000,"미매핑")=0,"OK","확인필요") | E18: 계정매핑에 계정 추가
A19: 13 | B19: TB ↔ 전표 당월 대사 | C19: ="차이 "&TEXT(계정변동!L22,"#,##0.0") | D19: =IF(ABS(계정변동!L22)<0.05,"OK","확인필요") | E19: 계정변동 시트에서 차이 나는 계정 확인 (전표 추출 범위 누락 등)
A20: 14 | B20: 예산판 ↔ 전표 당분기 대사 | C20: ="차이 "&TEXT(계정변동!O22,"#,##0.0") | D20: =IF(ABS(계정변동!O22)<0.05,"OK","확인필요") | E20: 예산판 추출 시점과 전표 기간 일치 여부 확인
A21: 15 | B21: 변동분석에 없는 조합 (전표) | C21: =COUNTIFS(전표_원본!$V$5:$V$100000,"N",전표_원본!$A$5:$A$100000,설정!$C$6)&"건" | D21: =IF(COUNTIFS(전표_원본!$V$5:$V$100000,"N",전표_원본!$A$5:$A$100000,설정!$C$6)=0,"OK","확인필요") | E21: 변동분석에 부서코드·G/L 행 추가
A22: 16 | B22: 변동분석에 없는 조합 (예산판) | C22: =COUNTIFS(예산판_원본!$Q$5:$Q$5000,"N",예산판_원본!$M$5:$M$5000,설정!$C$6)&"행" | D22: =IF(COUNTIFS(예산판_원본!$Q$5:$Q$5000,"N",예산판_원본!$M$5:$M$5000,설정!$C$6)=0,"OK","확인필요") | E22: 변동분석에 부서코드·G/L 행 추가
A23: 17 | B23: 무예산 집행 | C23: =COUNTIF(변동분석!$W$7:$W$506,"무예산")&"건" | D23: =IF(COUNTIF(변동분석!$W$7:$W$506,"무예산")=0,"OK","참고") | E23: 업무상 예외 - 전용·추가 배정 여부 확인
A24: 18 | B24: 원인분석 선택 항목 | C24: =원인분석!$E$9&" · 당기 전표 "&COUNTIF(전표_원본!$Q$5:$Q$100000,"당기")&"건" | D24: =IF(COUNTIF(전표_원본!$Q$5:$Q$100000,"당기")>0,"OK","참고") | E24: 원인분석 C5~C8 선택값 확인

Sheet 리포트
A1: =설정!$C$5&" TRACE 사업비 변동 점검 ("&INT((설정!$C$20-1)/12)&"-"&TEXT(MOD(설정!$C$20-1,12)+1,"00")&")"
A2: ="단위: "&설정!$C$9&" · 전표·TB·예산판 대사: "&계정변동!$P$22&" · 자가진단: "&자가진단!$B$4
A4: 사업비 당월 | B4: 전월 대비 | C4: 전년동월 대비 | D4: 예산 부족 예상 | E4: 예산 주의 | F4: 무예산 집행
A5: =월별집계!Z6 | B5: =IF(월별집계!Y6<=0,0,월별집계!Z6/월별집계!Y6-1) | C5: =IF(월별집계!N6<=0,0,월별집계!Z6/월별집계!N6-1) | D5: =COUNTIF(변동분석!$W$7:$W$506,"부족 예상") | E5: =COUNTIF(변동분석!$W$7:$W$506,"주의") | F5: =COUNTIF(변동분석!$W$7:$W$506,"무예산")
A7: 1. 주의 대상 TOP 10
A8: 순위 | B8: 부서 | C8: 계정 | D8: 당월 | E8: 전월대비 | F8: 예산 | G8: 빠른 신호 | H8: 확인된 원인
A9: =주의대상!A6 | B9: =주의대상!B6 | C9: =주의대상!C6 | D9: =주의대상!D6 | E9: =주의대상!E6 | F9: =주의대상!G6 | G9: =주의대상!J6 | H9: =주의대상!M6
A10: =주의대상!A7 | B10: =주의대상!B7 | C10: =주의대상!C7 | D10: =주의대상!D7 | E10: =주의대상!E7 | F10: =주의대상!G7 | G10: =주의대상!J7 | H10: =주의대상!M7
A11: =주의대상!A8 | B11: =주의대상!B8 | C11: =주의대상!C8 | D11: =주의대상!D8 | E11: =주의대상!E8 | F11: =주의대상!G8 | G11: =주의대상!J8 | H11: =주의대상!M8
A12: =주의대상!A9 | B12: =주의대상!B9 | C12: =주의대상!C9 | D12: =주의대상!D9 | E12: =주의대상!E9 | F12: =주의대상!G9 | G12: =주의대상!J9 | H12: =주의대상!M9
A13: =주의대상!A10 | B13: =주의대상!B10 | C13: =주의대상!C10 | D13: =주의대상!D10 | E13: =주의대상!E10 | F13: =주의대상!G10 | G13: =주의대상!J10 | H13: =주의대상!M10
A14: =주의대상!A11 | B14: =주의대상!B11 | C14: =주의대상!C11 | D14: =주의대상!D11 | E14: =주의대상!E11 | F14: =주의대상!G11 | G14: =주의대상!J11 | H14: =주의대상!M11
A15: =주의대상!A12 | B15: =주의대상!B12 | C15: =주의대상!C12 | D15: =주의대상!D12 | E15: =주의대상!E12 | F15: =주의대상!G12 | G15: =주의대상!J12 | H15: =주의대상!M12
A16: =주의대상!A13 | B16: =주의대상!B13 | C16: =주의대상!C13 | D16: =주의대상!D13 | E16: =주의대상!E13 | F16: =주의대상!G13 | G16: =주의대상!J13 | H16: =주의대상!M13
A17: =주의대상!A14 | B17: =주의대상!B14 | C17: =주의대상!C14 | D17: =주의대상!D14 | E17: =주의대상!E14 | F17: =주의대상!G14 | G17: =주의대상!J14 | H17: =주의대상!M14
A18: =주의대상!A15 | B18: =주의대상!B15 | C18: =주의대상!C15 | D18: =주의대상!D15 | E18: =주의대상!E15 | F18: =주의대상!G15 | G18: =주의대상!J15 | H18: =주의대상!M15
A20: 2. 원인 분석 (원인분석 시트에서 선택한 항목)
A21: =원인분석!A18
A22: 순위 | B22: 패턴 | C22: 근거 강도 | D22: 설명
A23: =원인분석!A21 | B23: =원인분석!B21 | C23: =원인분석!C21 | D23: =원인분석!D21
A24: =원인분석!A22 | B24: =원인분석!B22 | C24: =원인분석!C22 | D24: =원인분석!D22
A25: =원인분석!A23 | B25: =원인분석!B23 | C25: =원인분석!C23 | D25: =원인분석!D23
A26: =원인분석!A24 | B26: =원인분석!B24 | C26: =원인분석!C24 | D26: =원인분석!D24
A28: 3. 월별 사업비 (전사, 당해 vs 전년)
K29: 월 | L29: =설정!$C$6&"년" | M29: =설정!$C$6-1&"년"
K30: 1월 | L30: =IF(1>설정!$C$7,0,SUMIFS(전표_원본!$P$5:$P$100000,전표_원본!$M$5:$M$100000,설정!$C$6*12+1)) | M30: =SUMIFS(전표_원본!$P$5:$P$100000,전표_원본!$M$5:$M$100000,(설정!$C$6-1)*12+1)
K31: 2월 | L31: =IF(2>설정!$C$7,0,SUMIFS(전표_원본!$P$5:$P$100000,전표_원본!$M$5:$M$100000,설정!$C$6*12+2)) | M31: =SUMIFS(전표_원본!$P$5:$P$100000,전표_원본!$M$5:$M$100000,(설정!$C$6-1)*12+2)
K32: 3월 | L32: =IF(3>설정!$C$7,0,SUMIFS(전표_원본!$P$5:$P$100000,전표_원본!$M$5:$M$100000,설정!$C$6*12+3)) | M32: =SUMIFS(전표_원본!$P$5:$P$100000,전표_원본!$M$5:$M$100000,(설정!$C$6-1)*12+3)
K33: 4월 | L33: =IF(4>설정!$C$7,0,SUMIFS(전표_원본!$P$5:$P$100000,전표_원본!$M$5:$M$100000,설정!$C$6*12+4)) | M33: =SUMIFS(전표_원본!$P$5:$P$100000,전표_원본!$M$5:$M$100000,(설정!$C$6-1)*12+4)
K34: 5월 | L34: =IF(5>설정!$C$7,0,SUMIFS(전표_원본!$P$5:$P$100000,전표_원본!$M$5:$M$100000,설정!$C$6*12+5)) | M34: =SUMIFS(전표_원본!$P$5:$P$100000,전표_원본!$M$5:$M$100000,(설정!$C$6-1)*12+5)
K35: 6월 | L35: =IF(6>설정!$C$7,0,SUMIFS(전표_원본!$P$5:$P$100000,전표_원본!$M$5:$M$100000,설정!$C$6*12+6)) | M35: =SUMIFS(전표_원본!$P$5:$P$100000,전표_원본!$M$5:$M$100000,(설정!$C$6-1)*12+6)
K36: 7월 | L36: =IF(7>설정!$C$7,0,SUMIFS(전표_원본!$P$5:$P$100000,전표_원본!$M$5:$M$100000,설정!$C$6*12+7)) | M36: =SUMIFS(전표_원본!$P$5:$P$100000,전표_원본!$M$5:$M$100000,(설정!$C$6-1)*12+7)
K37: 8월 | L37: =IF(8>설정!$C$7,0,SUMIFS(전표_원본!$P$5:$P$100000,전표_원본!$M$5:$M$100000,설정!$C$6*12+8)) | M37: =SUMIFS(전표_원본!$P$5:$P$100000,전표_원본!$M$5:$M$100000,(설정!$C$6-1)*12+8)
K38: 9월 | L38: =IF(9>설정!$C$7,0,SUMIFS(전표_원본!$P$5:$P$100000,전표_원본!$M$5:$M$100000,설정!$C$6*12+9)) | M38: =SUMIFS(전표_원본!$P$5:$P$100000,전표_원본!$M$5:$M$100000,(설정!$C$6-1)*12+9)
K39: 10월 | L39: =IF(10>설정!$C$7,0,SUMIFS(전표_원본!$P$5:$P$100000,전표_원본!$M$5:$M$100000,설정!$C$6*12+10)) | M39: =SUMIFS(전표_원본!$P$5:$P$100000,전표_원본!$M$5:$M$100000,(설정!$C$6-1)*12+10)
K40: 11월 | L40: =IF(11>설정!$C$7,0,SUMIFS(전표_원본!$P$5:$P$100000,전표_원본!$M$5:$M$100000,설정!$C$6*12+11)) | M40: =SUMIFS(전표_원본!$P$5:$P$100000,전표_원본!$M$5:$M$100000,(설정!$C$6-1)*12+11)
K41: 12월 | L41: =IF(12>설정!$C$7,0,SUMIFS(전표_원본!$P$5:$P$100000,전표_원본!$M$5:$M$100000,설정!$C$6*12+12)) | M41: =SUMIFS(전표_원본!$P$5:$P$100000,전표_원본!$M$5:$M$100000,(설정!$C$6-1)*12+12)

Sheet 주의대상
A1: TRACE · 주의 대상 TOP 10
A2: 점수 = 증가액(30) + 증가율(20) + 이상치(25) + 예산(25), 작은 금액은 30%로 낮춤 · 원인은 원인분석 시트 C5에 순위 입력
A3: ="기준: "&INT((설정!$C$20-1)/12)&"-"&TEXT(MOD(설정!$C$20-1,12)+1,"00")&" · 단위: "&설정!$C$9&" · 예산 부족 예상 "&COUNTIF(변동분석!$W$7:$W$506,"부족 예상")&"건 · 주의 "&COUNTIF(변동분석!$W$7:$W$506,"주의")&"건 · 무예산 "&COUNTIF(변동분석!$W$7:$W$506,"무예산")&"건"
A5: 순위 | B5: 부서 | C5: 계정 | D5: 당월 | E5: 전월 대비 | F5: 전년동월 대비 | G5: 예산판정 | H5: 부족 예상액 | I5: 소진 예상월 | J5: 빠른 신호 | K5: 점수 | L5: 키 | M5: 확인된 원인 (코멘트) | N5: 행
A6: 1 | B6: =IF($N6="","",INDEX(변동분석!$B$7:$B$506,$N6)) | C6: =IF($N6="","",INDEX(변동분석!$D$7:$D$506,$N6)) | D6: =IF($N6="","",INDEX(변동분석!$F$7:$F$506,$N6)) | E6: =IF($N6="","",INDEX(변동분석!$H$7:$H$506,$N6)) | F6: =IF($N6="","",INDEX(변동분석!$J$7:$J$506,$N6)) | G6: =IF($N6="","",INDEX(변동분석!$W$7:$W$506,$N6)) | H6: =IF($N6="","",INDEX(변동분석!$X$7:$X$506,$N6)) | I6: =IF($N6="","",INDEX(변동분석!$Y$7:$Y$506,$N6)) | J6: =IF($N6="","",INDEX(변동분석!$Z$7:$Z$506,$N6)) | K6: =IF($N6="","",INDEX(변동분석!$AA$7:$AA$506,$N6)) | L6: =IF($N6="","",INDEX(변동분석!$E$7:$E$506,$N6)) | M6: =IF($L6="","",IFERROR(INDEX(코멘트!$F$5:$F$2004,MATCH(설정!$C$6&"|"&설정!$C$7&"|"&$L6,코멘트!$I$5:$I$2004,0)),"(미확인)")) | N6: =IFERROR(MATCH(LARGE(변동분석!$AB$7:$AB$506,A6),변동분석!$AB$7:$AB$506,0),"")
A7: 2 | B7: =IF($N7="","",INDEX(변동분석!$B$7:$B$506,$N7)) | C7: =IF($N7="","",INDEX(변동분석!$D$7:$D$506,$N7)) | D7: =IF($N7="","",INDEX(변동분석!$F$7:$F$506,$N7)) | E7: =IF($N7="","",INDEX(변동분석!$H$7:$H$506,$N7)) | F7: =IF($N7="","",INDEX(변동분석!$J$7:$J$506,$N7)) | G7: =IF($N7="","",INDEX(변동분석!$W$7:$W$506,$N7)) | H7: =IF($N7="","",INDEX(변동분석!$X$7:$X$506,$N7)) | I7: =IF($N7="","",INDEX(변동분석!$Y$7:$Y$506,$N7)) | J7: =IF($N7="","",INDEX(변동분석!$Z$7:$Z$506,$N7)) | K7: =IF($N7="","",INDEX(변동분석!$AA$7:$AA$506,$N7)) | L7: =IF($N7="","",INDEX(변동분석!$E$7:$E$506,$N7)) | M7: =IF($L7="","",IFERROR(INDEX(코멘트!$F$5:$F$2004,MATCH(설정!$C$6&"|"&설정!$C$7&"|"&$L7,코멘트!$I$5:$I$2004,0)),"(미확인)")) | N7: =IFERROR(MATCH(LARGE(변동분석!$AB$7:$AB$506,A7),변동분석!$AB$7:$AB$506,0),"")
A8: 3 | B8: =IF($N8="","",INDEX(변동분석!$B$7:$B$506,$N8)) | C8: =IF($N8="","",INDEX(변동분석!$D$7:$D$506,$N8)) | D8: =IF($N8="","",INDEX(변동분석!$F$7:$F$506,$N8)) | E8: =IF($N8="","",INDEX(변동분석!$H$7:$H$506,$N8)) | F8: =IF($N8="","",INDEX(변동분석!$J$7:$J$506,$N8)) | G8: =IF($N8="","",INDEX(변동분석!$W$7:$W$506,$N8)) | H8: =IF($N8="","",INDEX(변동분석!$X$7:$X$506,$N8)) | I8: =IF($N8="","",INDEX(변동분석!$Y$7:$Y$506,$N8)) | J8: =IF($N8="","",INDEX(변동분석!$Z$7:$Z$506,$N8)) | K8: =IF($N8="","",INDEX(변동분석!$AA$7:$AA$506,$N8)) | L8: =IF($N8="","",INDEX(변동분석!$E$7:$E$506,$N8)) | M8: =IF($L8="","",IFERROR(INDEX(코멘트!$F$5:$F$2004,MATCH(설정!$C$6&"|"&설정!$C$7&"|"&$L8,코멘트!$I$5:$I$2004,0)),"(미확인)")) | N8: =IFERROR(MATCH(LARGE(변동분석!$AB$7:$AB$506,A8),변동분석!$AB$7:$AB$506,0),"")
A9: 4 | B9: =IF($N9="","",INDEX(변동분석!$B$7:$B$506,$N9)) | C9: =IF($N9="","",INDEX(변동분석!$D$7:$D$506,$N9)) | D9: =IF($N9="","",INDEX(변동분석!$F$7:$F$506,$N9)) | E9: =IF($N9="","",INDEX(변동분석!$H$7:$H$506,$N9)) | F9: =IF($N9="","",INDEX(변동분석!$J$7:$J$506,$N9)) | G9: =IF($N9="","",INDEX(변동분석!$W$7:$W$506,$N9)) | H9: =IF($N9="","",INDEX(변동분석!$X$7:$X$506,$N9)) | I9: =IF($N9="","",INDEX(변동분석!$Y$7:$Y$506,$N9)) | J9: =IF($N9="","",INDEX(변동분석!$Z$7:$Z$506,$N9)) | K9: =IF($N9="","",INDEX(변동분석!$AA$7:$AA$506,$N9)) | L9: =IF($N9="","",INDEX(변동분석!$E$7:$E$506,$N9)) | M9: =IF($L9="","",IFERROR(INDEX(코멘트!$F$5:$F$2004,MATCH(설정!$C$6&"|"&설정!$C$7&"|"&$L9,코멘트!$I$5:$I$2004,0)),"(미확인)")) | N9: =IFERROR(MATCH(LARGE(변동분석!$AB$7:$AB$506,A9),변동분석!$AB$7:$AB$506,0),"")
A10: 5 | B10: =IF($N10="","",INDEX(변동분석!$B$7:$B$506,$N10)) | C10: =IF($N10="","",INDEX(변동분석!$D$7:$D$506,$N10)) | D10: =IF($N10="","",INDEX(변동분석!$F$7:$F$506,$N10)) | E10: =IF($N10="","",INDEX(변동분석!$H$7:$H$506,$N10)) | F10: =IF($N10="","",INDEX(변동분석!$J$7:$J$506,$N10)) | G10: =IF($N10="","",INDEX(변동분석!$W$7:$W$506,$N10)) | H10: =IF($N10="","",INDEX(변동분석!$X$7:$X$506,$N10)) | I10: =IF($N10="","",INDEX(변동분석!$Y$7:$Y$506,$N10)) | J10: =IF($N10="","",INDEX(변동분석!$Z$7:$Z$506,$N10)) | K10: =IF($N10="","",INDEX(변동분석!$AA$7:$AA$506,$N10)) | L10: =IF($N10="","",INDEX(변동분석!$E$7:$E$506,$N10)) | M10: =IF($L10="","",IFERROR(INDEX(코멘트!$F$5:$F$2004,MATCH(설정!$C$6&"|"&설정!$C$7&"|"&$L10,코멘트!$I$5:$I$2004,0)),"(미확인)")) | N10: =IFERROR(MATCH(LARGE(변동분석!$AB$7:$AB$506,A10),변동분석!$AB$7:$AB$506,0),"")
A11: 6 | B11: =IF($N11="","",INDEX(변동분석!$B$7:$B$506,$N11)) | C11: =IF($N11="","",INDEX(변동분석!$D$7:$D$506,$N11)) | D11: =IF($N11="","",INDEX(변동분석!$F$7:$F$506,$N11)) | E11: =IF($N11="","",INDEX(변동분석!$H$7:$H$506,$N11)) | F11: =IF($N11="","",INDEX(변동분석!$J$7:$J$506,$N11)) | G11: =IF($N11="","",INDEX(변동분석!$W$7:$W$506,$N11)) | H11: =IF($N11="","",INDEX(변동분석!$X$7:$X$506,$N11)) | I11: =IF($N11="","",INDEX(변동분석!$Y$7:$Y$506,$N11)) | J11: =IF($N11="","",INDEX(변동분석!$Z$7:$Z$506,$N11)) | K11: =IF($N11="","",INDEX(변동분석!$AA$7:$AA$506,$N11)) | L11: =IF($N11="","",INDEX(변동분석!$E$7:$E$506,$N11)) | M11: =IF($L11="","",IFERROR(INDEX(코멘트!$F$5:$F$2004,MATCH(설정!$C$6&"|"&설정!$C$7&"|"&$L11,코멘트!$I$5:$I$2004,0)),"(미확인)")) | N11: =IFERROR(MATCH(LARGE(변동분석!$AB$7:$AB$506,A11),변동분석!$AB$7:$AB$506,0),"")
A12: 7 | B12: =IF($N12="","",INDEX(변동분석!$B$7:$B$506,$N12)) | C12: =IF($N12="","",INDEX(변동분석!$D$7:$D$506,$N12)) | D12: =IF($N12="","",INDEX(변동분석!$F$7:$F$506,$N12)) | E12: =IF($N12="","",INDEX(변동분석!$H$7:$H$506,$N12)) | F12: =IF($N12="","",INDEX(변동분석!$J$7:$J$506,$N12)) | G12: =IF($N12="","",INDEX(변동분석!$W$7:$W$506,$N12)) | H12: =IF($N12="","",INDEX(변동분석!$X$7:$X$506,$N12)) | I12: =IF($N12="","",INDEX(변동분석!$Y$7:$Y$506,$N12)) | J12: =IF($N12="","",INDEX(변동분석!$Z$7:$Z$506,$N12)) | K12: =IF($N12="","",INDEX(변동분석!$AA$7:$AA$506,$N12)) | L12: =IF($N12="","",INDEX(변동분석!$E$7:$E$506,$N12)) | M12: =IF($L12="","",IFERROR(INDEX(코멘트!$F$5:$F$2004,MATCH(설정!$C$6&"|"&설정!$C$7&"|"&$L12,코멘트!$I$5:$I$2004,0)),"(미확인)")) | N12: =IFERROR(MATCH(LARGE(변동분석!$AB$7:$AB$506,A12),변동분석!$AB$7:$AB$506,0),"")
A13: 8 | B13: =IF($N13="","",INDEX(변동분석!$B$7:$B$506,$N13)) | C13: =IF($N13="","",INDEX(변동분석!$D$7:$D$506,$N13)) | D13: =IF($N13="","",INDEX(변동분석!$F$7:$F$506,$N13)) | E13: =IF($N13="","",INDEX(변동분석!$H$7:$H$506,$N13)) | F13: =IF($N13="","",INDEX(변동분석!$J$7:$J$506,$N13)) | G13: =IF($N13="","",INDEX(변동분석!$W$7:$W$506,$N13)) | H13: =IF($N13="","",INDEX(변동분석!$X$7:$X$506,$N13)) | I13: =IF($N13="","",INDEX(변동분석!$Y$7:$Y$506,$N13)) | J13: =IF($N13="","",INDEX(변동분석!$Z$7:$Z$506,$N13)) | K13: =IF($N13="","",INDEX(변동분석!$AA$7:$AA$506,$N13)) | L13: =IF($N13="","",INDEX(변동분석!$E$7:$E$506,$N13)) | M13: =IF($L13="","",IFERROR(INDEX(코멘트!$F$5:$F$2004,MATCH(설정!$C$6&"|"&설정!$C$7&"|"&$L13,코멘트!$I$5:$I$2004,0)),"(미확인)")) | N13: =IFERROR(MATCH(LARGE(변동분석!$AB$7:$AB$506,A13),변동분석!$AB$7:$AB$506,0),"")
A14: 9 | B14: =IF($N14="","",INDEX(변동분석!$B$7:$B$506,$N14)) | C14: =IF($N14="","",INDEX(변동분석!$D$7:$D$506,$N14)) | D14: =IF($N14="","",INDEX(변동분석!$F$7:$F$506,$N14)) | E14: =IF($N14="","",INDEX(변동분석!$H$7:$H$506,$N14)) | F14: =IF($N14="","",INDEX(변동분석!$J$7:$J$506,$N14)) | G14: =IF($N14="","",INDEX(변동분석!$W$7:$W$506,$N14)) | H14: =IF($N14="","",INDEX(변동분석!$X$7:$X$506,$N14)) | I14: =IF($N14="","",INDEX(변동분석!$Y$7:$Y$506,$N14)) | J14: =IF($N14="","",INDEX(변동분석!$Z$7:$Z$506,$N14)) | K14: =IF($N14="","",INDEX(변동분석!$AA$7:$AA$506,$N14)) | L14: =IF($N14="","",INDEX(변동분석!$E$7:$E$506,$N14)) | M14: =IF($L14="","",IFERROR(INDEX(코멘트!$F$5:$F$2004,MATCH(설정!$C$6&"|"&설정!$C$7&"|"&$L14,코멘트!$I$5:$I$2004,0)),"(미확인)")) | N14: =IFERROR(MATCH(LARGE(변동분석!$AB$7:$AB$506,A14),변동분석!$AB$7:$AB$506,0),"")
A15: 10 | B15: =IF($N15="","",INDEX(변동분석!$B$7:$B$506,$N15)) | C15: =IF($N15="","",INDEX(변동분석!$D$7:$D$506,$N15)) | D15: =IF($N15="","",INDEX(변동분석!$F$7:$F$506,$N15)) | E15: =IF($N15="","",INDEX(변동분석!$H$7:$H$506,$N15)) | F15: =IF($N15="","",INDEX(변동분석!$J$7:$J$506,$N15)) | G15: =IF($N15="","",INDEX(변동분석!$W$7:$W$506,$N15)) | H15: =IF($N15="","",INDEX(변동분석!$X$7:$X$506,$N15)) | I15: =IF($N15="","",INDEX(변동분석!$Y$7:$Y$506,$N15)) | J15: =IF($N15="","",INDEX(변동분석!$Z$7:$Z$506,$N15)) | K15: =IF($N15="","",INDEX(변동분석!$AA$7:$AA$506,$N15)) | L15: =IF($N15="","",INDEX(변동분석!$E$7:$E$506,$N15)) | M15: =IF($L15="","",IFERROR(INDEX(코멘트!$F$5:$F$2004,MATCH(설정!$C$6&"|"&설정!$C$7&"|"&$L15,코멘트!$I$5:$I$2004,0)),"(미확인)")) | N15: =IFERROR(MATCH(LARGE(변동분석!$AB$7:$AB$506,A15),변동분석!$AB$7:$AB$506,0),"")

Sheet 원인분석
A1: TRACE · 원인분석 (한 항목씩)
A2: C5~C8만 입력 · 선택 항목의 증가분을 거래처·전표로 쪼개고 8가지 패턴으로 원인 후보를 만듭니다 · 금액: 보고단위
B5: 주의대상 순위 | C5: 1 | D5: 1~10 | E5: 선택 항목
B6: 비교 기준 | C6: 전월 | D6: 전월 / 전년동월 / 전분기 | E6: =IF($C$9="","(선택 없음)",IFERROR(INDEX(부서매핑!$D$5:$D$504,MATCH(LEFT($C$9,FIND("|",$C$9)-1),부서매핑!$C$5:$C$504,0)),LEFT($C$9,FIND("|",$C$9)-1))&" · "&IFERROR(INDEX(계정매핑!$B$5:$B$504,MATCH(MID($C$9,FIND("|",$C$9)+1,20),계정매핑!$A$5:$A$504,0)),MID($C$9,FIND("|",$C$9)+1,20)))
B7: 직접 지정: 부서코드 | D7: 비워두면 순위 사용 | E7: ="당기 "&INT(($C$10-1)/12)&"-"&TEXT(MOD($C$10-1,12)+1,"00")&IF($C$10<>$C$11," ~ "&INT(($C$11-1)/12)&"-"&TEXT(MOD($C$11-1,12)+1,"00"),"")&" vs 비교 "&INT(($C$12-1)/12)&"-"&TEXT(MOD($C$12-1,12)+1,"00")&IF($C$12<>$C$13," ~ "&INT(($C$13-1)/12)&"-"&TEXT(MOD($C$13-1,12)+1,"00"),"")
B8: 직접 지정: G/L 계정 | D8: 부서코드와 함께 입력
B9: (계산) 선택 키 | C9: =IF(AND(C7<>"",C8<>""),C7&"|"&C8,IFERROR(INDEX(주의대상!$L$6:$L$15,C5),"")) | E9: =E6&" ("&C6&" 대비)"
B10: (계산) 당기 시작 | C10: =IF(C6="전분기",설정!$C$22,설정!$C$20)
B11: (계산) 당기 끝 | C11: =설정!$C$20
B12: (계산) 비교 시작 | C12: =IF(C6="전월",설정!$C$20-1,IF(C6="전년동월",설정!$C$20-12,설정!$C$22-3))
B13: (계산) 비교 끝 | C13: =IF(C6="전월",설정!$C$20-1,IF(C6="전년동월",설정!$C$20-12,설정!$C$20-3))
A15: 당기 합계 | B15: 비교 합계 | C15: 증감 | D15: 증감률 | E15: 예산 판정 | F15: 부족 예상액 | G15: 소진 예상월
A16: =SUMIFS(전표_원본!$P$5:$P$100000,전표_원본!$Q$5:$Q$100000,"당기") | B16: =SUMIFS(전표_원본!$P$5:$P$100000,전표_원본!$Q$5:$Q$100000,"비교") | C16: =A16-B16 | D16: =IF(B16<=0,IF(A16>0,1,0),A16/B16-1) | E16: =IFERROR(INDEX(변동분석!$W$7:$W$506,MATCH($C$9,변동분석!$E$7:$E$506,0)),"-") | F16: =IFERROR(INDEX(변동분석!$X$7:$X$506,MATCH($C$9,변동분석!$E$7:$E$506,0)),0) | G16: =IFERROR(INDEX(변동분석!$Y$7:$Y$506,MATCH($C$9,변동분석!$E$7:$E$506,0)),"")
A18: =IF($C$9="","선택된 항목이 없습니다.",$E$6&" "&$C$6&" 대비 "&TEXT($C$16,"+#,##0.0;-#,##0.0;0")&" ("&TEXT($D$16,"+0%;-0%;0%")&"). "&IF($C$16<=0,"감소 또는 변동 없음 - 원인 후보는 증가 항목에만 만듭니다. ",$D$21&". ")&"예산: "&$E$16&IF(N($F$16)>0," (연간 "&TEXT($F$16,"#,##0.0")&" 부족 예상, "&$G$16&" 소진 예상)","")&".")
A19: 원인 후보 (근거 강도 순) | N19: 패턴 | O19: 해당 | P19: 강도 | Q19: 강도점수 | R19: 비중 | S19: 문장 | T19: 정렬키 | Y19: 보조값 | Z19: 값
A20: 순위 | B20: 패턴 | C20: 근거 강도 | D20: 설명 (근거 포함) | N20: 일회성 대형 지출 | O20: =IF(OR(Z20="",$C$16<=0),"N",IF(AND(Z21>0,Z21/$C$16>=설정!$C$14),"Y","N")) | P20: 높음 | Q20: 3 | R20: =IF(O20="Y",MIN(1,Z21/$C$16),0) | S20: =IF(O20="Y","전표 "&Z22&" ("&TEXT(Z23,"m/d")&", "&Z24&", 적요 '"&Z25&"') "&TEXT(Z21,"#,##0.0")&"이 증가분의 "&TEXT(R20,"0%")&". 일회성 지출 가능성","") | T20: =IF(O20="Y",Q20*10+R20+ROW()/1000000,-1) | Y20: 최대 단건 위치 | Z20: =IFERROR(MATCH(LARGE(전표_원본!$T$5:$T$100000,1),전표_원본!$T$5:$T$100000,0),"")
A21: 1 | B21: =IF($K21="",IF(1=1,"뚜렷한 패턴 없음",""),INDEX($N$20:$N$27,$K21)) | C21: =IF($K21="","",INDEX($P$20:$P$27,$K21)) | D21: =IF($K21="",IF(1=1,"근거 전표 목록을 직접 확인하세요",""),INDEX($S$20:$S$27,$K21)) | K21: =IF(LARGE($T$20:$T$27,1)<0,"",MATCH(LARGE($T$20:$T$27,1),$T$20:$T$27,0)) | N21: 신규 거래처 | O21: =IF($C$16<=0,"N",IF(Z42/$C$16>=설정!$C$15,"Y","N")) | P21: 중간 | Q21: 2 | R21: =IF(O21="Y",MIN(1,Z42/$C$16),0) | S21: =IF(O21="Y","최근 12개월 거래가 없던 거래처("&Z44&IF(Z43>1," 등 "&Z43&"곳","")&")가 증가분의 "&TEXT(R21,"0%")&". 신규 계약·거래 개시 가능성","") | T21: =IF(O21="Y",Q21*10+R21+ROW()/1000000,-1) | Y21: 최대 단건 금액 | Z21: =IF(Z20="","",INDEX(전표_원본!$P$5:$P$100000,Z20))
A22: 2 | B22: =IF($K22="",IF(2=1,"뚜렷한 패턴 없음",""),INDEX($N$20:$N$27,$K22)) | C22: =IF($K22="","",INDEX($P$20:$P$27,$K22)) | D22: =IF($K22="",IF(2=1,"근거 전표 목록을 직접 확인하세요",""),INDEX($S$20:$S$27,$K22)) | K22: =IF(LARGE($T$20:$T$27,2)<0,"",MATCH(LARGE($T$20:$T$27,2),$T$20:$T$27,0)) | N22: 단가 인상 | O22: =IF(OR($C$16<=0,$A$32=""),"N",IF(AND($I$32="N",$F$32=$G$32,$G$32>0,$C$32>0),IF($D$32/$C$32>=설정!$C$18,"Y","N"),"N")) | P22: 중간 | Q22: 2 | R22: =IF(O22="Y",MIN(1,$D$32/$C$16),0) | S22: =IF(O22="Y","같은 건수("&$F$32&"건)로 "&$A$32&" 금액이 "&TEXT(IF($C$32>0,$D$32/$C$32,0),"0%")&" 상승. 단가·계약 조건 변경 가능성 (최근 몇 달 추이 확인)","") | T22: =IF(O22="Y",Q22*10+R22+ROW()/1000000,-1) | Y22: 전표번호 | Z22: =IF(Z20="","",INDEX(전표_원본!$C$5:$C$100000,Z20))
A23: 3 | B23: =IF($K23="",IF(3=1,"뚜렷한 패턴 없음",""),INDEX($N$20:$N$27,$K23)) | C23: =IF($K23="","",INDEX($P$20:$P$27,$K23)) | D23: =IF($K23="",IF(3=1,"근거 전표 목록을 직접 확인하세요",""),INDEX($S$20:$S$27,$K23)) | K23: =IF(LARGE($T$20:$T$27,3)<0,"",MATCH(LARGE($T$20:$T$27,3),$T$20:$T$27,0)) | N23: 계상 시점 이동 | O23: =IF(AND(Z29>0,Z28<0.5*Z29,Z27>1.5*Z29),"Y","N") | P23: 중간 | Q23: 2 | R23: =IF(O23="Y",0.5,0) | S23: =IF(O23="Y","전월 "&TEXT(Z28,"#,##0.0")&" (직전 3개월 평균 "&TEXT(Z29,"#,##0.0")&") → 당월 "&TEXT(Z27,"#,##0.0")&". 전월에 계상될 금액이 당월로 넘어왔을 가능성","") | T23: =IF(O23="Y",Q23*10+R23+ROW()/1000000,-1) | Y23: 전기일 | Z23: =IF(Z20="","",INDEX(전표_원본!$D$5:$D$100000,Z20))
A24: 4 | B24: =IF($K24="",IF(4=1,"뚜렷한 패턴 없음",""),INDEX($N$20:$N$27,$K24)) | C24: =IF($K24="","",INDEX($P$20:$P$27,$K24)) | D24: =IF($K24="",IF(4=1,"근거 전표 목록을 직접 확인하세요",""),INDEX($S$20:$S$27,$K24)) | K24: =IF(LARGE($T$20:$T$27,4)<0,"",MATCH(LARGE($T$20:$T$27,4),$T$20:$T$27,0)) | N24: 정정 · 역분개 | O24: =IF(Z30>0,"Y","N") | P24: 높음 | Q24: 3 | R24: =IF(O24="Y",MIN(1,ABS(Z31)/MAX(ABS($C$16),0.000001)),0) | S24: =IF(O24="Y","음수(정정·역분개) 전표 "&Z30&"건, 합계 "&TEXT(Z31,"#,##0.0")&". 정정 전후 순액 기준으로 다시 확인","") | T24: =IF(O24="Y",Q24*10+R24+ROW()/1000000,-1) | Y24: 거래처 | Z24: =IF(Z20="","",INDEX(전표_원본!$K$5:$K$100000,Z20))
A25: 5 | B25: =IF($K25="",IF(5=1,"뚜렷한 패턴 없음",""),INDEX($N$20:$N$27,$K25)) | C25: =IF($K25="","",INDEX($P$20:$P$27,$K25)) | D25: =IF($K25="",IF(5=1,"근거 전표 목록을 직접 확인하세요",""),INDEX($S$20:$S$27,$K25)) | K25: =IF(LARGE($T$20:$T$27,5)<0,"",MATCH(LARGE($T$20:$T$27,5),$T$20:$T$27,0)) | N25: 재분류 (수기 대체) | O25: =IF($C$16<=0,"N",IF(Z32/$C$16>=설정!$C$16,"Y","N")) | P25: 높음 | Q25: 3 | R25: =IF(O25="Y",MIN(1,Z32/$C$16),0) | S25: =IF(O25="Y","수기 대체전표(SA) 순증 "&TEXT(Z32,"#,##0.0")&"이 증가분의 "&TEXT(R25,"0%")&". 다른 부서·계정에서 이관됐을 가능성 (적요: '"&Z33&"')","") | T25: =IF(O25="Y",Q25*10+R25+ROW()/1000000,-1) | Y25: 적요 | Z25: =IF(Z20="","",INDEX(전표_원본!$I$5:$I$100000,Z20))
A26: 6 | B26: =IF($K26="",IF(6=1,"뚜렷한 패턴 없음",""),INDEX($N$20:$N$27,$K26)) | C26: =IF($K26="","",INDEX($P$20:$P$27,$K26)) | D26: =IF($K26="",IF(6=1,"근거 전표 목록을 직접 확인하세요",""),INDEX($S$20:$S$27,$K26)) | K26: =IF(LARGE($T$20:$T$27,6)<0,"",MATCH(LARGE($T$20:$T$27,6),$T$20:$T$27,0)) | N26: 적요 키워드 | O26: =IF(OR($C$16<=0,Z35=""),"N",IF(Z34>=설정!$C$17,"Y","N")) | P26: 중간 | Q26: 2 | R26: =IF(O26="Y",MIN(1,Z34),0) | S26: =IF(O26="Y",IF(Z35="","",INDEX(키워드사전!$A$5:$A$19,Z35)&": 적요에 '"&INDEX(키워드사전!$B$5:$B$19,Z35)&IF(INDEX(키워드사전!$C$5:$C$19,Z35)<>"","·"&INDEX(키워드사전!$C$5:$C$19,Z35),"")&IF(INDEX(키워드사전!$D$5:$D$19,Z35)<>"","·"&INDEX(키워드사전!$D$5:$D$19,Z35),"")&"' 등이 있는 전표 "&TEXT(INDEX(키워드사전!$H$5:$H$19,Z35),"#,##0.0")&" (증가분의 "&TEXT(Z34,"0%")&"). "&INDEX(키워드사전!$G$5:$G$19,Z35)),"") | T26: =IF(O26="Y",Q26*10+R26+ROW()/1000000,-1) | Y26: 월별집계 행 | Z26: =IFERROR(MATCH($C$9,월별집계!$A$7:$A$506,0),"")
A27: 7 | B27: =IF($K27="",IF(7=1,"뚜렷한 패턴 없음",""),INDEX($N$20:$N$27,$K27)) | C27: =IF($K27="","",INDEX($P$20:$P$27,$K27)) | D27: =IF($K27="",IF(7=1,"근거 전표 목록을 직접 확인하세요",""),INDEX($S$20:$S$27,$K27)) | K27: =IF(LARGE($T$20:$T$27,7)<0,"",MATCH(LARGE($T$20:$T$27,7),$T$20:$T$27,0)) | N27: 물량 vs 단가 | O27: =IF(AND($C$16>0,Z36>0,Z37>0),"Y","N") | P27: 참고 | Q27: 1 | R27: =0 | S27: =IF(O27="Y","건수 "&Z37&"→"&Z36&" ("&TEXT(Z36/MAX(Z37,1)-1,"+0%;-0%;0%")&"), 건당 "&TEXT(Z41,"#,##0.0")&"→"&TEXT(Z40,"#,##0.0")&". "&IF(ABS((Z36-Z37)*Z41)>=ABS((Z40-Z41)*Z36),"건수(물량) 증가","건당 금액(단가) 상승")&" 영향이 더 큼","") | T27: =IF(O27="Y",Q27*10+R27+ROW()/1000000,-1) | Y27: 당월 (기준월) | Z27: =IF(Z26="",0,INDEX(월별집계!$Z$7:$Z$506,Z26))
A28: 8 | B28: =IF($K28="",IF(8=1,"뚜렷한 패턴 없음",""),INDEX($N$20:$N$27,$K28)) | C28: =IF($K28="","",INDEX($P$20:$P$27,$K28)) | D28: =IF($K28="",IF(8=1,"근거 전표 목록을 직접 확인하세요",""),INDEX($S$20:$S$27,$K28)) | K28: =IF(LARGE($T$20:$T$27,8)<0,"",MATCH(LARGE($T$20:$T$27,8),$T$20:$T$27,0)) | Y28: 전월 | Z28: =IF(Z26="",0,INDEX(월별집계!$Y$7:$Y$506,Z26))
Y29: 직전3개월 평균 (전월 제외) | Z29: =IF(Z26="",0,(INDEX(월별집계!$V$7:$V$506,Z26)+INDEX(월별집계!$W$7:$W$506,Z26)+INDEX(월별집계!$X$7:$X$506,Z26))/3)
A30: 거래처별 증감 분해 (증가 큰 순) | Y30: 음수 전표 건수 | Z30: =COUNTIFS(전표_원본!$Q$5:$Q$100000,"당기",전표_원본!$P$5:$P$100000,"<0")
A31: 거래처 | B31: 당기 | C31: 비교 | D31: 증감 | E31: 증가분 기여율 | F31: 당기 건수 | G31: 비교 건수 | H31: 당기 최대 단건 | I31: 신규 거래처 | N31: 첫등장행 | O31: 거래처 | P31: 당기 | Q31: 비교 | R31: 증감 | S31: 당기건수 | T31: 비교건수 | U31: 최대단건 | V31: 신규 | W31: 정렬키 | Y31: 음수 전표 합계 | Z31: =SUMIFS(전표_원본!$P$5:$P$100000,전표_원본!$Q$5:$Q$100000,"당기",전표_원본!$P$5:$P$100000,"<0")
A32: =IF($K32="","",INDEX($O$32:$O$46,$K32)) | B32: =IF($K32="","",INDEX($P$32:$P$46,$K32)) | C32: =IF($K32="","",INDEX($Q$32:$Q$46,$K32)) | D32: =IF($K32="","",INDEX($R$32:$R$46,$K32)) | E32: =IF(OR($K32="",$C$16<=0),"",D32/$C$16) | F32: =IF($K32="","",INDEX($S$32:$S$46,$K32)) | G32: =IF($K32="","",INDEX($T$32:$T$46,$K32)) | H32: =IF($K32="","",INDEX($U$32:$U$46,$K32)) | I32: =IF($K32="","",INDEX($V$32:$V$46,$K32)) | K32: =IF(COUNT($W$32:$W$46)<1,"",MATCH(LARGE($W$32:$W$46,1),$W$32:$W$46,0)) | N32: =IFERROR(SMALL(전표_원본!$S$5:$S$100000,1),"") | O32: =IF(N32="","",INDEX(전표_원본!$K$1:$K$100000,N32)) | P32: =IF(O32="","",SUMIFS(전표_원본!$P$5:$P$100000,전표_원본!$Q$5:$Q$100000,"당기",전표_원본!$R$5:$R$100000,O32)) | Q32: =IF(O32="","",SUMIFS(전표_원본!$P$5:$P$100000,전표_원본!$Q$5:$Q$100000,"비교",전표_원본!$R$5:$R$100000,O32)) | R32: =IF(O32="","",P32-Q32) | S32: =IF(O32="","",COUNTIFS(전표_원본!$Q$5:$Q$100000,"당기",전표_원본!$R$5:$R$100000,O32,전표_원본!$P$5:$P$100000,">0")) | T32: =IF(O32="","",COUNTIFS(전표_원본!$Q$5:$Q$100000,"비교",전표_원본!$R$5:$R$100000,O32,전표_원본!$P$5:$P$100000,">0")) | U32: =IF(O32="","",SUMPRODUCT(MAX((전표_원본!$Q$5:$Q$100000="당기")*(전표_원본!$R$5:$R$100000=O32)*전표_원본!$P$5:$P$100000))) | V32: =IF(O32="","",IF(LEFT(O32,1)="(","N",IF(COUNTIFS(전표_원본!$O$5:$O$100000,$C$9,전표_원본!$K$5:$K$100000,O32,전표_원본!$M$5:$M$100000,">="&($C$10-12),전표_원본!$M$5:$M$100000,"<"&$C$10)=0,"Y","N"))) | W32: =IF(O32="","",R32+ROW()/1000000) | Y32: SA 순증 | Z32: =SUMIFS(전표_원본!$P$5:$P$100000,전표_원본!$Q$5:$Q$100000,"당기",전표_원본!$E$5:$E$100000,"SA")-SUMIFS(전표_원본!$P$5:$P$100000,전표_원본!$Q$5:$Q$100000,"비교",전표_원본!$E$5:$E$100000,"SA")
A33: =IF($K33="","",INDEX($O$32:$O$46,$K33)) | B33: =IF($K33="","",INDEX($P$32:$P$46,$K33)) | C33: =IF($K33="","",INDEX($Q$32:$Q$46,$K33)) | D33: =IF($K33="","",INDEX($R$32:$R$46,$K33)) | E33: =IF(OR($K33="",$C$16<=0),"",D33/$C$16) | F33: =IF($K33="","",INDEX($S$32:$S$46,$K33)) | G33: =IF($K33="","",INDEX($T$32:$T$46,$K33)) | H33: =IF($K33="","",INDEX($U$32:$U$46,$K33)) | I33: =IF($K33="","",INDEX($V$32:$V$46,$K33)) | K33: =IF(COUNT($W$32:$W$46)<2,"",MATCH(LARGE($W$32:$W$46,2),$W$32:$W$46,0)) | N33: =IFERROR(SMALL(전표_원본!$S$5:$S$100000,2),"") | O33: =IF(N33="","",INDEX(전표_원본!$K$1:$K$100000,N33)) | P33: =IF(O33="","",SUMIFS(전표_원본!$P$5:$P$100000,전표_원본!$Q$5:$Q$100000,"당기",전표_원본!$R$5:$R$100000,O33)) | Q33: =IF(O33="","",SUMIFS(전표_원본!$P$5:$P$100000,전표_원본!$Q$5:$Q$100000,"비교",전표_원본!$R$5:$R$100000,O33)) | R33: =IF(O33="","",P33-Q33) | S33: =IF(O33="","",COUNTIFS(전표_원본!$Q$5:$Q$100000,"당기",전표_원본!$R$5:$R$100000,O33,전표_원본!$P$5:$P$100000,">0")) | T33: =IF(O33="","",COUNTIFS(전표_원본!$Q$5:$Q$100000,"비교",전표_원본!$R$5:$R$100000,O33,전표_원본!$P$5:$P$100000,">0")) | U33: =IF(O33="","",SUMPRODUCT(MAX((전표_원본!$Q$5:$Q$100000="당기")*(전표_원본!$R$5:$R$100000=O33)*전표_원본!$P$5:$P$100000))) | V33: =IF(O33="","",IF(LEFT(O33,1)="(","N",IF(COUNTIFS(전표_원본!$O$5:$O$100000,$C$9,전표_원본!$K$5:$K$100000,O33,전표_원본!$M$5:$M$100000,">="&($C$10-12),전표_원본!$M$5:$M$100000,"<"&$C$10)=0,"Y","N"))) | W33: =IF(O33="","",R33+ROW()/1000000) | Y33: SA 첫 적요 | Z33: =IFERROR(INDEX(전표_원본!$I$5:$I$100000,MATCH(1,INDEX((전표_원본!$Q$5:$Q$100000="당기")*(전표_원본!$E$5:$E$100000="SA"),0),0)),"")
A34: =IF($K34="","",INDEX($O$32:$O$46,$K34)) | B34: =IF($K34="","",INDEX($P$32:$P$46,$K34)) | C34: =IF($K34="","",INDEX($Q$32:$Q$46,$K34)) | D34: =IF($K34="","",INDEX($R$32:$R$46,$K34)) | E34: =IF(OR($K34="",$C$16<=0),"",D34/$C$16) | F34: =IF($K34="","",INDEX($S$32:$S$46,$K34)) | G34: =IF($K34="","",INDEX($T$32:$T$46,$K34)) | H34: =IF($K34="","",INDEX($U$32:$U$46,$K34)) | I34: =IF($K34="","",INDEX($V$32:$V$46,$K34)) | K34: =IF(COUNT($W$32:$W$46)<3,"",MATCH(LARGE($W$32:$W$46,3),$W$32:$W$46,0)) | N34: =IFERROR(SMALL(전표_원본!$S$5:$S$100000,3),"") | O34: =IF(N34="","",INDEX(전표_원본!$K$1:$K$100000,N34)) | P34: =IF(O34="","",SUMIFS(전표_원본!$P$5:$P$100000,전표_원본!$Q$5:$Q$100000,"당기",전표_원본!$R$5:$R$100000,O34)) | Q34: =IF(O34="","",SUMIFS(전표_원본!$P$5:$P$100000,전표_원본!$Q$5:$Q$100000,"비교",전표_원본!$R$5:$R$100000,O34)) | R34: =IF(O34="","",P34-Q34) | S34: =IF(O34="","",COUNTIFS(전표_원본!$Q$5:$Q$100000,"당기",전표_원본!$R$5:$R$100000,O34,전표_원본!$P$5:$P$100000,">0")) | T34: =IF(O34="","",COUNTIFS(전표_원본!$Q$5:$Q$100000,"비교",전표_원본!$R$5:$R$100000,O34,전표_원본!$P$5:$P$100000,">0")) | U34: =IF(O34="","",SUMPRODUCT(MAX((전표_원본!$Q$5:$Q$100000="당기")*(전표_원본!$R$5:$R$100000=O34)*전표_원본!$P$5:$P$100000))) | V34: =IF(O34="","",IF(LEFT(O34,1)="(","N",IF(COUNTIFS(전표_원본!$O$5:$O$100000,$C$9,전표_원본!$K$5:$K$100000,O34,전표_원본!$M$5:$M$100000,">="&($C$10-12),전표_원본!$M$5:$M$100000,"<"&$C$10)=0,"Y","N"))) | W34: =IF(O34="","",R34+ROW()/1000000) | Y34: 키워드 최대 비중 | Z34: =IF(COUNT(키워드사전!$I$5:$I$19)=0,0,MAX(키워드사전!$I$5:$I$19))
A35: =IF($K35="","",INDEX($O$32:$O$46,$K35)) | B35: =IF($K35="","",INDEX($P$32:$P$46,$K35)) | C35: =IF($K35="","",INDEX($Q$32:$Q$46,$K35)) | D35: =IF($K35="","",INDEX($R$32:$R$46,$K35)) | E35: =IF(OR($K35="",$C$16<=0),"",D35/$C$16) | F35: =IF($K35="","",INDEX($S$32:$S$46,$K35)) | G35: =IF($K35="","",INDEX($T$32:$T$46,$K35)) | H35: =IF($K35="","",INDEX($U$32:$U$46,$K35)) | I35: =IF($K35="","",INDEX($V$32:$V$46,$K35)) | K35: =IF(COUNT($W$32:$W$46)<4,"",MATCH(LARGE($W$32:$W$46,4),$W$32:$W$46,0)) | N35: =IFERROR(SMALL(전표_원본!$S$5:$S$100000,4),"") | O35: =IF(N35="","",INDEX(전표_원본!$K$1:$K$100000,N35)) | P35: =IF(O35="","",SUMIFS(전표_원본!$P$5:$P$100000,전표_원본!$Q$5:$Q$100000,"당기",전표_원본!$R$5:$R$100000,O35)) | Q35: =IF(O35="","",SUMIFS(전표_원본!$P$5:$P$100000,전표_원본!$Q$5:$Q$100000,"비교",전표_원본!$R$5:$R$100000,O35)) | R35: =IF(O35="","",P35-Q35) | S35: =IF(O35="","",COUNTIFS(전표_원본!$Q$5:$Q$100000,"당기",전표_원본!$R$5:$R$100000,O35,전표_원본!$P$5:$P$100000,">0")) | T35: =IF(O35="","",COUNTIFS(전표_원본!$Q$5:$Q$100000,"비교",전표_원본!$R$5:$R$100000,O35,전표_원본!$P$5:$P$100000,">0")) | U35: =IF(O35="","",SUMPRODUCT(MAX((전표_원본!$Q$5:$Q$100000="당기")*(전표_원본!$R$5:$R$100000=O35)*전표_원본!$P$5:$P$100000))) | V35: =IF(O35="","",IF(LEFT(O35,1)="(","N",IF(COUNTIFS(전표_원본!$O$5:$O$100000,$C$9,전표_원본!$K$5:$K$100000,O35,전표_원본!$M$5:$M$100000,">="&($C$10-12),전표_원본!$M$5:$M$100000,"<"&$C$10)=0,"Y","N"))) | W35: =IF(O35="","",R35+ROW()/1000000) | Y35: 키워드 유형 행 | Z35: =IF(Z34<=0,"",MATCH(Z34,키워드사전!$I$5:$I$19,0))
A36: =IF($K36="","",INDEX($O$32:$O$46,$K36)) | B36: =IF($K36="","",INDEX($P$32:$P$46,$K36)) | C36: =IF($K36="","",INDEX($Q$32:$Q$46,$K36)) | D36: =IF($K36="","",INDEX($R$32:$R$46,$K36)) | E36: =IF(OR($K36="",$C$16<=0),"",D36/$C$16) | F36: =IF($K36="","",INDEX($S$32:$S$46,$K36)) | G36: =IF($K36="","",INDEX($T$32:$T$46,$K36)) | H36: =IF($K36="","",INDEX($U$32:$U$46,$K36)) | I36: =IF($K36="","",INDEX($V$32:$V$46,$K36)) | K36: =IF(COUNT($W$32:$W$46)<5,"",MATCH(LARGE($W$32:$W$46,5),$W$32:$W$46,0)) | N36: =IFERROR(SMALL(전표_원본!$S$5:$S$100000,5),"") | O36: =IF(N36="","",INDEX(전표_원본!$K$1:$K$100000,N36)) | P36: =IF(O36="","",SUMIFS(전표_원본!$P$5:$P$100000,전표_원본!$Q$5:$Q$100000,"당기",전표_원본!$R$5:$R$100000,O36)) | Q36: =IF(O36="","",SUMIFS(전표_원본!$P$5:$P$100000,전표_원본!$Q$5:$Q$100000,"비교",전표_원본!$R$5:$R$100000,O36)) | R36: =IF(O36="","",P36-Q36) | S36: =IF(O36="","",COUNTIFS(전표_원본!$Q$5:$Q$100000,"당기",전표_원본!$R$5:$R$100000,O36,전표_원본!$P$5:$P$100000,">0")) | T36: =IF(O36="","",COUNTIFS(전표_원본!$Q$5:$Q$100000,"비교",전표_원본!$R$5:$R$100000,O36,전표_원본!$P$5:$P$100000,">0")) | U36: =IF(O36="","",SUMPRODUCT(MAX((전표_원본!$Q$5:$Q$100000="당기")*(전표_원본!$R$5:$R$100000=O36)*전표_원본!$P$5:$P$100000))) | V36: =IF(O36="","",IF(LEFT(O36,1)="(","N",IF(COUNTIFS(전표_원본!$O$5:$O$100000,$C$9,전표_원본!$K$5:$K$100000,O36,전표_원본!$M$5:$M$100000,">="&($C$10-12),전표_원본!$M$5:$M$100000,"<"&$C$10)=0,"Y","N"))) | W36: =IF(O36="","",R36+ROW()/1000000) | Y36: 당기 건수 (+) | Z36: =COUNTIFS(전표_원본!$Q$5:$Q$100000,"당기",전표_원본!$P$5:$P$100000,">0")
A37: =IF($K37="","",INDEX($O$32:$O$46,$K37)) | B37: =IF($K37="","",INDEX($P$32:$P$46,$K37)) | C37: =IF($K37="","",INDEX($Q$32:$Q$46,$K37)) | D37: =IF($K37="","",INDEX($R$32:$R$46,$K37)) | E37: =IF(OR($K37="",$C$16<=0),"",D37/$C$16) | F37: =IF($K37="","",INDEX($S$32:$S$46,$K37)) | G37: =IF($K37="","",INDEX($T$32:$T$46,$K37)) | H37: =IF($K37="","",INDEX($U$32:$U$46,$K37)) | I37: =IF($K37="","",INDEX($V$32:$V$46,$K37)) | K37: =IF(COUNT($W$32:$W$46)<6,"",MATCH(LARGE($W$32:$W$46,6),$W$32:$W$46,0)) | N37: =IFERROR(SMALL(전표_원본!$S$5:$S$100000,6),"") | O37: =IF(N37="","",INDEX(전표_원본!$K$1:$K$100000,N37)) | P37: =IF(O37="","",SUMIFS(전표_원본!$P$5:$P$100000,전표_원본!$Q$5:$Q$100000,"당기",전표_원본!$R$5:$R$100000,O37)) | Q37: =IF(O37="","",SUMIFS(전표_원본!$P$5:$P$100000,전표_원본!$Q$5:$Q$100000,"비교",전표_원본!$R$5:$R$100000,O37)) | R37: =IF(O37="","",P37-Q37) | S37: =IF(O37="","",COUNTIFS(전표_원본!$Q$5:$Q$100000,"당기",전표_원본!$R$5:$R$100000,O37,전표_원본!$P$5:$P$100000,">0")) | T37: =IF(O37="","",COUNTIFS(전표_원본!$Q$5:$Q$100000,"비교",전표_원본!$R$5:$R$100000,O37,전표_원본!$P$5:$P$100000,">0")) | U37: =IF(O37="","",SUMPRODUCT(MAX((전표_원본!$Q$5:$Q$100000="당기")*(전표_원본!$R$5:$R$100000=O37)*전표_원본!$P$5:$P$100000))) | V37: =IF(O37="","",IF(LEFT(O37,1)="(","N",IF(COUNTIFS(전표_원본!$O$5:$O$100000,$C$9,전표_원본!$K$5:$K$100000,O37,전표_원본!$M$5:$M$100000,">="&($C$10-12),전표_원본!$M$5:$M$100000,"<"&$C$10)=0,"Y","N"))) | W37: =IF(O37="","",R37+ROW()/1000000) | Y37: 비교 건수 (+) | Z37: =COUNTIFS(전표_원본!$Q$5:$Q$100000,"비교",전표_원본!$P$5:$P$100000,">0")
A38: =IF($K38="","",INDEX($O$32:$O$46,$K38)) | B38: =IF($K38="","",INDEX($P$32:$P$46,$K38)) | C38: =IF($K38="","",INDEX($Q$32:$Q$46,$K38)) | D38: =IF($K38="","",INDEX($R$32:$R$46,$K38)) | E38: =IF(OR($K38="",$C$16<=0),"",D38/$C$16) | F38: =IF($K38="","",INDEX($S$32:$S$46,$K38)) | G38: =IF($K38="","",INDEX($T$32:$T$46,$K38)) | H38: =IF($K38="","",INDEX($U$32:$U$46,$K38)) | I38: =IF($K38="","",INDEX($V$32:$V$46,$K38)) | K38: =IF(COUNT($W$32:$W$46)<7,"",MATCH(LARGE($W$32:$W$46,7),$W$32:$W$46,0)) | N38: =IFERROR(SMALL(전표_원본!$S$5:$S$100000,7),"") | O38: =IF(N38="","",INDEX(전표_원본!$K$1:$K$100000,N38)) | P38: =IF(O38="","",SUMIFS(전표_원본!$P$5:$P$100000,전표_원본!$Q$5:$Q$100000,"당기",전표_원본!$R$5:$R$100000,O38)) | Q38: =IF(O38="","",SUMIFS(전표_원본!$P$5:$P$100000,전표_원본!$Q$5:$Q$100000,"비교",전표_원본!$R$5:$R$100000,O38)) | R38: =IF(O38="","",P38-Q38) | S38: =IF(O38="","",COUNTIFS(전표_원본!$Q$5:$Q$100000,"당기",전표_원본!$R$5:$R$100000,O38,전표_원본!$P$5:$P$100000,">0")) | T38: =IF(O38="","",COUNTIFS(전표_원본!$Q$5:$Q$100000,"비교",전표_원본!$R$5:$R$100000,O38,전표_원본!$P$5:$P$100000,">0")) | U38: =IF(O38="","",SUMPRODUCT(MAX((전표_원본!$Q$5:$Q$100000="당기")*(전표_원본!$R$5:$R$100000=O38)*전표_원본!$P$5:$P$100000))) | V38: =IF(O38="","",IF(LEFT(O38,1)="(","N",IF(COUNTIFS(전표_원본!$O$5:$O$100000,$C$9,전표_원본!$K$5:$K$100000,O38,전표_원본!$M$5:$M$100000,">="&($C$10-12),전표_원본!$M$5:$M$100000,"<"&$C$10)=0,"Y","N"))) | W38: =IF(O38="","",R38+ROW()/1000000) | Y38: 당기 금액 (+) | Z38: =SUMIFS(전표_원본!$P$5:$P$100000,전표_원본!$Q$5:$Q$100000,"당기",전표_원본!$P$5:$P$100000,">0")
A39: =IF($K39="","",INDEX($O$32:$O$46,$K39)) | B39: =IF($K39="","",INDEX($P$32:$P$46,$K39)) | C39: =IF($K39="","",INDEX($Q$32:$Q$46,$K39)) | D39: =IF($K39="","",INDEX($R$32:$R$46,$K39)) | E39: =IF(OR($K39="",$C$16<=0),"",D39/$C$16) | F39: =IF($K39="","",INDEX($S$32:$S$46,$K39)) | G39: =IF($K39="","",INDEX($T$32:$T$46,$K39)) | H39: =IF($K39="","",INDEX($U$32:$U$46,$K39)) | I39: =IF($K39="","",INDEX($V$32:$V$46,$K39)) | K39: =IF(COUNT($W$32:$W$46)<8,"",MATCH(LARGE($W$32:$W$46,8),$W$32:$W$46,0)) | N39: =IFERROR(SMALL(전표_원본!$S$5:$S$100000,8),"") | O39: =IF(N39="","",INDEX(전표_원본!$K$1:$K$100000,N39)) | P39: =IF(O39="","",SUMIFS(전표_원본!$P$5:$P$100000,전표_원본!$Q$5:$Q$100000,"당기",전표_원본!$R$5:$R$100000,O39)) | Q39: =IF(O39="","",SUMIFS(전표_원본!$P$5:$P$100000,전표_원본!$Q$5:$Q$100000,"비교",전표_원본!$R$5:$R$100000,O39)) | R39: =IF(O39="","",P39-Q39) | S39: =IF(O39="","",COUNTIFS(전표_원본!$Q$5:$Q$100000,"당기",전표_원본!$R$5:$R$100000,O39,전표_원본!$P$5:$P$100000,">0")) | T39: =IF(O39="","",COUNTIFS(전표_원본!$Q$5:$Q$100000,"비교",전표_원본!$R$5:$R$100000,O39,전표_원본!$P$5:$P$100000,">0")) | U39: =IF(O39="","",SUMPRODUCT(MAX((전표_원본!$Q$5:$Q$100000="당기")*(전표_원본!$R$5:$R$100000=O39)*전표_원본!$P$5:$P$100000))) | V39: =IF(O39="","",IF(LEFT(O39,1)="(","N",IF(COUNTIFS(전표_원본!$O$5:$O$100000,$C$9,전표_원본!$K$5:$K$100000,O39,전표_원본!$M$5:$M$100000,">="&($C$10-12),전표_원본!$M$5:$M$100000,"<"&$C$10)=0,"Y","N"))) | W39: =IF(O39="","",R39+ROW()/1000000) | Y39: 비교 금액 (+) | Z39: =SUMIFS(전표_원본!$P$5:$P$100000,전표_원본!$Q$5:$Q$100000,"비교",전표_원본!$P$5:$P$100000,">0")
A40: =IF($K40="","",INDEX($O$32:$O$46,$K40)) | B40: =IF($K40="","",INDEX($P$32:$P$46,$K40)) | C40: =IF($K40="","",INDEX($Q$32:$Q$46,$K40)) | D40: =IF($K40="","",INDEX($R$32:$R$46,$K40)) | E40: =IF(OR($K40="",$C$16<=0),"",D40/$C$16) | F40: =IF($K40="","",INDEX($S$32:$S$46,$K40)) | G40: =IF($K40="","",INDEX($T$32:$T$46,$K40)) | H40: =IF($K40="","",INDEX($U$32:$U$46,$K40)) | I40: =IF($K40="","",INDEX($V$32:$V$46,$K40)) | K40: =IF(COUNT($W$32:$W$46)<9,"",MATCH(LARGE($W$32:$W$46,9),$W$32:$W$46,0)) | N40: =IFERROR(SMALL(전표_원본!$S$5:$S$100000,9),"") | O40: =IF(N40="","",INDEX(전표_원본!$K$1:$K$100000,N40)) | P40: =IF(O40="","",SUMIFS(전표_원본!$P$5:$P$100000,전표_원본!$Q$5:$Q$100000,"당기",전표_원본!$R$5:$R$100000,O40)) | Q40: =IF(O40="","",SUMIFS(전표_원본!$P$5:$P$100000,전표_원본!$Q$5:$Q$100000,"비교",전표_원본!$R$5:$R$100000,O40)) | R40: =IF(O40="","",P40-Q40) | S40: =IF(O40="","",COUNTIFS(전표_원본!$Q$5:$Q$100000,"당기",전표_원본!$R$5:$R$100000,O40,전표_원본!$P$5:$P$100000,">0")) | T40: =IF(O40="","",COUNTIFS(전표_원본!$Q$5:$Q$100000,"비교",전표_원본!$R$5:$R$100000,O40,전표_원본!$P$5:$P$100000,">0")) | U40: =IF(O40="","",SUMPRODUCT(MAX((전표_원본!$Q$5:$Q$100000="당기")*(전표_원본!$R$5:$R$100000=O40)*전표_원본!$P$5:$P$100000))) | V40: =IF(O40="","",IF(LEFT(O40,1)="(","N",IF(COUNTIFS(전표_원본!$O$5:$O$100000,$C$9,전표_원본!$K$5:$K$100000,O40,전표_원본!$M$5:$M$100000,">="&($C$10-12),전표_원본!$M$5:$M$100000,"<"&$C$10)=0,"Y","N"))) | W40: =IF(O40="","",R40+ROW()/1000000) | Y40: 건당 당기 | Z40: =IF(Z36=0,0,Z38/Z36)
A41: =IF($K41="","",INDEX($O$32:$O$46,$K41)) | B41: =IF($K41="","",INDEX($P$32:$P$46,$K41)) | C41: =IF($K41="","",INDEX($Q$32:$Q$46,$K41)) | D41: =IF($K41="","",INDEX($R$32:$R$46,$K41)) | E41: =IF(OR($K41="",$C$16<=0),"",D41/$C$16) | F41: =IF($K41="","",INDEX($S$32:$S$46,$K41)) | G41: =IF($K41="","",INDEX($T$32:$T$46,$K41)) | H41: =IF($K41="","",INDEX($U$32:$U$46,$K41)) | I41: =IF($K41="","",INDEX($V$32:$V$46,$K41)) | K41: =IF(COUNT($W$32:$W$46)<10,"",MATCH(LARGE($W$32:$W$46,10),$W$32:$W$46,0)) | N41: =IFERROR(SMALL(전표_원본!$S$5:$S$100000,10),"") | O41: =IF(N41="","",INDEX(전표_원본!$K$1:$K$100000,N41)) | P41: =IF(O41="","",SUMIFS(전표_원본!$P$5:$P$100000,전표_원본!$Q$5:$Q$100000,"당기",전표_원본!$R$5:$R$100000,O41)) | Q41: =IF(O41="","",SUMIFS(전표_원본!$P$5:$P$100000,전표_원본!$Q$5:$Q$100000,"비교",전표_원본!$R$5:$R$100000,O41)) | R41: =IF(O41="","",P41-Q41) | S41: =IF(O41="","",COUNTIFS(전표_원본!$Q$5:$Q$100000,"당기",전표_원본!$R$5:$R$100000,O41,전표_원본!$P$5:$P$100000,">0")) | T41: =IF(O41="","",COUNTIFS(전표_원본!$Q$5:$Q$100000,"비교",전표_원본!$R$5:$R$100000,O41,전표_원본!$P$5:$P$100000,">0")) | U41: =IF(O41="","",SUMPRODUCT(MAX((전표_원본!$Q$5:$Q$100000="당기")*(전표_원본!$R$5:$R$100000=O41)*전표_원본!$P$5:$P$100000))) | V41: =IF(O41="","",IF(LEFT(O41,1)="(","N",IF(COUNTIFS(전표_원본!$O$5:$O$100000,$C$9,전표_원본!$K$5:$K$100000,O41,전표_원본!$M$5:$M$100000,">="&($C$10-12),전표_원본!$M$5:$M$100000,"<"&$C$10)=0,"Y","N"))) | W41: =IF(O41="","",R41+ROW()/1000000) | Y41: 건당 비교 | Z41: =IF(Z37=0,0,Z39/Z37)
A42: =IF($K42="","",INDEX($O$32:$O$46,$K42)) | B42: =IF($K42="","",INDEX($P$32:$P$46,$K42)) | C42: =IF($K42="","",INDEX($Q$32:$Q$46,$K42)) | D42: =IF($K42="","",INDEX($R$32:$R$46,$K42)) | E42: =IF(OR($K42="",$C$16<=0),"",D42/$C$16) | F42: =IF($K42="","",INDEX($S$32:$S$46,$K42)) | G42: =IF($K42="","",INDEX($T$32:$T$46,$K42)) | H42: =IF($K42="","",INDEX($U$32:$U$46,$K42)) | I42: =IF($K42="","",INDEX($V$32:$V$46,$K42)) | K42: =IF(COUNT($W$32:$W$46)<11,"",MATCH(LARGE($W$32:$W$46,11),$W$32:$W$46,0)) | N42: =IFERROR(SMALL(전표_원본!$S$5:$S$100000,11),"") | O42: =IF(N42="","",INDEX(전표_원본!$K$1:$K$100000,N42)) | P42: =IF(O42="","",SUMIFS(전표_원본!$P$5:$P$100000,전표_원본!$Q$5:$Q$100000,"당기",전표_원본!$R$5:$R$100000,O42)) | Q42: =IF(O42="","",SUMIFS(전표_원본!$P$5:$P$100000,전표_원본!$Q$5:$Q$100000,"비교",전표_원본!$R$5:$R$100000,O42)) | R42: =IF(O42="","",P42-Q42) | S42: =IF(O42="","",COUNTIFS(전표_원본!$Q$5:$Q$100000,"당기",전표_원본!$R$5:$R$100000,O42,전표_원본!$P$5:$P$100000,">0")) | T42: =IF(O42="","",COUNTIFS(전표_원본!$Q$5:$Q$100000,"비교",전표_원본!$R$5:$R$100000,O42,전표_원본!$P$5:$P$100000,">0")) | U42: =IF(O42="","",SUMPRODUCT(MAX((전표_원본!$Q$5:$Q$100000="당기")*(전표_원본!$R$5:$R$100000=O42)*전표_원본!$P$5:$P$100000))) | V42: =IF(O42="","",IF(LEFT(O42,1)="(","N",IF(COUNTIFS(전표_원본!$O$5:$O$100000,$C$9,전표_원본!$K$5:$K$100000,O42,전표_원본!$M$5:$M$100000,">="&($C$10-12),전표_원본!$M$5:$M$100000,"<"&$C$10)=0,"Y","N"))) | W42: =IF(O42="","",R42+ROW()/1000000) | Y42: 신규 거래처 증감 | Z42: =SUMIFS($R$32:$R$46,$V$32:$V$46,"Y")
A43: =IF($K43="","",INDEX($O$32:$O$46,$K43)) | B43: =IF($K43="","",INDEX($P$32:$P$46,$K43)) | C43: =IF($K43="","",INDEX($Q$32:$Q$46,$K43)) | D43: =IF($K43="","",INDEX($R$32:$R$46,$K43)) | E43: =IF(OR($K43="",$C$16<=0),"",D43/$C$16) | F43: =IF($K43="","",INDEX($S$32:$S$46,$K43)) | G43: =IF($K43="","",INDEX($T$32:$T$46,$K43)) | H43: =IF($K43="","",INDEX($U$32:$U$46,$K43)) | I43: =IF($K43="","",INDEX($V$32:$V$46,$K43)) | K43: =IF(COUNT($W$32:$W$46)<12,"",MATCH(LARGE($W$32:$W$46,12),$W$32:$W$46,0)) | N43: =IFERROR(SMALL(전표_원본!$S$5:$S$100000,12),"") | O43: =IF(N43="","",INDEX(전표_원본!$K$1:$K$100000,N43)) | P43: =IF(O43="","",SUMIFS(전표_원본!$P$5:$P$100000,전표_원본!$Q$5:$Q$100000,"당기",전표_원본!$R$5:$R$100000,O43)) | Q43: =IF(O43="","",SUMIFS(전표_원본!$P$5:$P$100000,전표_원본!$Q$5:$Q$100000,"비교",전표_원본!$R$5:$R$100000,O43)) | R43: =IF(O43="","",P43-Q43) | S43: =IF(O43="","",COUNTIFS(전표_원본!$Q$5:$Q$100000,"당기",전표_원본!$R$5:$R$100000,O43,전표_원본!$P$5:$P$100000,">0")) | T43: =IF(O43="","",COUNTIFS(전표_원본!$Q$5:$Q$100000,"비교",전표_원본!$R$5:$R$100000,O43,전표_원본!$P$5:$P$100000,">0")) | U43: =IF(O43="","",SUMPRODUCT(MAX((전표_원본!$Q$5:$Q$100000="당기")*(전표_원본!$R$5:$R$100000=O43)*전표_원본!$P$5:$P$100000))) | V43: =IF(O43="","",IF(LEFT(O43,1)="(","N",IF(COUNTIFS(전표_원본!$O$5:$O$100000,$C$9,전표_원본!$K$5:$K$100000,O43,전표_원본!$M$5:$M$100000,">="&($C$10-12),전표_원본!$M$5:$M$100000,"<"&$C$10)=0,"Y","N"))) | W43: =IF(O43="","",R43+ROW()/1000000) | Y43: 신규 거래처 수 | Z43: =COUNTIFS($V$32:$V$46,"Y",$R$32:$R$46,">0")
A44: =IF($K44="","",INDEX($O$32:$O$46,$K44)) | B44: =IF($K44="","",INDEX($P$32:$P$46,$K44)) | C44: =IF($K44="","",INDEX($Q$32:$Q$46,$K44)) | D44: =IF($K44="","",INDEX($R$32:$R$46,$K44)) | E44: =IF(OR($K44="",$C$16<=0),"",D44/$C$16) | F44: =IF($K44="","",INDEX($S$32:$S$46,$K44)) | G44: =IF($K44="","",INDEX($T$32:$T$46,$K44)) | H44: =IF($K44="","",INDEX($U$32:$U$46,$K44)) | I44: =IF($K44="","",INDEX($V$32:$V$46,$K44)) | K44: =IF(COUNT($W$32:$W$46)<13,"",MATCH(LARGE($W$32:$W$46,13),$W$32:$W$46,0)) | N44: =IFERROR(SMALL(전표_원본!$S$5:$S$100000,13),"") | O44: =IF(N44="","",INDEX(전표_원본!$K$1:$K$100000,N44)) | P44: =IF(O44="","",SUMIFS(전표_원본!$P$5:$P$100000,전표_원본!$Q$5:$Q$100000,"당기",전표_원본!$R$5:$R$100000,O44)) | Q44: =IF(O44="","",SUMIFS(전표_원본!$P$5:$P$100000,전표_원본!$Q$5:$Q$100000,"비교",전표_원본!$R$5:$R$100000,O44)) | R44: =IF(O44="","",P44-Q44) | S44: =IF(O44="","",COUNTIFS(전표_원본!$Q$5:$Q$100000,"당기",전표_원본!$R$5:$R$100000,O44,전표_원본!$P$5:$P$100000,">0")) | T44: =IF(O44="","",COUNTIFS(전표_원본!$Q$5:$Q$100000,"비교",전표_원본!$R$5:$R$100000,O44,전표_원본!$P$5:$P$100000,">0")) | U44: =IF(O44="","",SUMPRODUCT(MAX((전표_원본!$Q$5:$Q$100000="당기")*(전표_원본!$R$5:$R$100000=O44)*전표_원본!$P$5:$P$100000))) | V44: =IF(O44="","",IF(LEFT(O44,1)="(","N",IF(COUNTIFS(전표_원본!$O$5:$O$100000,$C$9,전표_원본!$K$5:$K$100000,O44,전표_원본!$M$5:$M$100000,">="&($C$10-12),전표_원본!$M$5:$M$100000,"<"&$C$10)=0,"Y","N"))) | W44: =IF(O44="","",R44+ROW()/1000000) | Y44: 첫 신규 거래처 | Z44: =IFERROR(INDEX($A$32:$A$46,MATCH("Y",$I$32:$I$46,0)),"")
...

Sheet 변동분석
A1: TRACE · 변동분석 (부서 × 계정)
A2: A·C열만 입력 · 전월/전분기/전년동월 비교 → 예산 점검 → 주의 점수 · 금액: 보고단위
A3: ="기준: "&INT((설정!$C$20-1)/12)&"-"&TEXT(MOD(설정!$C$20-1,12)+1,"00")&" · 단위: "&설정!$C$9
F5: ③ 변동 | P5: ④ 예산 점검 | Z5: ⑤ 주의
A6: 부서코드 | B6: 부서명 | C6: G/L 계정 | D6: 계정명 | E6: 키 | F6: 당월 | G6: 전월 | H6: 전월 대비 | I6: 전년 동월 | J6: 전년동월 대비 | K6: 당분기 | L6: 전분기 | M6: 전분기 대비 | N6: 주요 증가액 | O6: 이상치 (z) | P6: 연간가용 (배정+조정) | Q6: 누계실적 | R6: 잔여 | S6: 남은기간 예상 A (최근추세) | T6: 남은기간 예상 B (전년패턴) | U6: 예상 연간실적 | V6: 예상 소진율 | W6: 예산판정 | X6: 부족 예상액 | Y6: 소진 예상월 | Z6: 빠른 신호 (당월) | AA6: 주의 점수 | AB6: 정렬키 | AC6: 단건비중 | AD6: SA순증 | AE6: 음수건수 | AF6: 증가액 (30) | AG6: 증가율 (20) | AH6: 이상치 (25) | AI6: 예산 (25)
A7: D100 | B7: =IF($A7="","",IFERROR(INDEX(부서매핑!$D$5:$D$504,MATCH($A7,부서매핑!$C$5:$C$504,0)),"부서매핑 없음")) | C7: 62101000 | D7: =IF($A7="","",IFERROR(INDEX(계정매핑!$B$5:$B$504,MATCH($C7&"",계정매핑!$A$5:$A$504,0)),"계정매핑 없음")) | E7: =IF($A7="","",$A7&"|"&$C7) | F7: =IF($A7="","",월별집계!$Z7) | G7: =IF($A7="","",월별집계!$Y7) | H7: =IF($A7="","",IF(G7<=0,IF(F7>0,1,0),F7/G7-1)) | I7: =IF($A7="","",월별집계!$N7) | J7: =IF($A7="","",IF(I7<=0,IF(F7>0,1,0),F7/I7-1)) | K7: =IF($A7="","",SUMIFS(월별집계!$C7:$Z7,월별집계!$C$5:$Z$5,">="&설정!$C$22,월별집계!$C$5:$Z$5,"<="&설정!$C$20)) | L7: =IF($A7="","",SUMIFS(월별집계!$C7:$Z7,월별집계!$C$5:$Z$5,">="&(설정!$C$22-3),월별집계!$C$5:$Z$5,"<="&(설정!$C$20-3))) | M7: =IF($A7="","",IF(L7<=0,IF(K7>0,1,0),K7/L7-1)) | N7: =IF($A7="","",MAX(F7-G7,F7-I7)) | O7: =IF($A7="","",IFERROR((월별집계!$Z7-AVERAGE(월별집계!N7:Y7))/STDEV(월별집계!N7:Y7),0)) | P7: =IF($A7="","",SUMIFS(예산판_원본!$O$5:$O$5000,예산판_원본!$L$5:$L$5000,$E7,예산판_원본!$M$5:$M$5000,설정!$C$6)) | Q7: =IF($A7="","",SUMIFS(월별집계!$C7:$Z7,월별집계!$C$5:$Z$5,">="&(설정!$C$6*12+1),월별집계!$C$5:$Z$5,"<="&설정!$C$20)) | R7: =IF($A7="","",P7-Q7) | S7: =IF($A7="","",AVERAGE(월별집계!X7:Z7)*(12-설정!$C$7)) | T7: =IF($A7="","",IFERROR(Q7/(SUMIFS(월별집계!$C7:$Z7,월별집계!$C$5:$Z$5,">="&((설정!$C$6-1)*12+1),월별집계!$C$5:$Z$5,"<="&(설정!$C$20-12))/SUMIFS(월별집계!$C7:$Z7,월별집계!$C$5:$Z$5,">="&((설정!$C$6-1)*12+1),월별집계!$C$5:$Z$5,"<="&((설정!$C$6-1)*12+12)))-Q7,S7)) | U7: =IF($A7="","",Q7+MAX(S7,T7)) | V7: =IF($A7="","",IF(P7=0,0,U7/P7)) | W7: =IF($A7="","",IF(AND(P7=0,Q7>0),"무예산",IF(P7=0,"-",IF(V7>설정!$C$12,"부족 예상",IF(V7>설정!$C$11,"주의","여유"))))) | X7: =IF($A7="","",IF(P7=0,0,MAX(0,U7-P7))) | Y7: =IF($A7="","",IF(OR(W7<>"부족 예상",설정!$C$7=12),"",IF(R7<=0,"이미 초과",MIN(12,설정!$C$7+ROUNDUP(R7/(MAX(S7,T7)/(12-설정!$C$7)),0))&"월"))) | Z7: =IF($A7="","",TRIM(IF(N(AC7)>=설정!$C$14,"단건"&TEXT(AC7,"0%")&" ","")&IF(AND(N7>0,AD7>0),IF(AD7/N7>=설정!$C$16,"SA대체 ",""),"")&IF(AE7>0,"역분개"&AE7&"건 ","")&IF(O7>=설정!$C$13,"이상치 ","")&IF(AND(I7=0,F7>0),"신규지출 ",""))) | AA7: =IF($A7="","",ROUND((AF7+AG7+AH7+AI7)*IF(AND(F7<설정!$C$10,N7<설정!$C$10),0.3,1),1)) | AB7: =IF($A7="","",AA7+ROW()/1000000) | AC7: =IF(OR($A7="",N7<=0),"",SUMPRODUCT(MAX((전표_원본!$O$5:$O$100000=$E7)*(전표_원본!$M$5:$M$100000=설정!$C$20)*전표_원본!$P$5:$P$100000))/N7) | AD7: =IF($A7="","",SUMIFS(전표_원본!$P$5:$P$100000,전표_원본!$O$5:$O$100000,$E7,전표_원본!$M$5:$M$100000,설정!$C$20,전표_원본!$E$5:$E$100000,"SA")-SUMIFS(전표_원본!$P$5:$P$100000,전표_원본!$O$5:$O$100000,$E7,전표_원본!$M$5:$M$100000,설정!$C$20-1,전표_원본!$E$5:$E$100000,"SA")) | AE7: =IF($A7="","",COUNTIFS(전표_원본!$O$5:$O$100000,$E7,전표_원본!$M$5:$M$100000,설정!$C$20,전표_원본!$P$5:$P$100000,"<0")) | AF7: =IF($A7="","",MIN(MAX(0,N7)/(설정!$C$10*5),1)*30) | AG7: =IF($A7="","",MIN(MAX(0,H7,J7),1)*20) | AH7: =IF($A7="","",MIN(MAX(0,O7)/3,1)*25) | AI7: =IF($A7="","",IF(OR(W7="부족 예상",W7="무예산"),25,IF(W7="주의",15,0)))
A8: D100 | B8: =IF($A8="","",IFERROR(INDEX(부서매핑!$D$5:$D$504,MATCH($A8,부서매핑!$C$5:$C$504,0)),"부서매핑 없음")) | C8: 62102000 | D8: =IF($A8="","",IFERROR(INDEX(계정매핑!$B$5:$B$504,MATCH($C8&"",계정매핑!$A$5:$A$504,0)),"계정매핑 없음")) | E8: =IF($A8="","",$A8&"|"&$C8) | F8: =IF($A8="","",월별집계!$Z8) | G8: =IF($A8="","",월별집계!$Y8) | H8: =IF($A8="","",IF(G8<=0,IF(F8>0,1,0),F8/G8-1)) | I8: =IF($A8="","",월별집계!$N8) | J8: =IF($A8="","",IF(I8<=0,IF(F8>0,1,0),F8/I8-1)) | K8: =IF($A8="","",SUMIFS(월별집계!$C8:$Z8,월별집계!$C$5:$Z$5,">="&설정!$C$22,월별집계!$C$5:$Z$5,"<="&설정!$C$20)) | L8: =IF($A8="","",SUMIFS(월별집계!$C8:$Z8,월별집계!$C$5:$Z$5,">="&(설정!$C$22-3),월별집계!$C$5:$Z$5,"<="&(설정!$C$20-3))) | M8: =IF($A8="","",IF(L8<=0,IF(K8>0,1,0),K8/L8-1)) | N8: =IF($A8="","",MAX(F8-G8,F8-I8)) | O8: =IF($A8="","",IFERROR((월별집계!$Z8-AVERAGE(월별집계!N8:Y8))/STDEV(월별집계!N8:Y8),0)) | P8: =IF($A8="","",SUMIFS(예산판_원본!$O$5:$O$5000,예산판_원본!$L$5:$L$5000,$E8,예산판_원본!$M$5:$M$5000,설정!$C$6)) | Q8: =IF($A8="","",SUMIFS(월별집계!$C8:$Z8,월별집계!$C$5:$Z$5,">="&(설정!$C$6*12+1),월별집계!$C$5:$Z$5,"<="&설정!$C$20)) | R8: =IF($A8="","",P8-Q8) | S8: =IF($A8="","",AVERAGE(월별집계!X8:Z8)*(12-설정!$C$7)) | T8: =IF($A8="","",IFERROR(Q8/(SUMIFS(월별집계!$C8:$Z8,월별집계!$C$5:$Z$5,">="&((설정!$C$6-1)*12+1),월별집계!$C$5:$Z$5,"<="&(설정!$C$20-12))/SUMIFS(월별집계!$C8:$Z8,월별집계!$C$5:$Z$5,">="&((설정!$C$6-1)*12+1),월별집계!$C$5:$Z$5,"<="&((설정!$C$6-1)*12+12)))-Q8,S8)) | U8: =IF($A8="","",Q8+MAX(S8,T8)) | V8: =IF($A8="","",IF(P8=0,0,U8/P8)) | W8: =IF($A8="","",IF(AND(P8=0,Q8>0),"무예산",IF(P8=0,"-",IF(V8>설정!$C$12,"부족 예상",IF(V8>설정!$C$11,"주의","여유"))))) | X8: =IF($A8="","",IF(P8=0,0,MAX(0,U8-P8))) | Y8: =IF($A8="","",IF(OR(W8<>"부족 예상",설정!$C$7=12),"",IF(R8<=0,"이미 초과",MIN(12,설정!$C$7+ROUNDUP(R8/(MAX(S8,T8)/(12-설정!$C$7)),0))&"월"))) | Z8: =IF($A8="","",TRIM(IF(N(AC8)>=설정!$C$14,"단건"&TEXT(AC8,"0%")&" ","")&IF(AND(N8>0,AD8>0),IF(AD8/N8>=설정!$C$16,"SA대체 ",""),"")&IF(AE8>0,"역분개"&AE8&"건 ","")&IF(O8>=설정!$C$13,"이상치 ","")&IF(AND(I8=0,F8>0),"신규지출 ",""))) | AA8: =IF($A8="","",ROUND((AF8+AG8+AH8+AI8)*IF(AND(F8<설정!$C$10,N8<설정!$C$10),0.3,1),1)) | AB8: =IF($A8="","",AA8+ROW()/1000000) | AC8: =IF(OR($A8="",N8<=0),"",SUMPRODUCT(MAX((전표_원본!$O$5:$O$100000=$E8)*(전표_원본!$M$5:$M$100000=설정!$C$20)*전표_원본!$P$5:$P$100000))/N8) | AD8: =IF($A8="","",SUMIFS(전표_원본!$P$5:$P$100000,전표_원본!$O$5:$O$100000,$E8,전표_원본!$M$5:$M$100000,설정!$C$20,전표_원본!$E$5:$E$100000,"SA")-SUMIFS(전표_원본!$P$5:$P$100000,전표_원본!$O$5:$O$100000,$E8,전표_원본!$M$5:$M$100000,설정!$C$20-1,전표_원본!$E$5:$E$100000,"SA")) | AE8: =IF($A8="","",COUNTIFS(전표_원본!$O$5:$O$100000,$E8,전표_원본!$M$5:$M$100000,설정!$C$20,전표_원본!$P$5:$P$100000,"<0")) | AF8: =IF($A8="","",MIN(MAX(0,N8)/(설정!$C$10*5),1)*30) | AG8: =IF($A8="","",MIN(MAX(0,H8,J8),1)*20) | AH8: =IF($A8="","",MIN(MAX(0,O8)/3,1)*25) | AI8: =IF($A8="","",IF(OR(W8="부족 예상",W8="무예산"),25,IF(W8="주의",15,0)))
A9: D100 | B9: =IF($A9="","",IFERROR(INDEX(부서매핑!$D$5:$D$504,MATCH($A9,부서매핑!$C$5:$C$504,0)),"부서매핑 없음")) | C9: 62201000 | D9: =IF($A9="","",IFERROR(INDEX(계정매핑!$B$5:$B$504,MATCH($C9&"",계정매핑!$A$5:$A$504,0)),"계정매핑 없음")) | E9: =IF($A9="","",$A9&"|"&$C9) | F9: =IF($A9="","",월별집계!$Z9) | G9: =IF($A9="","",월별집계!$Y9) | H9: =IF($A9="","",IF(G9<=0,IF(F9>0,1,0),F9/G9-1)) | I9: =IF($A9="","",월별집계!$N9) | J9: =IF($A9="","",IF(I9<=0,IF(F9>0,1,0),F9/I9-1)) | K9: =IF($A9="","",SUMIFS(월별집계!$C9:$Z9,월별집계!$C$5:$Z$5,">="&설정!$C$22,월별집계!$C$5:$Z$5,"<="&설정!$C$20)) | L9: =IF($A9="","",SUMIFS(월별집계!$C9:$Z9,월별집계!$C$5:$Z$5,">="&(설정!$C$22-3),월별집계!$C$5:$Z$5,"<="&(설정!$C$20-3))) | M9: =IF($A9="","",IF(L9<=0,IF(K9>0,1,0),K9/L9-1)) | N9: =IF($A9="","",MAX(F9-G9,F9-I9)) | O9: =IF($A9="","",IFERROR((월별집계!$Z9-AVERAGE(월별집계!N9:Y9))/STDEV(월별집계!N9:Y9),0)) | P9: =IF($A9="","",SUMIFS(예산판_원본!$O$5:$O$5000,예산판_원본!$L$5:$L$5000,$E9,예산판_원본!$M$5:$M$5000,설정!$C$6)) | Q9: =IF($A9="","",SUMIFS(월별집계!$C9:$Z9,월별집계!$C$5:$Z$5,">="&(설정!$C$6*12+1),월별집계!$C$5:$Z$5,"<="&설정!$C$20)) | R9: =IF($A9="","",P9-Q9) | S9: =IF($A9="","",AVERAGE(월별집계!X9:Z9)*(12-설정!$C$7)) | T9: =IF($A9="","",IFERROR(Q9/(SUMIFS(월별집계!$C9:$Z9,월별집계!$C$5:$Z$5,">="&((설정!$C$6-1)*12+1),월별집계!$C$5:$Z$5,"<="&(설정!$C$20-12))/SUMIFS(월별집계!$C9:$Z9,월별집계!$C$5:$Z$5,">="&((설정!$C$6-1)*12+1),월별집계!$C$5:$Z$5,"<="&((설정!$C$6-1)*12+12)))-Q9,S9)) | U9: =IF($A9="","",Q9+MAX(S9,T9)) | V9: =IF($A9="","",IF(P9=0,0,U9/P9)) | W9: =IF($A9="","",IF(AND(P9=0,Q9>0),"무예산",IF(P9=0,"-",IF(V9>설정!$C$12,"부족 예상",IF(V9>설정!$C$11,"주의","여유"))))) | X9: =IF($A9="","",IF(P9=0,0,MAX(0,U9-P9))) | Y9: =IF($A9="","",IF(OR(W9<>"부족 예상",설정!$C$7=12),"",IF(R9<=0,"이미 초과",MIN(12,설정!$C$7+ROUNDUP(R9/(MAX(S9,T9)/(12-설정!$C$7)),0))&"월"))) | Z9: =IF($A9="","",TRIM(IF(N(AC9)>=설정!$C$14,"단건"&TEXT(AC9,"0%")&" ","")&IF(AND(N9>0,AD9>0),IF(AD9/N9>=설정!$C$16,"SA대체 ",""),"")&IF(AE9>0,"역분개"&AE9&"건 ","")&IF(O9>=설정!$C$13,"이상치 ","")&IF(AND(I9=0,F9>0),"신규지출 ",""))) | AA9: =IF($A9="","",ROUND((AF9+AG9+AH9+AI9)*IF(AND(F9<설정!$C$10,N9<설정!$C$10),0.3,1),1)) | AB9: =IF($A9="","",AA9+ROW()/1000000) | AC9: =IF(OR($A9="",N9<=0),"",SUMPRODUCT(MAX((전표_원본!$O$5:$O$100000=$E9)*(전표_원본!$M$5:$M$100000=설정!$C$20)*전표_원본!$P$5:$P$100000))/N9) | AD9: =IF($A9="","",SUMIFS(전표_원본!$P$5:$P$100000,전표_원본!$O$5:$O$100000,$E9,전표_원본!$M$5:$M$100000,설정!$C$20,전표_원본!$E$5:$E$100000,"SA")-SUMIFS(전표_원본!$P$5:$P$100000,전표_원본!$O$5:$O$100000,$E9,전표_원본!$M$5:$M$100000,설정!$C$20-1,전표_원본!$E$5:$E$100000,"SA")) | AE9: =IF($A9="","",COUNTIFS(전표_원본!$O$5:$O$100000,$E9,전표_원본!$M$5:$M$100000,설정!$C$20,전표_원본!$P$5:$P$100000,"<0")) | AF9: =IF($A9="","",MIN(MAX(0,N9)/(설정!$C$10*5),1)*30) | AG9: =IF($A9="","",MIN(MAX(0,H9,J9),1)*20) | AH9: =IF($A9="","",MIN(MAX(0,O9)/3,1)*25) | AI9: =IF($A9="","",IF(OR(W9="부족 예상",W9="무예산"),25,IF(W9="주의",15,0)))
A10: D100 | B10: =IF($A10="","",IFERROR(INDEX(부서매핑!$D$5:$D$504,MATCH($A10,부서매핑!$C$5:$C$504,0)),"부서매핑 없음")) | C10: 62301000 | D10: =IF($A10="","",IFERROR(INDEX(계정매핑!$B$5:$B$504,MATCH($C10&"",계정매핑!$A$5:$A$504,0)),"계정매핑 없음")) | E10: =IF($A10="","",$A10&"|"&$C10) | F10: =IF($A10="","",월별집계!$Z10) | G10: =IF($A10="","",월별집계!$Y10) | H10: =IF($A10="","",IF(G10<=0,IF(F10>0,1,0),F10/G10-1)) | I10: =IF($A10="","",월별집계!$N10) | J10: =IF($A10="","",IF(I10<=0,IF(F10>0,1,0),F10/I10-1)) | K10: =IF($A10="","",SUMIFS(월별집계!$C10:$Z10,월별집계!$C$5:$Z$5,">="&설정!$C$22,월별집계!$C$5:$Z$5,"<="&설정!$C$20)) | L10: =IF($A10="","",SUMIFS(월별집계!$C10:$Z10,월별집계!$C$5:$Z$5,">="&(설정!$C$22-3),월별집계!$C$5:$Z$5,"<="&(설정!$C$20-3))) | M10: =IF($A10="","",IF(L10<=0,IF(K10>0,1,0),K10/L10-1)) | N10: =IF($A10="","",MAX(F10-G10,F10-I10)) | O10: =IF($A10="","",IFERROR((월별집계!$Z10-AVERAGE(월별집계!N10:Y10))/STDEV(월별집계!N10:Y10),0)) | P10: =IF($A10="","",SUMIFS(예산판_원본!$O$5:$O$5000,예산판_원본!$L$5:$L$5000,$E10,예산판_원본!$M$5:$M$5000,설정!$C$6)) | Q10: =IF($A10="","",SUMIFS(월별집계!$C10:$Z10,월별집계!$C$5:$Z$5,">="&(설정!$C$6*12+1),월별집계!$C$5:$Z$5,"<="&설정!$C$20)) | R10: =IF($A10="","",P10-Q10) | S10: =IF($A10="","",AVERAGE(월별집계!X10:Z10)*(12-설정!$C$7)) | T10: =IF($A10="","",IFERROR(Q10/(SUMIFS(월별집계!$C10:$Z10,월별집계!$C$5:$Z$5,">="&((설정!$C$6-1)*12+1),월별집계!$C$5:$Z$5,"<="&(설정!$C$20-12))/SUMIFS(월별집계!$C10:$Z10,월별집계!$C$5:$Z$5,">="&((설정!$C$6-1)*12+1),월별집계!$C$5:$Z$5,"<="&((설정!$C$6-1)*12+12)))-Q10,S10)) | U10: =IF($A10="","",Q10+MAX(S10,T10)) | V10: =IF($A10="","",IF(P10=0,0,U10/P10)) | W10: =IF($A10="","",IF(AND(P10=0,Q10>0),"무예산",IF(P10=0,"-",IF(V10>설정!$C$12,"부족 예상",IF(V10>설정!$C$11,"주의","여유"))))) | X10: =IF($A10="","",IF(P10=0,0,MAX(0,U10-P10))) | Y10: =IF($A10="","",IF(OR(W10<>"부족 예상",설정!$C$7=12),"",IF(R10<=0,"이미 초과",MIN(12,설정!$C$7+ROUNDUP(R10/(MAX(S10,T10)/(12-설정!$C$7)),0))&"월"))) | Z10: =IF($A10="","",TRIM(IF(N(AC10)>=설정!$C$14,"단건"&TEXT(AC10,"0%")&" ","")&IF(AND(N10>0,AD10>0),IF(AD10/N10>=설정!$C$16,"SA대체 ",""),"")&IF(AE10>0,"역분개"&AE10&"건 ","")&IF(O10>=설정!$C$13,"이상치 ","")&IF(AND(I10=0,F10>0),"신규지출 ",""))) | AA10: =IF($A10="","",ROUND((AF10+AG10+AH10+AI10)*IF(AND(F10<설정!$C$10,N10<설정!$C$10),0.3,1),1)) | AB10: =IF($A10="","",AA10+ROW()/1000000) | AC10: =IF(OR($A10="",N10<=0),"",SUMPRODUCT(MAX((전표_원본!$O$5:$O$100000=$E10)*(전표_원본!$M$5:$M$100000=설정!$C$20)*전표_원본!$P$5:$P$100000))/N10) | AD10: =IF($A10="","",SUMIFS(전표_원본!$P$5:$P$100000,전표_원본!$O$5:$O$100000,$E10,전표_원본!$M$5:$M$100000,설정!$C$20,전표_원본!$E$5:$E$100000,"SA")-SUMIFS(전표_원본!$P$5:$P$100000,전표_원본!$O$5:$O$100000,$E10,전표_원본!$M$5:$M$100000,설정!$C$20-1,전표_원본!$E$5:$E$100000,"SA")) | AE10: =IF($A10="","",COUNTIFS(전표_원본!$O$5:$O$100000,$E10,전표_원본!$M$5:$M$100000,설정!$C$20,전표_원본!$P$5:$P$100000,"<0")) | AF10: =IF($A10="","",MIN(MAX(0,N10)/(설정!$C$10*5),1)*30) | AG10: =IF($A10="","",MIN(MAX(0,H10,J10),1)*20) | AH10: =IF($A10="","",MIN(MAX(0,O10)/3,1)*25) | AI10: =IF($A10="","",IF(OR(W10="부족 예상",W10="무예산"),25,IF(W10="주의",15,0)))
