Workbook

Sheet 안내
A1: 예산 대비 실적 리포트 v0.1
A2: Excel 2016 호환 · 예시 데이터는 가상 수치 · 단위는 설정 시트에서 변경
A4: 최초 설치 (1회)
A5: 1. 이 파일을 연 상태에서 Alt+F11 → [파일] → [파일 가져오기] → modBudget.bas 선택
A6: 2. Alt+F8 → SetupButtons 실행 → 설정 시트에 버튼 6개가 생깁니다
A7: 3. [다른 이름으로 저장] → 파일 형식 'Excel 매크로 사용 통합 문서 (*.xlsm)'
A8: 4. 대시보드.html 을 이 엑셀 파일과 같은 폴더에 둡니다
A10: 매월 사용 순서
A11: 1. 설정 시트에서 기준연도·기준월 변경
A12: 2. [실적 불러오기] → 자체 화면에서 내려받은 파일 선택 (전년 실적 포함, 열 순서 무관)
A13: 3. [예산 불러오기] → 예산 파일 선택 (예산이 바뀐 달에만)
A14: 4. 자가진단 시트가 '전체 정상'인지 확인 (불러오기 후 자동으로 결과 팝업)
... A31: 시트 구성
A32: 시트 | B32: 역할
A33: 설정 | B33: 기준월·단위·경고 기준, 열 매핑, 매크로 버튼
A34: 자가진단 | B34: 데이터 구조·매핑·대사 점검 (15개 항목)
A35: 리포트 | B35: 인쇄용 1장 보고서 (PDF 출력 대상)
A36: 요약 | B36: 부서별·예산항목별 요약, 부서별 보고 문구 초안
A37: 예외목록 | B37: 경고 기준을 넘은 항목, 차이 금액 큰 순
A38: 월별추이 | B38: 부서별 월 예산·실적·전년실적 (대시보드 원천)
A39: 집계 | B39: 부서 × 예산항목 상세 (모든 계산의 중심)
A40: 코멘트 | B40: 예외 항목 원인·조치 입력 (월별 누적)
A41: 마감이력 | B41: [월마감 저장] 시 집계 결과 보관
A42: 예산_원본 | B42: 예산 파일 (부서 × 항목 × 12개월)
A43: 실적_원본 | B43: 자체 화면 실적 (코스트센터 × G/L × 월)
... A45: 부서매핑 | B45: 코스트센터 → 부서

Sheet 설정
A1: 설정
A2: 노란 칸만 바꾸세요 · 오른쪽 버튼은 SetupButtons 실행 후 생깁니다
B4: 항목 | C4: 값 | D4: 설명 | F4: 단위 | G4: 원 환산 | I4: 매크로 버튼
B5: 회사명 | C5: 예시보험㈜ | D5: 리포트 제목에 표시 | F5: 원 | G5: 1
B6: 기준연도 | C6: 2026 | D6: 보고 대상 연도 | F6: 천원 | G6: 1000
B7: 기준월 | C7: 9 | D7: 1~12. 누계는 1월~기준월 | F7: 백만원 | G7: 1000000
B8: 적용 예산버전 | C8: 본예산 | D8: 예산_원본 B열(예산버전) 중 집계할 버전
B9: 예산_원본 금액단위 | C9: 천원 | D9: 예산 파일에 적힌 금액 단위
B10: 실적_원본 금액단위 | C10: 원 | D10: 자체 화면 금액 단위
B11: 보고 단위 | C11: 천원 | D11: 모든 집계·리포트 표시 단위
B12: 경고 기준: 집행률 차이 | C12: 0.1 | D12: 누계 집행률이 100% ± 이 값을 벗어나면 초과/과소
B13: 경고 기준: 금액 하한 (보고단위) | C13: 10000 | D13: 누계 차이가 이 금액 미만이면 집행률과 무관하게 정상
B14: (계산) 예산 환산계수 | C14: =INDEX($G$5:$G$7,MATCH(C9,$F$5:$F$7,0))/INDEX($G$5:$G$7,MATCH(C11,$F$5:$F$7,0)) | D14: 예산_원본 금액 × 계수 = 보고단위
B15: (계산) 실적 환산계수 | C15: =INDEX($G$5:$G$7,MATCH(C10,$F$5:$F$7,0))/INDEX($G$5:$G$7,MATCH(C11,$F$5:$F$7,0)) | D15: 실적_원본 금액 × 계수 = 보고단위
B19: 열 매핑 - 실적 (자체 화면)
B20: 표준 열 (실적_원본) | C20: 원본 화면 열 이름 | D20: 설명
B21: A열 회계연도 | C21: 회계연도 | D21: 숫자·텍스트 모두 가능
B22: B열 기간 | C22: 기간 | D22: 1~12 또는 001~012
B23: C열 회사코드 | C23: 회사코드
B24: D열 코스트센터 | C24: 코스트센터 | D24: 코스트센터 코드 (비어 있는 행은 제외)
B25: E열 코스트센터명 | C25: 코스트센터명
B26: F열 G/L계정 | C26: G/L계정
B27: G열 계정명 | C27: 계정명
B28: H열 금액 | C28: 금액 | D28: 회사코드 통화, 비용 차변 +
B30: 열 매핑 - 예산 파일
B31: 표준 열 (예산_원본) | C31: 원본 파일 열 이름 | D31: 설명
B32: A열 연도 | C32: 연도
B33: B열 예산버전 | C33: 예산버전
B34: C열 부서코드 | C34: 부서코드 | D34: 부서코드가 비어 있는 행은 제외
B35: D열 부서명 | C35: 부서명
B36: E열 예산항목코드 | C36: 예산항목코드
B37: F열 예산항목명 | C37: 예산항목명
B38: G열 1월 | C38: 1월
B39: H열 2월 | C39: 2월
B40: I열 3월 | C40: 3월
B41: J열 4월 | C41: 4월
B42: K열 5월 | C42: 5월
B43: L열 6월 | C43: 6월
B44: M열 7월 | C44: 7월
B45: N열 8월 | C45: 8월
...

Sheet 자가진단
A1: 자가진단
A2: 불러오기 후 자동 점검 · 외부망으로 오류를 알릴 때는 [점검 항목]과 [상태]만 전달하세요
A4: 종합 | B4: =IF(COUNTIF(D7:D23,"확인필요")=0,"전체 정상"&IF(COUNTIF(D7:D23,"참고")>0," (참고 "&COUNTIF(D7:D23,"참고")&"건)",""),"확인필요 "&COUNTIF(D7:D23,"확인필요")&"건")
A6: No | B6: 점검 항목 | C6: 결과 | D6: 상태 | E6: 조치 방법
A7: 1 | B7: 설정값 유효성 | C7: =IF(AND(ISNUMBER(설정!$C$7),설정!$C$7>=1,설정!$C$7<=12,ISNUMBER(설정!$C$14),ISNUMBER(설정!$C$15)),"정상","기준월 또는 단위 오류") | D7: =IF(C7="정상","OK","확인필요") | E7: 설정 시트의 기준월(1~12)과 단위(원/천원/백만원) 확인
A8: 2 | B8: 실적_원본 머리글 | C8: =IF(IF(실적_원본!A4<>"회계연도","A ","")&IF(실적_원본!B4<>"기간","B ","")&IF(실적_원본!C4<>"회사코드","C ","")&IF(실적_원본!D4<>"코스트센터","D ","")&IF(실적_원본!E4<>"코스트센터명","E ","")&IF(실적_원본!F4<>"G/L계정","F ","")&IF(실적_원본!G4<>"계정명","G ","")&IF(실적_원본!H4<>"금액","H ","")="","일치","불일치 열: "&IF(실적_원본!A4<>"회계연도","A ","")&IF(실적_원본!B4<>"기간","B ","")&IF(실적_원본!C4<>"회사코드","C ","")&IF(실적_원본!D4<>"코스트센터","D ","")&IF(실적_원본!E4<>"코스트센터명","E ","")&IF(실적_원본!F4<>"G/L계정","F ","")&IF(실적_원본!G4<>"계정명","G ","")&IF(실적_원본!H4<>"금액","H ","")) | D8: =IF(C8="일치","OK","확인필요") | E8: 실적_원본 4행 머리글을 표준 이름으로 되돌리기
A9: 3 | B9: 예산_원본 머리글 | C9: =IF(AND(IF(예산_원본!A4<>"연도","A ","")&IF(예산_원본!B4<>"예산버전","B ","")&IF(예산_원본!C4<>"부서코드","C ","")&IF(예산_원본!D4<>"부서명","D ","")&IF(예산_원본!E4<>"예산항목코드","E ","")&IF(예산_원본!F4<>"예산항목명","F ","")="",예산_원본!G4=1,예산_원본!R4=12),"일치","불일치 열: "&IF(예산_원본!A4<>"연도","A ","")&IF(예산_원본!B4<>"예산버전","B ","")&IF(예산_원본!C4<>"부서코드","C ","")&IF(예산_원본!D4<>"부서명","D ","")&IF(예산_원본!E4<>"예산항목코드","E ","")&IF(예산_원본!F4<>"예산항목명","F ","")&IF(예산_원본!G4<>1,"G(1월) ","")) | D9: =IF(C9="일치","OK","확인필요") | E9: 예산_원본 4행 머리글을 표준 이름으로 되돌리기
A10: 4 | B10: 실적 행 수 / 보조수식 범위 | C10: =COUNTA(실적_원본!A5:A100000)&"행 / 보조수식 "&COUNTA(실적_원본!O5:O100000)&"행" | D10: =IF(AND(COUNTA(실적_원본!A5:A100000)<=99996,COUNTA(실적_원본!O5:O100000)>=COUNTA(실적_원본!A5:A100000)),"OK","확인필요") | E10: 보조수식(J~Q열)을 데이터 마지막 행까지 채우기 ([보조수식 다시 채우기] 버튼)
A11: 5 | B11: 예산 행 수 / 보조수식 범위 | C11: =COUNTA(예산_원본!A5:A3004)&"행 / 보조수식 "&COUNTA(예산_원본!T5:T3004)&"행" | D11: =IF(COUNTA(예산_원본!T5:T3004)>=COUNTA(예산_원본!A5:A3004),"OK","확인필요") | E11: 보조수식(T~Y열)을 데이터 마지막 행까지 채우기
A12: 6 | B12: 기준월 실적 존재 | C12: =COUNTIFS(실적_원본!$L$5:$L$100000,설정!$C$6,실적_원본!$M$5:$M$100000,설정!$C$7)&"건" | D12: =IF(COUNTIFS(실적_원본!$L$5:$L$100000,설정!$C$6,실적_원본!$M$5:$M$100000,설정!$C$7)>0,"OK","확인필요") | E12: 기준월 실적이 포함된 파일인지, 기간 열 형식 확인
A13: 7 | B13: 전년 실적 존재 | C13: =COUNTIFS(실적_원본!$L$5:$L$100000,설정!$C$6-1)&"건" | D13: =IF(COUNTIFS(실적_원본!$L$5:$L$100000,설정!$C$6-1)>0,"OK","참고") | E13: 전년 대비가 필요하면 전년 실적도 함께 불러오기
A14: 8 | B14: 미매핑 코스트센터 | C14: =COUNTIF(실적_원본!$J$5:$J$100000,"미매핑")&"건"&IF(COUNTIF(실적_원본!$J$5:$J$100000,"미매핑")>0," (예: "&INDEX(실적_원본!$D$5:$D$100000,MATCH("미매핑",실적_원본!$J$5:$J$100000,0))&")","") | D14: =IF(COUNTIF(실적_원본!$J$5:$J$100000,"미매핑")=0,"OK","확인필요") | E14: 부서매핑 시트에 해당 코스트센터 추가
A15: 9 | B15: 미매핑 G/L 계정 | C15: =COUNTIF(실적_원본!$K$5:$K$100000,"미매핑")&"건"&IF(COUNTIF(실적_원본!$K$5:$K$100000,"미매핑")>0," (예: "&INDEX(실적_원본!$F$5:$F$100000,MATCH("미매핑",실적_원본!$K$5:$K$100000,0))&")","") | D15: =IF(COUNTIF(실적_원본!$K$5:$K$100000,"미매핑")=0,"OK","확인필요") | E15: 계정매핑 시트에 해당 계정 추가 (예산 통제 대상이 아니면 예산항목코드에 '제외' 입력)
A16: 10 | B16: 적용버전 예산 존재 | C16: =COUNTIFS(예산_원본!$B$5:$B$3004,설정!$C$8,예산_원본!$U$5:$U$3004,설정!$C$6)&"행" | D16: =IF(COUNTIFS(예산_원본!$B$5:$B$3004,설정!$C$8,예산_원본!$U$5:$U$3004,설정!$C$6)>0,"OK","확인필요") | E16: 설정의 '적용 예산버전'이 예산_원본 B열 값과 같은지 확인
A17: 11 | B17: 집계표에 없는 예산 조합 | C17: =COUNTIFS(예산_원본!$Y$5:$Y$3004,"N",예산_원본!$B$5:$B$3004,설정!$C$8,예산_원본!$U$5:$U$3004,설정!$C$6)&"건" | D17: =IF(COUNTIFS(예산_원본!$Y$5:$Y$3004,"N",예산_원본!$B$5:$B$3004,설정!$C$8,예산_원본!$U$5:$U$3004,설정!$C$6)=0,"OK","확인필요") | E17: 집계 시트에 부서코드·항목코드 행 추가 (매크로 불러오기 시 자동)
A18: 12 | B18: 집계표에 없는 실적 조합 (당해) | C18: =COUNTIFS(실적_원본!$Q$5:$Q$100000,"N",실적_원본!$L$5:$L$100000,설정!$C$6)&"건" | D18: =IF(COUNTIFS(실적_원본!$Q$5:$Q$100000,"N",실적_원본!$L$5:$L$100000,설정!$C$6)=0,"OK","확인필요") | E18: 미매핑이 아니라면 집계 시트에 행 추가 (매크로 불러오기 시 자동)
A19: 13 | B19: 무예산 집행 (예산 없는 실적) | C19: =COUNTIFS(실적_원본!$P$5:$P$100000,"N",실적_원본!$L$5:$L$100000,설정!$C$6,실적_원본!$M$5:$M$100000,"<="&설정!$C$7)&"건" | D19: =IF(COUNTIFS(실적_원본!$P$5:$P$100000,"N",실적_원본!$L$5:$L$100000,설정!$C$6,실적_원본!$M$5:$M$100000,"<="&설정!$C$7)=0,"OK","참고") | E19: 업무상 예외 - 예외목록에서 전용·추가예산 여부 확인
A20: 14 | B20: 실적 총액 대사 (원본 ↔ 집계) | C20: ="차이 "&TEXT(SUMIFS(실적_원본!$N$5:$N$100000,실적_원본!$L$5:$L$100000,설정!$C$6,실적_원본!$M$5:$M$100000,"<="&설정!$C$7)-집계!J4,"#,##0") | D20: =IF(ABS(SUMIFS(실적_원본!$N$5:$N$100000,실적_원본!$L$5:$L$100000,설정!$C$6,실적_원본!$M$5:$M$100000,"<="&설정!$C$7)-집계!J4)<1,"OK","확인필요") | E20: 미매핑·집계 누락 항목을 먼저 해결하면 대부분 0이 됩니다
A21: 15 | B21: 예산 총액 대사 (원본 ↔ 집계) | C21: ="차이 "&TEXT(SUMIFS(예산_원본!$V$5:$V$3004,예산_원본!$B$5:$B$3004,설정!$C$8,예산_원본!$U$5:$U$3004,설정!$C$6)-집계!M4,"#,##0") | D21: =IF(ABS(SUMIFS(예산_원본!$V$5:$V$3004,예산_원본!$B$5:$B$3004,설정!$C$8,예산_원본!$U$5:$U$3004,설정!$C$6)-집계!M4)<1,"OK","확인필요") | E21: 집계표에 없는 예산 조합 해결
A22: 16 | B22: 매핑 코드 중복 | C22: ="계정 "&SUMPRODUCT((계정매핑!$A$5:$A$504<>"")*(COUNTIF(계정매핑!$A$5:$A$504,계정매핑!$A$5:$A$504)>1))&"건 / 코스트센터 "&SUMPRODUCT((부서매핑!$A$5:$A$504<>"")*(COUNTIF(부서매핑!$A$5:$A$504,부서매핑!$A$5:$A$504)>1))&"건" | D22: =IF(SUMPRODUCT((계정매핑!$A$5:$A$504<>"")*(COUNTIF(계정매핑!$A$5:$A$504,계정매핑!$A$5:$A$504)>1))+SUMPRODUCT((부서매핑!$A$5:$A$504<>"")*(COUNTIF(부서매핑!$A$5:$A$504,부서매핑!$A$5:$A$504)>1))=0,"OK","확인필요") | E22: 매핑 시트에서 같은 코드가 두 번 있는 행 정리
A23: 17 | B23: 요약 시트 부서 누락 | C23: =SUMPRODUCT((집계!$A$7:$A$506<>"")*(COUNTIF(요약!$A$7:$A$14,집계!$A$7:$A$506)=0))&"행" | D23: =IF(SUMPRODUCT((집계!$A$7:$A$506<>"")*(COUNTIF(요약!$A$7:$A$14,집계!$A$7:$A$506)=0))=0,"OK","확인필요") | E23: 요약 시트 부서별 표에 부서코드 행 추가

Sheet 리포트
A1: =설정!$C$5&" 예산 집행 현황 ("&설정!$C$6&"년 "&설정!$C$7&"월 누계)"
A2: ="단위: "&설정!$C$11&" · 예산버전: "&설정!$C$8&" · 판정 기준: 집행률 ±"&TEXT(설정!$C$12,"0%")&", 차이 "&TEXT(설정!$C$13,"#,##0")&" 이상"
A4: 연간예산 | B4: 누계예산 | C4: 누계실적 | D4: 누계 집행률 | E4: 전년 동기 대비 | F4: 예외 항목
A5: =요약!G15 | B5: =요약!C15 | C5: =요약!D15 | D5: =요약!F15 | E5: =요약!J15 | F5: =요약!K15
A7: 1. 부서별 집행 현황
A8: 부서 | B8: 누계예산 | C8: 누계실적 | D8: 누계차이 | E8: 집행률 | F8: 전년비 | G8: 예외 | H8: 요약
A9: =요약!B7 | B9: =요약!C7 | C9: =요약!D7 | D9: =요약!E7 | E9: =요약!F7 | F9: =요약!J7 | G9: =요약!K7 | H9: =IF(요약!O7="","",요약!L7)&IF(요약!K7>0," / 예외 "&요약!K7&"건","")
A10: =요약!B8 | B10: =요약!C8 | C10: =요약!D8 | D10: =요약!E8 | E10: =요약!F8 | F10: =요약!J8 | G10: =요약!K8 | H10: =IF(요약!O8="","",요약!L8)&IF(요약!K8>0," / 예외 "&요약!K8&"건","")
A11: =요약!B9 | B11: =요약!C9 | C11: =요약!D9 | D11: =요약!E9 | E11: =요약!F9 | F11: =요약!J9 | G11: =요약!K9 | H11: =IF(요약!O9="","",요약!L9)&IF(요약!K9>0," / 예외 "&요약!K9&"건","")
A12: =요약!B10 | B12: =요약!C10 | C12: =요약!D10 | D12: =요약!E10 | E12: =요약!F10 | F12: =요약!J10 | G12: =요약!K10 | H12: =IF(요약!O10="","",요약!L10)&IF(요약!K10>0," / 예외 "&요약!K10&"건","")
A13: =요약!B11 | B13: =요약!C11 | C13: =요약!D11 | D13: =요약!E11 | E13: =요약!F11 | F13: =요약!J11 | G13: =요약!K11 | H13: =IF(요약!O11="","",요약!L11)&IF(요약!K11>0," / 예외 "&요약!K11&"건","")
A14: =요약!B12 | B14: =요약!C12 | C14: =요약!D12 | D14: =요약!E12 | E14: =요약!F12 | F14: =요약!J12 | G14: =요약!K12 | H14: =IF(요약!O12="","",요약!L12)&IF(요약!K12>0," / 예외 "&요약!K12&"건","")
A15: =요약!B13 | B15: =요약!C13 | C15: =요약!D13 | D15: =요약!E13 | E15: =요약!F13 | F15: =요약!J13 | G15: =요약!K13 | H15: =IF(요약!O13="","",요약!L13)&IF(요약!K13>0," / 예외 "&요약!K13&"건","")
A16: =요약!B14 | B16: =요약!C14 | C16: =요약!D14 | D16: =요약!E14 | E16: =요약!F14 | F16: =요약!J14 | G16: =요약!K14 | H16: =IF(요약!O14="","",요약!L14)&IF(요약!K14>0," / 예외 "&요약!K14&"건","")
A17: 합계 | B17: =요약!C15 | C17: =요약!D15 | D17: =요약!E15 | E17: =요약!F15 | F17: =요약!J15 | G17: =요약!K15
A19: 2. 예외 항목 TOP 10
A20: 부서 | B20: 예산항목 | C20: 판정 | D20: 누계차이 | E20: 집행률 | F20: 원인·조치
A21: =예외목록!B6 | B21: =예외목록!C6 | C21: =예외목록!D6 | D21: =예외목록!G6 | E21: =예외목록!H6 | F21: =예외목록!I6
A22: =예외목록!B7 | B22: =예외목록!C7 | C22: =예외목록!D7 | D22: =예외목록!G7 | E22: =예외목록!H7 | F22: =예외목록!I7
A23: =예외목록!B8 | B23: =예외목록!C8 | C23: =예외목록!D8 | D23: =예외목록!G8 | E23: =예외목록!H8 | F23: =예외목록!I8
A24: =예외목록!B9 | B24: =예외목록!C9 | C24: =예외목록!D9 | D24: =예외목록!G9 | E24: =예외목록!H9 | F24: =예외목록!I9
A25: =예외목록!B10 | B25: =예외목록!C10 | C25: =예외목록!D10 | D25: =예외목록!G10 | E25: =예외목록!H10 | F25: =예외목록!I10
A26: =예외목록!B11 | B26: =예외목록!C11 | C26: =예외목록!D11 | D26: =예외목록!G11 | E26: =예외목록!H11 | F26: =예외목록!I11
A27: =예외목록!B12 | B27: =예외목록!C12 | C27: =예외목록!D12 | D27: =예외목록!G12 | E27: =예외목록!H12 | F27: =예외목록!I12
A28: =예외목록!B13 | B28: =예외목록!C13 | C28: =예외목록!D13 | D28: =예외목록!G13 | E28: =예외목록!H13 | F28: =예외목록!I13
A29: =예외목록!B14 | B29: =예외목록!C14 | C29: =예외목록!D14 | D29: =예외목록!G14 | E29: =예외목록!H14 | F29: =예외목록!I14
A30: =예외목록!B15 | B30: =예외목록!C15 | C30: =예외목록!D15 | D30: =예외목록!G15 | E30: =예외목록!H15 | F30: =예외목록!I15

Sheet 요약
A1: 요약 (부서별 · 예산항목별)
A2: 부서·항목 목록은 파란 칸 · 새 부서가 생기면 행을 추가하세요 (자가진단이 누락을 알려줌)
A3: ="기준: "&설정!$C$6&"년 "&설정!$C$7&"월 누계 · 단위: "&설정!$C$11
A5: 1. 부서별
A6: 부서코드 | B6: 부서명 | C6: 누계예산 | D6: 누계실적 | E6: 누계차이 | F6: 집행률 | G6: 연간예산 | H6: 잔여예산 | I6: 전년동기 | J6: 전년비 | K6: 예외건수 | L6: 주요 초과 항목 | M6: 보고 문구 초안 | N6: 최대초과점수 | O6: 집계행
A7: D100 | B7: =IFERROR(INDEX(부서매핑!$D$5:$D$504,MATCH($A7,부서매핑!$C$5:$C$504,0)),"부서매핑 없음") | C7: =SUMIFS(집계!$I$7:$I$506,집계!$A$7:$A$506,$A7) | D7: =SUMIFS(집계!$J$7:$J$506,집계!$A$7:$A$506,$A7) | E7: =D7-C7 | F7: =IF(C7=0,0,D7/C7) | G7: =SUMIFS(집계!$M$7:$M$506,집계!$A$7:$A$506,$A7) | H7: =G7-D7 | I7: =SUMIFS(집계!$P$7:$P$506,집계!$A$7:$A$506,$A7) | J7: =IF(I7=0,0,D7/I7-1) | K7: =COUNTIFS(집계!$A$7:$A$506,$A7,집계!$S$7:$S$506,"<>정상") | L7: =IF(O7="","없음",INDEX(집계!$D$7:$D$506,O7)&" "&TEXT(INDEX(집계!$K$7:$K$506,O7),"+#,##0")) | M7: =B7&": 누계 집행률 "&TEXT(F7,"0.0%")&" (예산 "&TEXT(C7,"#,##0")&" / 실적 "&TEXT(D7,"#,##0")&"), "&IF(I7=0,"전년 실적 없음","전년 동기 대비 "&TEXT(J7,"+0.0%;-0.0%;0.0%"))&IF(O7="","",", 주요 초과 "&L7)&IF(K7>0,", 예외 "&K7&"건","")&"." | N7: =SUMPRODUCT(MAX((집계!$A$7:$A$506=$A7)*집계!$V$7:$V$506)) | O7: =IF(N7<설정!$C$13,"",MATCH(N7,집계!$V$7:$V$506,0))
A8: D200 | B8: =IFERROR(INDEX(부서매핑!$D$5:$D$504,MATCH($A8,부서매핑!$C$5:$C$504,0)),"부서매핑 없음") | C8: =SUMIFS(집계!$I$7:$I$506,집계!$A$7:$A$506,$A8) | D8: =SUMIFS(집계!$J$7:$J$506,집계!$A$7:$A$506,$A8) | E8: =D8-C8 | F8: =IF(C8=0,0,D8/C8) | G8: =SUMIFS(집계!$M$7:$M$506,집계!$A$7:$A$506,$A8) | H8: =G8-D8 | I8: =SUMIFS(집계!$P$7:$P$506,집계!$A$7:$A$506,$A8) | J8: =IF(I8=0,0,D8/I8-1) | K8: =COUNTIFS(집계!$A$7:$A$506,$A8,집계!$S$7:$S$506,"<>정상") | L8: =IF(O8="","없음",INDEX(집계!$D$7:$D$506,O8)&" "&TEXT(INDEX(집계!$K$7:$K$506,O8),"+#,##0")) | M8: =B8&": 누계 집행률 "&TEXT(F8,"0.0%")&" (예산 "&TEXT(C8,"#,##0")&" / 실적 "&TEXT(D8,"#,##0")&"), "&IF(I8=0,"전년 실적 없음","전년 동기 대비 "&TEXT(J8,"+0.0%;-0.0%;0.0%"))&IF(O8="","",", 주요 초과 "&L8)&IF(K8>0,", 예외 "&K8&"건","")&"." | N8: =SUMPRODUCT(MAX((집계!$A$7:$A$506=$A8)*집계!$V$7:$V$506)) | O8: =IF(N8<설정!$C$13,"",MATCH(N8,집계!$V$7:$V$506,0))
A9: D300 | B9: =IFERROR(INDEX(부서매핑!$D$5:$D$504,MATCH($A9,부서매핑!$C$5:$C$504,0)),"부서매핑 없음") | C9: =SUMIFS(집계!$I$7:$I$506,집계!$A$7:$A$506,$A9) | D9: =SUMIFS(집계!$J$7:$J$506,집계!$A$7:$A$506,$A9) | E9: =D9-C9 | F9: =IF(C9=0,0,D9/C9) | G9: =SUMIFS(집계!$M$7:$M$506,집계!$A$7:$A$506,$A9) | H9: =G9-D9 | I9: =SUMIFS(집계!$P$7:$P$506,집계!$A$7:$A$506,$A9) | J9: =IF(I9=0,0,D9/I9-1) | K9: =COUNTIFS(집계!$A$7:$A$506,$A9,집계!$S$7:$S$506,"<>정상") | L9: =IF(O9="","없음",INDEX(집계!$D$7:$D$506,O9)&" "&TEXT(INDEX(집계!$K$7:$K$506,O9),"+#,##0")) | M9: =B9&": 누계 집행률 "&TEXT(F9,"0.0%")&" (예산 "&TEXT(C9,"#,##0")&" / 실적 "&TEXT(D9,"#,##0")&"), "&IF(I9=0,"전년 실적 없음","전년 동기 대비 "&TEXT(J9,"+0.0%;-0.0%;0.0%"))&IF(O9="","",", 주요 초과 "&L9)&IF(K9>0,", 예외 "&K9&"건","")&"." | N9: =SUMPRODUCT(MAX((집계!$A$7:$A$506=$A9)*집계!$V$7:$V$506)) | O9: =IF(N9<설정!$C$13,"",MATCH(N9,집계!$V$7:$V$506,0))
A10: D400 | B10: =IFERROR(INDEX(부서매핑!$D$5:$D$504,MATCH($A10,부서매핑!$C$5:$C$504,0)),"부서매핑 없음") | C10: =SUMIFS(집계!$I$7:$I$506,집계!$A$7:$A$506,$A10) | D10: =SUMIFS(집계!$J$7:$J$506,집계!$A$7:$A$506,$A10) | E10: =D10-C10 | F10: =IF(C10=0,0,D10/C10) | G10: =SUMIFS(집계!$M$7:$M$506,집계!$A$7:$A$506,$A10) | H10: =G10-D10 | I10: =SUMIFS(집계!$P$7:$P$506,집계!$A$7:$A$506,$A10) | J10: =IF(I10=0,0,D10/I10-1) | K10: =COUNTIFS(집계!$A$7:$A$506,$A10,집계!$S$7:$S$506,"<>정상") | L10: =IF(O10="","없음",INDEX(집계!$D$7:$D$506,O10)&" "&TEXT(INDEX(집계!$K$7:$K$506,O10),"+#,##0")) | M10: =B10&": 누계 집행률 "&TEXT(F10,"0.0%")&" (예산 "&TEXT(C10,"#,##0")&" / 실적 "&TEXT(D10,"#,##0")&"), "&IF(I10=0,"전년 실적 없음","전년 동기 대비 "&TEXT(J10,"+0.0%;-0.0%;0.0%"))&IF(O10="","",", 주요 초과 "&L10)&IF(K10>0,", 예외 "&K10&"건","")&"." | N10: =SUMPRODUCT(MAX((집계!$A$7:$A$506=$A10)*집계!$V$7:$V$506)) | O10: =IF(N10<설정!$C$13,"",MATCH(N10,집계!$V$7:$V$506,0))
A11: D500 | B11: =IFERROR(INDEX(부서매핑!$D$5:$D$504,MATCH($A11,부서매핑!$C$5:$C$504,0)),"부서매핑 없음") | C11: =SUMIFS(집계!$I$7:$I$506,집계!$A$7:$A$506,$A11) | D11: =SUMIFS(집계!$J$7:$J$506,집계!$A$7:$A$506,$A11) | E11: =D11-C11 | F11: =IF(C11=0,0,D11/C11) | G11: =SUMIFS(집계!$M$7:$M$506,집계!$A$7:$A$506,$A11) | H11: =G11-D11 | I11: =SUMIFS(집계!$P$7:$P$506,집계!$A$7:$A$506,$A11) | J11: =IF(I11=0,0,D11/I11-1) | K11: =COUNTIFS(집계!$A$7:$A$506,$A11,집계!$S$7:$S$506,"<>정상") | L11: =IF(O11="","없음",INDEX(집계!$D$7:$D$506,O11)&" "&TEXT(INDEX(집계!$K$7:$K$506,O11),"+#,##0")) | M11: =B11&": 누계 집행률 "&TEXT(F11,"0.0%")&" (예산 "&TEXT(C11,"#,##0")&" / 실적 "&TEXT(D11,"#,##0")&"), "&IF(I11=0,"전년 실적 없음","전년 동기 대비 "&TEXT(J11,"+0.0%;-0.0%;0.0%"))&IF(O11="","",", 주요 초과 "&L11)&IF(K11>0,", 예외 "&K11&"건","")&"." | N11: =SUMPRODUCT(MAX((집계!$A$7:$A$506=$A11)*집계!$V$7:$V$506)) | O11: =IF(N11<설정!$C$13,"",MATCH(N11,집계!$V$7:$V$506,0))
A12: D600 | B12: =IFERROR(INDEX(부서매핑!$D$5:$D$504,MATCH($A12,부서매핑!$C$5:$C$504,0)),"부서매핑 없음") | C12: =SUMIFS(집계!$I$7:$I$506,집계!$A$7:$A$506,$A12) | D12: =SUMIFS(집계!$J$7:$J$506,집계!$A$7:$A$506,$A12) | E12: =D12-C12 | F12: =IF(C12=0,0,D12/C12) | G12: =SUMIFS(집계!$M$7:$M$506,집계!$A$7:$A$506,$A12) | H12: =G12-D12 | I12: =SUMIFS(집계!$P$7:$P$506,집계!$A$7:$A$506,$A12) | J12: =IF(I12=0,0,D12/I12-1) | K12: =COUNTIFS(집계!$A$7:$A$506,$A12,집계!$S$7:$S$506,"<>정상") | L12: =IF(O12="","없음",INDEX(집계!$D$7:$D$506,O12)&" "&TEXT(INDEX(집계!$K$7:$K$506,O12),"+#,##0")) | M12: =B12&": 누계 집행률 "&TEXT(F12,"0.0%")&" (예산 "&TEXT(C12,"#,##0")&" / 실적 "&TEXT(D12,"#,##0")&"), "&IF(I12=0,"전년 실적 없음","전년 동기 대비 "&TEXT(J12,"+0.0%;-0.0%;0.0%"))&IF(O12="","",", 주요 초과 "&L12)&IF(K12>0,", 예외 "&K12&"건","")&"." | N12: =SUMPRODUCT(MAX((집계!$A$7:$A$506=$A12)*집계!$V$7:$V$506)) | O12: =IF(N12<설정!$C$13,"",MATCH(N12,집계!$V$7:$V$506,0))
A13: D700 | B13: =IFERROR(INDEX(부서매핑!$D$5:$D$504,MATCH($A13,부서매핑!$C$5:$C$504,0)),"부서매핑 없음") | C13: =SUMIFS(집계!$I$7:$I$506,집계!$A$7:$A$506,$A13) | D13: =SUMIFS(집계!$J$7:$J$506,집계!$A$7:$A$506,$A13) | E13: =D13-C13 | F13: =IF(C13=0,0,D13/C13) | G13: =SUMIFS(집계!$M$7:$M$506,집계!$A$7:$A$506,$A13) | H13: =G13-D13 | I13: =SUMIFS(집계!$P$7:$P$506,집계!$A$7:$A$506,$A13) | J13: =IF(I13=0,0,D13/I13-1) | K13: =COUNTIFS(집계!$A$7:$A$506,$A13,집계!$S$7:$S$506,"<>정상") | L13: =IF(O13="","없음",INDEX(집계!$D$7:$D$506,O13)&" "&TEXT(INDEX(집계!$K$7:$K$506,O13),"+#,##0")) | M13: =B13&": 누계 집행률 "&TEXT(F13,"0.0%")&" (예산 "&TEXT(C13,"#,##0")&" / 실적 "&TEXT(D13,"#,##0")&"), "&IF(I13=0,"전년 실적 없음","전년 동기 대비 "&TEXT(J13,"+0.0%;-0.0%;0.0%"))&IF(O13="","",", 주요 초과 "&L13)&IF(K13>0,", 예외 "&K13&"건","")&"." | N13: =SUMPRODUCT(MAX((집계!$A$7:$A$506=$A13)*집계!$V$7:$V$506)) | O13: =IF(N13<설정!$C$13,"",MATCH(N13,집계!$V$7:$V$506,0))
A14: D800 | B14: =IFERROR(INDEX(부서매핑!$D$5:$D$504,MATCH($A14,부서매핑!$C$5:$C$504,0)),"부서매핑 없음") | C14: =SUMIFS(집계!$I$7:$I$506,집계!$A$7:$A$506,$A14) | D14: =SUMIFS(집계!$J$7:$J$506,집계!$A$7:$A$506,$A14) | E14: =D14-C14 | F14: =IF(C14=0,0,D14/C14) | G14: =SUMIFS(집계!$M$7:$M$506,집계!$A$7:$A$506,$A14) | H14: =G14-D14 | I14: =SUMIFS(집계!$P$7:$P$506,집계!$A$7:$A$506,$A14) | J14: =IF(I14=0,0,D14/I14-1) | K14: =COUNTIFS(집계!$A$7:$A$506,$A14,집계!$S$7:$S$506,"<>정상") | L14: =IF(O14="","없음",INDEX(집계!$D$7:$D$506,O14)&" "&TEXT(INDEX(집계!$K$7:$K$506,O14),"+#,##0")) | M14: =B14&": 누계 집행률 "&TEXT(F14,"0.0%")&" (예산 "&TEXT(C14,"#,##0")&" / 실적 "&TEXT(D14,"#,##0")&"), "&IF(I14=0,"전년 실적 없음","전년 동기 대비 "&TEXT(J14,"+0.0%;-0.0%;0.0%"))&IF(O14="","",", 주요 초과 "&L14)&IF(K14>0,", 예외 "&K14&"건","")&"." | N14: =SUMPRODUCT(MAX((집계!$A$7:$A$506=$A14)*집계!$V$7:$V$506)) | O14: =IF(N14<설정!$C$13,"",MATCH(N14,집계!$V$7:$V$506,0))
A15: 합계 | C15: =SUM(C7:C14) | D15: =SUM(D7:D14) | E15: =SUM(E7:E14) | F15: =IF(C15=0,0,D15/C15) | G15: =SUM(G7:G14) | H15: =SUM(H7:H14) | I15: =SUM(I7:I14) | J15: =IF(I15=0,0,D15/I15-1) | K15: =SUM(K7:K14) | M15: ="전사: 누계 집행률 "&TEXT(F15,"0.0%")&" (예산 "&TEXT(C15,"#,##0")&" / 실적 "&TEXT(D15,"#,##0")&"), 전년 동기 대비 "&TEXT(J15,"+0.0%;-0.0%;0.0%")&", 예외 "&K15&"건."
A17: 2. 예산항목별
A18: 항목코드 | B18: 예산항목명 | C18: 누계예산 | D18: 누계실적 | E18: 누계차이 | F18: 집행률 | G18: 연간예산 | H18: 잔여예산 | I18: 전년동기 | J18: 전년비 | K18: 예외건수
A19: B01 | B19: =IFERROR(INDEX(계정매핑!$D$5:$D$504,MATCH($A19,계정매핑!$C$5:$C$504,0)),"항목매핑 없음") | C19: =SUMIFS(집계!$I$7:$I$506,집계!$C$7:$C$506,$A19) | D19: =SUMIFS(집계!$J$7:$J$506,집계!$C$7:$C$506,$A19) | E19: =D19-C19 | F19: =IF(C19=0,0,D19/C19) | G19: =SUMIFS(집계!$M$7:$M$506,집계!$C$7:$C$506,$A19) | H19: =G19-D19 | I19: =SUMIFS(집계!$P$7:$P$506,집계!$C$7:$C$506,$A19) | J19: =IF(I19=0,0,D19/I19-1) | K19: =COUNTIFS(집계!$C$7:$C$506,$A19,집계!$S$7:$S$506,"<>정상")
A20: B02 | B20: =IFERROR(INDEX(계정매핑!$D$5:$D$504,MATCH($A20,계정매핑!$C$5:$C$504,0)),"항목매핑 없음") | C20: =SUMIFS(집계!$I$7:$I$506,집계!$C$7:$C$506,$A20) | D20: =SUMIFS(집계!$J$7:$J$506,집계!$C$7:$C$506,$A20) | E20: =D20-C20 | F20: =IF(C20=0,0,D20/C20) | G20: =SUMIFS(집계!$M$7:$M$506,집계!$C$7:$C$506,$A20) | H20: =G20-D20 | I20: =SUMIFS(집계!$P$7:$P$506,집계!$C$7:$C$506,$A20) | J20: =IF(I20=0,0,D20/I20-1) | K20: =COUNTIFS(집계!$C$7:$C$506,$A20,집계!$S$7:$S$506,"<>정상")
A21: B03 | B21: =IFERROR(INDEX(계정매핑!$D$5:$D$504,MATCH($A21,계정매핑!$C$5:$C$504,0)),"항목매핑 없음") | C21: =SUMIFS(집계!$I$7:$I$506,집계!$C$7:$C$506,$A21) | D21: =SUMIFS(집계!$J$7:$J$506,집계!$C$7:$C$506,$A21) | E21: =D21-C21 | F21: =IF(C21=0,0,D21/C21) | G21: =SUMIFS(집계!$M$7:$M$506,집계!$C$7:$C$506,$A21) | H21: =G21-D21 | I21: =SUMIFS(집계!$P$7:$P$506,집계!$C$7:$C$506,$A21) | J21: =IF(I21=0,0,D21/I21-1) | K21: =COUNTIFS(집계!$C$7:$C$506,$A21,집계!$S$7:$S$506,"<>정상")
A22: B04 | B22: =IFERROR(INDEX(계정매핑!$D$5:$D$504,MATCH($A22,계정매핑!$C$5:$C$504,0)),"항목매핑 없음") | C22: =SUMIFS(집계!$I$7:$I$506,집계!$C$7:$C$506,$A22) | D22: =SUMIFS(집계!$J$7:$J$506,집계!$C$7:$C$506,$A22) | E22: =D22-C22 | F22: =IF(C22=0,0,D22/C22) | G22: =SUMIFS(집계!$M$7:$M$506,집계!$C$7:$C$506,$A22) | H22: =G22-D22 | I22: =SUMIFS(집계!$P$7:$P$506,집계!$C$7:$C$506,$A22) | J22: =IF(I22=0,0,D22/I22-1) | K22: =COUNTIFS(집계!$C$7:$C$506,$A22,집계!$S$7:$S$506,"<>정상")
A23: B05 | B23: =IFERROR(INDEX(계정매핑!$D$5:$D$504,MATCH($A23,계정매핑!$C$5:$C$504,0)),"항목매핑 없음") | C23: =SUMIFS(집계!$I$7:$I$506,집계!$C$7:$C$506,$A23) | D23: =SUMIFS(집계!$J$7:$J$506,집계!$C$7:$C$506,$A23) | E23: =D23-C23 | F23: =IF(C23=0,0,D23/C23) | G23: =SUMIFS(집계!$M$7:$M$506,집계!$C$7:$C$506,$A23) | H23: =G23-D23 | I23: =SUMIFS(집계!$P$7:$P$506,집계!$C$7:$C$506,$A23) | J23: =IF(I23=0,0,D23/I23-1) | K23: =COUNTIFS(집계!$C$7:$C$506,$A23,집계!$S$7:$S$506,"<>정상")
A24: B06 | B24: =IFERROR(INDEX(계정매핑!$D$5:$D$504,MATCH($A24,계정매핑!$C$5:$C$504,0)),"항목매핑 없음") | C24: =SUMIFS(집계!$I$7:$I$506,집계!$C$7:$C$506,$A24) | D24: =SUMIFS(집계!$J$7:$J$506,집계!$C$7:$C$506,$A24) | E24: =D24-C24 | F24: =IF(C24=0,0,D24/C24) | G24: =SUMIFS(집계!$M$7:$M$506,집계!$C$7:$C$506,$A24) | H24: =G24-D24 | I24: =SUMIFS(집계!$P$7:$P$506,집계!$C$7:$C$506,$A24) | J24: =IF(I24=0,0,D24/I24-1) | K24: =COUNTIFS(집계!$C$7:$C$506,$A24,집계!$S$7:$S$506,"<>정상")
A25: B07 | B25: =IFERROR(INDEX(계정매핑!$D$5:$D$504,MATCH($A25,계정매핑!$C$5:$C$504,0)),"항목매핑 없음") | C25: =SUMIFS(집계!$I$7:$I$506,집계!$C$7:$C$506,$A25) | D25: =SUMIFS(집계!$J$7:$J$506,집계!$C$7:$C$506,$A25) | E25: =D25-C25 | F25: =IF(C25=0,0,D25/C25) | G25: =SUMIFS(집계!$M$7:$M$506,집계!$C$7:$C$506,$A25) | H25: =G25-D25 | I25: =SUMIFS(집계!$P$7:$P$506,집계!$C$7:$C$506,$A25) | J25: =IF(I25=0,0,D25/I25-1) | K25: =COUNTIFS(집계!$C$7:$C$506,$A25,집계!$S$7:$S$506,"<>정상")
A26: B08 | B26: =IFERROR(INDEX(계정매핑!$D$5:$D$504,MATCH($A26,계정매핑!$C$5:$C$504,0)),"항목매핑 없음") | C26: =SUMIFS(집계!$I$7:$I$506,집계!$C$7:$C$506,$A26) | D26: =SUMIFS(집계!$J$7:$J$506,집계!$C$7:$C$506,$A26) | E26: =D26-C26 | F26: =IF(C26=0,0,D26/C26) | G26: =SUMIFS(집계!$M$7:$M$506,집계!$C$7:$C$506,$A26) | H26: =G26-D26 | I26: =SUMIFS(집계!$P$7:$P$506,집계!$C$7:$C$506,$A26) | J26: =IF(I26=0,0,D26/I26-1) | K26: =COUNTIFS(집계!$C$7:$C$506,$A26,집계!$S$7:$S$506,"<>정상")
A27: B09 | B27: =IFERROR(INDEX(계정매핑!$D$5:$D$504,MATCH($A27,계정매핑!$C$5:$C$504,0)),"항목매핑 없음") | C27: =SUMIFS(집계!$I$7:$I$506,집계!$C$7:$C$506,$A27) | D27: =SUMIFS(집계!$J$7:$J$506,집계!$C$7:$C$506,$A27) | E27: =D27-C27 | F27: =IF(C27=0,0,D27/C27) | G27: =SUMIFS(집계!$M$7:$M$506,집계!$C$7:$C$506,$A27) | H27: =G27-D27 | I27: =SUMIFS(집계!$P$7:$P$506,집계!$C$7:$C$506,$A27) | J27: =IF(I27=0,0,D27/I27-1) | K27: =COUNTIFS(집계!$C$7:$C$506,$A27,집계!$S$7:$S$506,"<>정상")
A28: B10 | B28: =IFERROR(INDEX(계정매핑!$D$5:$D$504,MATCH($A28,계정매핑!$C$5:$C$504,0)),"항목매핑 없음") | C28: =SUMIFS(집계!$I$7:$I$506,집계!$C$7:$C$506,$A28) | D28: =SUMIFS(집계!$J$7:$J$506,집계!$C$7:$C$506,$A28) | E28: =D28-C28 | F28: =IF(C28=0,0,D28/C28) | G28: =SUMIFS(집계!$M$7:$M$506,집계!$C$7:$C$506,$A28) | H28: =G28-D28 | I28: =SUMIFS(집계!$P$7:$P$506,집계!$C$7:$C$506,$A28) | J28: =IF(I28=0,0,D28/I28-1) | K28: =COUNTIFS(집계!$C$7:$C$506,$A28,집계!$S$7:$S$506,"<>정상")
A29: B11 | B29: =IFERROR(INDEX(계정매핑!$D$5:$D$504,MATCH($A29,계정매핑!$C$5:$C$504,0)),"항목매핑 없음") | C29: =SUMIFS(집계!$I$7:$I$506,집계!$C$7:$C$506,$A29) | D29: =SUMIFS(집계!$J$7:$J$506,집계!$C$7:$C$506,$A29) | E29: =D29-C29 | F29: =IF(C29=0,0,D29/C29) | G29: =SUMIFS(집계!$M$7:$M$506,집계!$C$7:$C$506,$A29) | H29: =G29-D29 | I29: =SUMIFS(집계!$P$7:$P$506,집계!$C$7:$C$506,$A29) | J29: =IF(I29=0,0,D29/I29-1) | K29: =COUNTIFS(집계!$C$7:$C$506,$A29,집계!$S$7:$S$506,"<>정상")
A30: B12 | B30: =IFERROR(INDEX(계정매핑!$D$5:$D$504,MATCH($A30,계정매핑!$C$5:$C$504,0)),"항목매핑 없음") | C30: =SUMIFS(집계!$I$7:$I$506,집계!$C$7:$C$506,$A30) | D30: =SUMIFS(집계!$J$7:$J$506,집계!$C$7:$C$506,$A30) | E30: =D30-C30 | F30: =IF(C30=0,0,D30/C30) | G30: =SUMIFS(집계!$M$7:$M$506,집계!$C$7:$C$506,$A30) | H30: =G30-D30 | I30: =SUMIFS(집계!$P$7:$P$506,집계!$C$7:$C$506,$A30) | J30: =IF(I30=0,0,D30/I30-1) | K30: =COUNTIFS(집계!$C$7:$C$506,$A30,집계!$S$7:$S$506,"<>정상")
A31: 합계 | C31: =SUM(C19:C30) | D31: =SUM(D19:D30) | E31: =SUM(E19:E30) | F31: =IF(C31=0,0,D31/C31) | G31: =SUM(G19:G30) | H31: =SUM(H19:H30) | I31: =SUM(I19:I30) | J31: =IF(I31=0,0,D31/I31-1) | K31: =SUM(K19:K30)

Sheet 예외목록
A1: 예외 항목 (누계 기준, 차이 금액 큰 순)
A2: 판정 기준은 설정 시트 · 최대 30건 표시
A3: ="기준: "&설정!$C$6&"년 "&설정!$C$7&"월 누계 · 단위: "&설정!$C$11&" · 예외 "&COUNTIF(집계!$U$7:$U$506,">=0")&"건"
A5: 순위 | B5: 부서명 | C5: 예산항목명 | D5: 판정 | E5: 누계예산 | F5: 누계실적 | G5: 누계차이 | H5: 집행률 | I5: 원인·조치 코멘트 | J5: 행번호
A6: 1 | B6: =IF($J6="","",INDEX(집계!$B$7:$B$506,$J6)) | C6: =IF($J6="","",INDEX(집계!$D$7:$D$506,$J6)) | D6: =IF($J6="","",INDEX(집계!$S$7:$S$506,$J6)) | E6: =IF($J6="","",INDEX(집계!$I$7:$I$506,$J6)) | F6: =IF($J6="","",INDEX(집계!$J$7:$J$506,$J6)) | G6: =IF($J6="","",INDEX(집계!$K$7:$K$506,$J6)) | H6: =IF($J6="","",INDEX(집계!$L$7:$L$506,$J6)) | I6: =IF($J6="","",IF(INDEX(집계!$T$7:$T$506,$J6)="","(미입력 - 코멘트 시트에 작성)",INDEX(집계!$T$7:$T$506,$J6))) | J6: =IF(IFERROR(LARGE(집계!$U$7:$U$506,A6),-1)<0,"",MATCH(LARGE(집계!$U$7:$U$506,A6),집계!$U$7:$U$506,0))
A7: 2 | B7: =IF($J7="","",INDEX(집계!$B$7:$B$506,$J7)) | C7: =IF($J7="","",INDEX(집계!$D$7:$D$506,$J7)) | D7: =IF($J7="","",INDEX(집계!$S$7:$S$506,$J7)) | E7: =IF($J7="","",INDEX(집계!$I$7:$I$506,$J7)) | F7: =IF($J7="","",INDEX(집계!$J$7:$J$506,$J7)) | G7: =IF($J7="","",INDEX(집계!$K$7:$K$506,$J7)) | H7: =IF($J7="","",INDEX(집계!$L$7:$L$506,$J7)) | I7: =IF($J7="","",IF(INDEX(집계!$T$7:$T$506,$J7)="","(미입력 - 코멘트 시트에 작성)",INDEX(집계!$T$7:$T$506,$J7))) | J7: =IF(IFERROR(LARGE(집계!$U$7:$U$506,A7),-1)<0,"",MATCH(LARGE(집계!$U$7:$U$506,A7),집계!$U$7:$U$506,0))
A8: 3 | B8: =IF($J8="","",INDEX(집계!$B$7:$B$506,$J8)) | C8: =IF($J8="","",INDEX(집계!$D$7:$D$506,$J8)) | D8: =IF($J8="","",INDEX(집계!$S$7:$S$506,$J8)) | E8: =IF($J8="","",INDEX(집계!$I$7:$I$506,$J8)) | F8: =IF($J8="","",INDEX(집계!$J$7:$J$506,$J8)) | G8: =IF($J8="","",INDEX(집계!$K$7:$K$506,$J8)) | H8: =IF($J8="","",INDEX(집계!$L$7:$L$506,$J8)) | I8: =IF($J8="","",IF(INDEX(집계!$T$7:$T$506,$J8)="","(미입력 - 코멘트 시트에 작성)",INDEX(집계!$T$7:$T$506,$J8))) | J8: =IF(IFERROR(LARGE(집계!$U$7:$U$506,A8),-1)<0,"",MATCH(LARGE(집계!$U$7:$U$506,A8),집계!$U$7:$U$506,0))
A9: 4 | B9: =IF($J9="","",INDEX(집계!$B$7:$B$506,$J9)) | C9: =IF($J9="","",INDEX(집계!$D$7:$D$506,$J9)) | D9: =IF($J9="","",INDEX(집계!$S$7:$S$506,$J9)) | E9: =IF($J9="","",INDEX(집계!$I$7:$I$506,$J9)) | F9: =IF($J9="","",INDEX(집계!$J$7:$J$506,$J9)) | G9: =IF($J9="","",INDEX(집계!$K$7:$K$506,$J9)) | H9: =IF($J9="","",INDEX(집계!$L$7:$L$506,$J9)) | I9: =IF($J9="","",IF(INDEX(집계!$T$7:$T$506,$J9)="","(미입력 - 코멘트 시트에 작성)",INDEX(집계!$T$7:$T$506,$J9))) | J9: =IF(IFERROR(LARGE(집계!$U$7:$U$506,A9),-1)<0,"",MATCH(LARGE(집계!$U$7:$U$506,A9),집계!$U$7:$U$506,0))
A10: 5 | B10: =IF($J10="","",INDEX(집계!$B$7:$B$506,$J10)) | C10: =IF($J10="","",INDEX(집계!$D$7:$D$506,$J10)) | D10: =IF($J10="","",INDEX(집계!$S$7:$S$506,$J10)) | E10: =IF($J10="","",INDEX(집계!$I$7:$I$506,$J10)) | F10: =IF($J10="","",INDEX(집계!$J$7:$J$506,$J10)) | G10: =IF($J10="","",INDEX(집계!$K$7:$K$506,$J10)) | H10: =IF($J10="","",INDEX(집계!$L$7:$L$506,$J10)) | I10: =IF($J10="","",IF(INDEX(집계!$T$7:$T$506,$J10)="","(미입력 - 코멘트 시트에 작성)",INDEX(집계!$T$7:$T$506,$J10))) | J10: =IF(IFERROR(LARGE(집계!$U$7:$U$506,A10),-1)<0,"",MATCH(LARGE(집계!$U$7:$U$506,A10),집계!$U$7:$U$506,0))
A11: 6 | B11: =IF($J11="","",INDEX(집계!$B$7:$B$506,$J11)) | C11: =IF($J11="","",INDEX(집계!$D$7:$D$506,$J11)) | D11: =IF($J11="","",INDEX(집계!$S$7:$S$506,$J11)) | E11: =IF($J11="","",INDEX(집계!$I$7:$I$506,$J11)) | F11: =IF($J11="","",INDEX(집계!$J$7:$J$506,$J11)) | G11: =IF($J11="","",INDEX(집계!$K$7:$K$506,$J11)) | H11: =IF($J11="","",INDEX(집계!$L$7:$L$506,$J11)) | I11: =IF($J11="","",IF(INDEX(집계!$T$7:$T$506,$J11)="","(미입력 - 코멘트 시트에 작성)",INDEX(집계!$T$7:$T$506,$J11))) | J11: =IF(IFERROR(LARGE(집계!$U$7:$U$506,A11),-1)<0,"",MATCH(LARGE(집계!$U$7:$U$506,A11),집계!$U$7:$U$506,0))
A12: 7 | B12: =IF($J12="","",INDEX(집계!$B$7:$B$506,$J12)) | C12: =IF($J12="","",INDEX(집계!$D$7:$D$506,$J12)) | D12: =IF($J12="","",INDEX(집계!$S$7:$S$506,$J12)) | E12: =IF($J12="","",INDEX(집계!$I$7:$I$506,$J12)) | F12: =IF($J12="","",INDEX(집계!$J$7:$J$506,$J12)) | G12: =IF($J12="","",INDEX(집계!$K$7:$K$506,$J12)) | H12: =IF($J12="","",INDEX(집계!$L$7:$L$506,$J12)) | I12: =IF($J12="","",IF(INDEX(집계!$T$7:$T$506,$J12)="","(미입력 - 코멘트 시트에 작성)",INDEX(집계!$T$7:$T$506,$J12))) | J12: =IF(IFERROR(LARGE(집계!$U$7:$U$506,A12),-1)<0,"",MATCH(LARGE(집계!$U$7:$U$506,A12),집계!$U$7:$U$506,0))
A13: 8 | B13: =IF($J13="","",INDEX(집계!$B$7:$B$506,$J13)) | C13: =IF($J13="","",INDEX(집계!$D$7:$D$506,$J13)) | D13: =IF($J13="","",INDEX(집계!$S$7:$S$506,$J13)) | E13: =IF($J13="","",INDEX(집계!$I$7:$I$506,$J13)) | F13: =IF($J13="","",INDEX(집계!$J$7:$J$506,$J13)) | G13: =IF($J13="","",INDEX(집계!$K$7:$K$506,$J13)) | H13: =IF($J13="","",INDEX(집계!$L$7:$L$506,$J13)) | I13: =IF($J13="","",IF(INDEX(집계!$T$7:$T$506,$J13)="","(미입력 - 코멘트 시트에 작성)",INDEX(집계!$T$7:$T$506,$J13))) | J13: =IF(IFERROR(LARGE(집계!$U$7:$U$506,A13),-1)<0,"",MATCH(LARGE(집계!$U$7:$U$506,A13),집계!$U$7:$U$506,0))
A14: 9 | B14: =IF($J14="","",INDEX(집계!$B$7:$B$506,$J14)) | C14: =IF($J14="","",INDEX(집계!$D$7:$D$506,$J14)) | D14: =IF($J14="","",INDEX(집계!$S$7:$S$506,$J14)) | E14: =IF($J14="","",INDEX(집계!$I$7:$I$506,$J14)) | F14: =IF($J14="","",INDEX(집계!$J$7:$J$506,$J14)) | G14: =IF($J14="","",INDEX(집계!$K$7:$K$506,$J14)) | H14: =IF($J14="","",INDEX(집계!$L$7:$L$506,$J14)) | I14: =IF($J14="","",IF(INDEX(집계!$T$7:$T$506,$J14)="","(미입력 - 코멘트 시트에 작성)",INDEX(집계!$T$7:$T$506,$J14))) | J14: =IF(IFERROR(LARGE(집계!$U$7:$U$506,A14),-1)<0,"",MATCH(LARGE(집계!$U$7:$U$506,A14),집계!$U$7:$U$506,0))
A15: 10 | B15: =IF($J15="","",INDEX(집계!$B$7:$B$506,$J15)) | C15: =IF($J15="","",INDEX(집계!$D$7:$D$506,$J15)) | D15: =IF($J15="","",INDEX(집계!$S$7:$S$506,$J15)) | E15: =IF($J15="","",INDEX(집계!$I$7:$I$506,$J15)) | F15: =IF($J15="","",INDEX(집계!$J$7:$J$506,$J15)) | G15: =IF($J15="","",INDEX(집계!$K$7:$K$506,$J15)) | H15: =IF($J15="","",INDEX(집계!$L$7:$L$506,$J15)) | I15: =IF($J15="","",IF(INDEX(집계!$T$7:$T$506,$J15)="","(미입력 - 코멘트 시트에 작성)",INDEX(집계!$T$7:$T$506,$J15))) | J15: =IF(IFERROR(LARGE(집계!$U$7:$U$506,A15),-1)<0,"",MATCH(LARGE(집계!$U$7:$U$506,A15),집계!$U$7:$U$506,0))
A16: 11 | B16: =IF($J16="","",INDEX(집계!$B$7:$B$506,$J16)) | C16: =IF($J16="","",INDEX(집계!$D$7:$D$506,$J16)) | D16: =IF($J16="","",INDEX(집계!$S$7:$S$506,$J16)) | E16: =IF($J16="","",INDEX(집계!$I$7:$I$506,$J16)) | F16: =IF($J16="","",INDEX(집계!$J$7:$J$506,$J16)) | G16: =IF($J16="","",INDEX(집계!$K$7:$K$506,$J16)) | H16: =IF($J16="","",INDEX(집계!$L$7:$L$506,$J16)) | I16: =IF($J16="","",IF(INDEX(집계!$T$7:$T$506,$J16)="","(미입력 - 코멘트 시트에 작성)",INDEX(집계!$T$7:$T$506,$J16))) | J16: =IF(IFERROR(LARGE(집계!$U$7:$U$506,A16),-1)<0,"",MATCH(LARGE(집계!$U$7:$U$506,A16),집계!$U$7:$U$506,0))
A17: 12 | B17: =IF($J17="","",INDEX(집계!$B$7:$B$506,$J17)) | C17: =IF($J17="","",INDEX(집계!$D$7:$D$506,$J17)) | D17: =IF($J17="","",INDEX(집계!$S$7:$S$506,$J17)) | E17: =IF($J17="","",INDEX(집계!$I$7:$I$506,$J17)) | F17: =IF($J17="","",INDEX(집계!$J$7:$J$506,$J17)) | G17: =IF($J17="","",INDEX(집계!$K$7:$K$506,$J17)) | H17: =IF($J17="","",INDEX(집계!$L$7:$L$506,$J17)) | I17: =IF($J17="","",IF(INDEX(집계!$T$7:$T$506,$J17)="","(미입력 - 코멘트 시트에 작성)",INDEX(집계!$T$7:$T$506,$J17))) | J17: =IF(IFERROR(LARGE(집계!$U$7:$U$506,A17),-1)<0,"",MATCH(LARGE(집계!$U$7:$U$506,A17),집계!$U$7:$U$506,0))
... A35: 30 | B35: =IF($J35="","",INDEX(집계!$B$7:$B$506,$J35)) | C35: =IF($J35="","",INDEX(집계!$D$7:$D$506,$J35)) | D35: =IF($J35="","",INDEX(집계!$S$7:$S$506,$J35)) | E35: =IF($J35="","",INDEX(집계!$I$7:$I$506,$J35)) | F35: =IF($J35="","",INDEX(집계!$J$7:$J$506,$J35)) | G35: =IF($J35="","",INDEX(집계!$K$7:$K$506,$J35)) | H35: =IF($J35="","",INDEX(집계!$L$7:$L$506,$J35)) | I35: =IF($J35="","",IF(INDEX(집계!$T$7:$T$506,$J35)="","(미입력 - 코멘트 시트에 작성)",INDEX(집계!$T$7:$T$506,$J35))) | J35: =IF(IFERROR(LARGE(집계!$U$7:$U$506,A35),-1)<0,"",MATCH(LARGE(집계!$U$7:$U$506,A35),집계!$U$7:$U$506,0))

Sheet 월별추이
A1: 월별 추이 (예산 · 실적 · 전년실적)
A2: 대시보드 원천 데이터 · 기준월 이후 실적은 빈칸
A3: ="기준: "&설정!$C$6&"년 · 단위: "&설정!$C$11
A5: 부서코드 | B5: 부서명 | C5: 구분 | D5: 1 | E5: 2 | F5: 3 | G5: 4 | H5: 5 | I5: 6 | J5: 7 | K5: 8 | L5: 9 | M5: 10 | N5: 11 | O5: 12 | P5: 합계
A6: 전체 | B6: 전사 | C6: 예산 | D6: =SUMIFS(예산_원본!$G$5:$G$3004,예산_원본!$B$5:$B$3004,설정!$C$8,예산_원본!$U$5:$U$3004,설정!$C$6)*설정!$C$14 | E6: =SUMIFS(예산_원본!$H$5:$H$3004,예산_원본!$B$5:$B$3004,설정!$C$8,예산_원본!$U$5:$U$3004,설정!$C$6)*설정!$C$14 | F6: =SUMIFS(예산_원본!$I$5:$I$3004,예산_원본!$B$5:$B$3004,설정!$C$8,예산_원본!$U$5:$U$3004,설정!$C$6)*설정!$C$14 | G6: =SUMIFS(예산_원본!$J$5:$J$3004,예산_원본!$B$5:$B$3004,설정!$C$8,예산_원본!$U$5:$U$3004,설정!$C$6)*설정!$C$14 | H6: =SUMIFS(예산_원본!$K$5:$K$3004,예산_원본!$B$5:$B$3004,설정!$C$8,예산_원본!$U$5:$U$3004,설정!$C$6)*설정!$C$14 | I6: =SUMIFS(예산_원본!$L$5:$L$3004,예산_원본!$B$5:$B$3004,설정!$C$8,예산_원본!$U$5:$U$3004,설정!$C$6)*설정!$C$14 | J6: =SUMIFS(예산_원본!$M$5:$M$3004,예산_원본!$B$5:$B$3004,설정!$C$8,예산_원본!$U$5:$U$3004,설정!$C$6)*설정!$C$14 | K6: =SUMIFS(예산_원본!$N$5:$N$3004,예산_원본!$B$5:$B$3004,설정!$C$8,예산_원본!$U$5:$U$3004,설정!$C$6)*설정!$C$14 | L6: =SUMIFS(예산_원본!$O$5:$O$3004,예산_원본!$B$5:$B$3004,설정!$C$8,예산_원본!$U$5:$U$3004,설정!$C$6)*설정!$C$14 | M6: =SUMIFS(예산_원본!$P$5:$P$3004,예산_원본!$B$5:$B$3004,설정!$C$8,예산_원본!$U$5:$U$3004,설정!$C$6)*설정!$C$14 | N6: =SUMIFS(예산_원본!$Q$5:$Q$3004,예산_원본!$B$5:$B$3004,설정!$C$8,예산_원본!$U$5:$U$3004,설정!$C$6)*설정!$C$14 | O6: =SUMIFS(예산_원본!$R$5:$R$3004,예산_원본!$B$5:$B$3004,설정!$C$8,예산_원본!$U$5:$U$3004,설정!$C$6)*설정!$C$14 | P6: =SUM(D6:O6)
A7: 전체 | B7: 전사 | C7: 실적 | D7: =IF(D$5>설정!$C$7,"",SUMIFS(실적_원본!$N$5:$N$100000,실적_원본!$L$5:$L$100000,설정!$C$6,실적_원본!$M$5:$M$100000,D$5)) | E7: =IF(E$5>설정!$C$7,"",SUMIFS(실적_원본!$N$5:$N$100000,실적_원본!$L$5:$L$100000,설정!$C$6,실적_원본!$M$5:$M$100000,E$5)) | F7: =IF(F$5>설정!$C$7,"",SUMIFS(실적_원본!$N$5:$N$100000,실적_원본!$L$5:$L$100000,설정!$C$6,실적_원본!$M$5:$M$100000,F$5)) | G7: =IF(G$5>설정!$C$7,"",SUMIFS(실적_원본!$N$5:$N$100000,실적_원본!$L$5:$L$100000,설정!$C$6,실적_원본!$M$5:$M$100000,G$5)) | H7: =IF(H$5>설정!$C$7,"",SUMIFS(실적_원본!$N$5:$N$100000,실적_원본!$L$5:$L$100000,설정!$C$6,실적_원본!$M$5:$M$100000,H$5)) | I7: =IF(I$5>설정!$C$7,"",SUMIFS(실적_원본!$N$5:$N$100000,실적_원본!$L$5:$L$100000,설정!$C$6,실적_원본!$M$5:$M$100000,I$5)) | J7: =IF(J$5>설정!$C$7,"",SUMIFS(실적_원본!$N$5:$N$100000,실적_원본!$L$5:$L$100000,설정!$C$6,실적_원본!$M$5:$M$100000,J$5)) | K7: =IF(K$5>설정!$C$7,"",SUMIFS(실적_원본!$N$5:$N$100000,실적_원본!$L$5:$L$100000,설정!$C$6,실적_원본!$M$5:$M$100000,K$5)) | ... O7: =IF(O$5>설정!$C$7,"",SUMIFS(실적_원본!$N$5:$N$100000,실적_원본!$L$5:$L$100000,설정!$C$6,실적_원본!$M$5:$M$100000,O$5)) | P7: =SUM(D7:O7)
A8: 전체 | B8: 전사 | C8: 전년실적 | D8: =SUMIFS(실적_원본!$N$5:$N$100000,실적_원본!$L$5:$L$100000,설정!$C$6-1,실적_원본!$M$5:$M$100000,D$5) | E8: =SUMIFS(실적_원본!$N$5:$N$100000,실적_원본!$L$5:$L$100000,설정!$C$6-1,실적_원본!$M$5:$M$100000,E$5) | F8: =SUMIFS(실적_원본!$N$5:$N$100000,실적_원본!$L$5:$L$100000,설정!$C$6-1,실적_원본!$M$5:$M$100000,F$5) | G8: =SUMIFS(실적_원본!$N$5:$N$100000,실적_원본!$L$5:$L$100000,설정!$C$6-1,실적_원본!$M$5:$M$100000,G$5) | H8: =SUMIFS(실적_원본!$N$5:$N$100000,실적_원본!$L$5:$L$100000,설정!$C$6-1,실적_원본!$M$5:$M$100000,H$5) | I8: =SUMIFS(실적_원본!$N$5:$N$100000,실적_원본!$L$5:$L$100000,설정!$C$6-1,실적_원본!$M$5:$M$100000,I$5) | J8: =SUMIFS(실적_원본!$N$5:$N$100000,실적_원본!$L$5:$L$100000,설정!$C$6-1,실적_원본!$M$5:$M$100000,J$5) | K8: =SUMIFS(실적_원본!$N$5:$N$100000,실적_원본!$L$5:$L$100000,설정!$C$6-1,실적_원본!$M$5:$M$100000,K$5) | ... O8: =SUMIFS(실적_원본!$N$5:$N$100000,실적_원본!$L$5:$L$100000,설정!$C$6-1,실적_원본!$M$5:$M$100000,O$5) | P8: =SUM(D8:O8)
A9: D100 | B9: =IFERROR(INDEX(부서매핑!$D$5:$D$504,MATCH($A9,부서매핑!$C$5:$C$504,0)),"") | C9: 예산 | D9: =SUMIFS(예산_원본!$G$5:$G$3004,예산_원본!$B$5:$B$3004,설정!$C$8,예산_원본!$U$5:$U$3004,설정!$C$6,예산_원본!$C$5:$C$3004,$A9)*설정!$C$14 | E9: =SUMIFS(예산_원본!$H$5:$H$3004,예산_원본!$B$5:$B$3004,설정!$C$8,예산_원본!$U$5:$U$3004,설정!$C$6,예산_원본!$C$5:$C$3004,$A9)*설정!$C$14 | F9: =SUMIFS(예산_원본!$I$5:$I$3004,예산_원본!$B$5:$B$3004,설정!$C$8,예산_원본!$U$5:$U$3004,설정!$C$6,예산_원본!$C$5:$C$3004,$A9)*설정!$C$14 | G9: =SUMIFS(예산_원본!$J$5:$J$3004,예산_원본!$B$5:$B$3004,설정!$C$8,예산_원본!$U$5:$U$3004,설정!$C$6,예산_원본!$C$5:$C$3004,$A9)*설정!$C$14 | H9: =SUMIFS(예산_원본!$K$5:$K$3004,예산_원본!$B$5:$B$3004,설정!$C$8,예산_원본!$U$5:$U$3004,설정!$C$6,예산_원본!$C$5:$C$3004,$A9)*설정!$C$14 | I9: =SUMIFS(예산_원본!$L$5:$L$3004,예산_원본!$B$5:$B$3004,설정!$C$8,예산_원본!$U$5:$U$3004,설정!$C$6,예산_원본!$C$5:$C$3004,$A9)*설정!$C$14 | J9: =SUMIFS(예산_원본!$M$5:$M$3004,예산_원본!$B$5:$B$3004,설정!$C$8,예산_원본!$U$5:$U$3004,설정!$C$6,예산_원본!$C$5:$C$3004,$A9)*설정!$C$14 | K9: =SUMIFS(예산_원본!$N$5:$N$3004,예산_원본!$B$5:$B$3004,설정!$C$8,예산_원본!$U$5:$U$3004,설정!$C$6,예산_원본!$C$5:$C$3004,$A9)*설정!$C$14 | L9: =SUMIFS(예산_원본!$O$5:$O$3004,예산_원본!$B$5:$B$3004,설정!$C$8,예산_원본!$U$5:$U$3004,설정!$C$6,예산_원본!$C$5:$C$3004,$A9)*설정!$C$14 | M9: =SUMIFS(예산_원본!$P$5:$P$3004,예산_원본!$B$5:$B$3004,설정!$C$8,예산_원본!$U$5:$U$3004,설정!$C$6,예산_원본!$C$5:$C$3004,$A9)*설정!$C$14 | N9: =SUMIFS(예산_원본!$Q$5:$Q$3004,예산_원본!$B$5:$B$3004,설정!$C$8,예산_원본!$U$5:$U$3004,설정!$C$6,예산_원본!$C$5:$C$3004,$A9)*설정!$C$14 | O9: =SUMIFS(예산_원본!$R$5:$R$3004,예산_원본!$B$5:$B$3004,설정!$C$8,예산_원본!$U$5:$U$3004,설정!$C$6,예산_원본!$C$5:$C$3004,$A9)*설정!$C$14 | P9: =SUM(D9:O9)
A10: D100 | B10: =IFERROR(INDEX(부서매핑!$D$5:$D$504,MATCH($A10,부서매핑!$C$5:$C$504,0)),"") | C10: 실적 | D10: =IF(D$5>설정!$C$7,"",SUMIFS(실적_원본!$N$5:$N$100000,실적_원본!$L$5:$L$100000,설정!$C$6,실적_원본!$M$5:$M$100000,D$5,실적_원본!$J$5:$J$100000,$A10)) | E10: =IF(E$5>설정!$C$7,"",SUMIFS(실적_원본!$N$5:$N$100000,실적_원본!$L$5:$L$100000,설정!$C$6,실적_원본!$M$5:$M$100000,E$5,실적_원본!$J$5:$J$100000,$A10)) | F10: =IF(F$5>설정!$C$7,"",SUMIFS(실적_원본!$N$5:$N$100000,실적_원본!$L$5:$L$100000,설정!$C$6,실적_원본!$M$5:$M$100000,F$5,실적_원본!$J$5:$J$100000,$A10)) | G10: =IF(G$5>설정!$C$7,"",SUMIFS(실적_원본!$N$5:$N$100000,실적_원본!$L$5:$L$100000,설정!$C$6,실적_원본!$M$5:$M$100000,G$5,실적_원본!$J$5:$J$100000,$A10)) | H10: =IF(H$5>설정!$C$7,"",SUMIFS(실적_원본!$N$5:$N$100000,실적_원본!$L$5:$L$100000,설정!$C$6,실적_원본!$M$5:$M$100000,H$5,실적_원본!$J$5:$J$100000,$A10)) | I10: =IF(I$5>설정!$C$7,"",SUMIFS(실적_원본!$N$5:$N$100000,실적_원본!$L$5:$L$100000,설정!$C$6,실적_원본!$M$5:$M$100000,I$5,실적_원본!$J$5:$J$100000,$A10)) | J10: =IF(J$5>설정!$C$7,"",SUMIFS(실적_원본!$N$5:$N$100000,실적_원본!$L$5:$L$100000,설정!$C$6,실적_원본!$M$5:$M$100000,J$5,실적_원본!$J$5:$J$100000,$A10)) | K10: =IF(K$5>설정!$C$7,"",SUMIFS(실적_원본!$N$5:$N$100000,실적_원본!$L$5:$L$100000,설정!$C$6,실적_원본!$M$5:$M$100000,K$5,실적_원본!$J$5:$J$100000,$A10)) | ... O10: =IF(O$5>설정!$C$7,"",SUMIFS(실적_원본!$N$5:$N$100000,실적_원본!$L$5:$L$100000,설정!$C$6,실적_원본!$M$5:$M$100000,O$5,실적_원본!$J$5:$J$100000,$A10)) | P10: =SUM(D10:O10)
A11: D100 | B11: =IFERROR(INDEX(부서매핑!$D$5:$D$504,MATCH($A11,부서매핑!$C$5:$C$504,0)),"") | C11: 전년실적 | D11: =SUMIFS(실적_원본!$N$5:$N$100000,실적_원본!$L$5:$L$100000,설정!$C$6-1,실적_원본!$M$5:$M$100000,D$5,실적_원본!$J$5:$J$100000,$A11) | E11: =SUMIFS(실적_원본!$N$5:$N$100000,실적_원본!$L$5:$L$100000,설정!$C$6-1,실적_원본!$M$5:$M$100000,E$5,실적_원본!$J$5:$J$100000,$A11) | F11: =SUMIFS(실적_원본!$N$5:$N$100000,실적_원본!$L$5:$L$100000,설정!$C$6-1,실적_원본!$M$5:$M$100000,F$5,실적_원본!$J$5:$J$100000,$A11) | G11: =SUMIFS(실적_원본!$N$5:$N$100000,실적_원본!$L$5:$L$100000,설정!$C$6-1,실적_원본!$M$5:$M$100000,G$5,실적_원본!$J$5:$J$100000,$A11) | H11: =SUMIFS(실적_원본!$N$5:$N$100000,실적_원본!$L$5:$L$100000,설정!$C$6-1,실적_원본!$M$5:$M$100000,H$5,실적_원본!$J$5:$J$100000,$A11) | I11: =SUMIFS(실적_원본!$N$5:$N$100000,실적_원본!$L$5:$L$100000,설정!$C$6-1,실적_원본!$M$5:$M$100000,I$5,실적_원본!$J$5:$J$100000,$A11) | J11: =SUMIFS(실적_원본!$N$5:$N$100000,실적_원본!$L$5:$L$100000,설정!$C$6-1,실적_원본!$M$5:$M$100000,J$5,실적_원본!$J$5:$J$100000,$A11) | K11: =SUMIFS(실적_원본!$N$5:$N$100000,실적_원본!$L$5:$L$100000,설정!$C$6-1,실적_원본!$M$5:$M$100000,K$5,실적_원본!$J$5:$J$100000,$A11) | ... O11: =SUMIFS(실적_원본!$N$5:$N$100000,실적_원본!$L$5:$L$100000,설정!$C$6-1,실적_원본!$M$5:$M$100000,O$5,실적_원본!$J$5:$J$100000,$A11) | P11: =SUM(D11:O11)
A12: D200 | B12: =IFERROR(INDEX(부서매핑!$D$5:$D$504,MATCH($A12,부서매핑!$C$5:$C$504,0)),"") | C12: 예산 | D12: =SUMIFS(예산_원본!$G$5:$G$3004,예산_원본!$B$5:$B$3004,설정!$C$8,예산_원본!$U$5:$U$3004,설정!$C$6,예산_원본!$C$5:$C$3004,$A12)*설정!$C$14 | E12: =SUMIFS(예산_원본!$H$5:$H$3004,예산_원본!$B$5:$B$3004,설정!$C$8,예산_원본!$U$5:$U$3004,설정!$C$6,예산_원본!$C$5:$C$3004,$A12)*설정!$C$14 | F12: =SUMIFS(예산_원본!$I$5:$I$3004,예산_원본!$B$5:$B$3004,설정!$C$8,예산_원본!$U$5:$U$3004,설정!$C$6,예산_원본!$C$5:$C$3004,$A12)*설정!$C$14 | G12: =SUMIFS(예산_원본!$J$5:$J$3004,예산_원본!$B$5:$B$3004,설정!$C$8,예산_원본!$U$5:$U$3004,설정!$C$6,예산_원본!$C$5:$C$3004,$A12)*설정!$C$14 | H12: =SUMIFS(예산_원본!$K$5:$K$3004,예산_원본!$B$5:$B$3004,설정!$C$8,예산_원본!$U$5:$U$3004,설정!$C$6,예산_원본!$C$5:$C$3004,$A12)*설정!$C$14 | I12: =SUMIFS(예산_원본!$L$5:$L$3004,예산_원본!$B$5:$B$3004,설정!$C$8,예산_원본!$U$5:$U$3004,설정!$C$6,예산_원본!$C$5:$C$3004,$A12)*설정!$C$14 | J12: =SUMIFS(예산_원본!$M$5:$M$3004,예산_원본!$B$5:$B$3004,설정!$C$8,예산_원본!$U$5:$U$3004,설정!$C$6,예산_원본!$C$5:$C$3004,$A12)*설정!$C$14 | K12: =SUMIFS(예산_원본!$N$5:$N$3004,예산_원본!$B$5:$B$3004,설정!$C$8,예산_원본!$U$5:$U$3004,설정!$C$6,예산_원본!$C$5:$C$3004,$A12)*설정!$C$14 | L12: =SUMIFS(예산_원본!$O$5:$O$3004,예산_원본!$B$5:$B$3004,설정!$C$8,예산_원본!$U$5:$U$3004,설정!$C$6,예산_원본!$C$5:$C$3004,$A12)*설정!$C$14 | M12: =SUMIFS(예산_원본!$P$5:$P$3004,예산_원본!$B$5:$B$3004,설정!$C$8,예산_원본!$U$5:$U$3004,설정!$C$6,예산_원본!$C$5:$C$3004,$A12)*설정!$C$14 | N12: =SUMIFS(예산_원본!$Q$5:$Q$3004,예산_원본!$B$5:$B$3004,설정!$C$8,예산_원본!$U$5:$U$3004,설정!$C$6,예산_원본!$C$5:$C$3004,$A12)*설정!$C$14 | O12: =SUMIFS(예산_원본!$R$5:$R$3004,예산_원본!$B$5:$B$3004,설정!$C$8,예산_원본!$U$5:$U$3004,설정!$C$6,예산_원본!$C$5:$C$3004,$A12)*설정!$C$14 | P12: =SUM(D12:O12)
A13: D200 | B13: =IFERROR(INDEX(부서매핑!$D$5:$D$504,MATCH($A13,부서매핑!$C$5:$C$504,0)),"") | C13: 실적 | D13: =IF(D$5>설정!$C$7,"",SUMIFS(실적_원본!$N$5:$N$100000,실적_원본!$L$5:$L$100000,설정!$C$6,실적_원본!$M$5:$M$100000,D$5,실적_원본!$J$5:$J$100000,$A13)) | E13: =IF(E$5>설정!$C$7,"",SUMIFS(실적_원본!$N$5:$N$100000,실적_원본!$L$5:$L$100000,설정!$C$6,실적_원본!$M$5:$M$100000,E$5,실적_원본!$J$5:$J$100000,$A13)) | F13: =IF(F$5>설정!$C$7,"",SUMIFS(실적_원본!$N$5:$N$100000,실적_원본!$L$5:$L$100000,설정!$C$6,실적_원본!$M$5:$M$100000,F$5,실적_원본!$J$5:$J$100000,$A13)) | G13: =IF(G$5>설정!$C$7,"",SUMIFS(실적_원본!$N$5:$N$100000,실적_원본!$L$5:$L$100000,설정!$C$6,실적_원본!$M$5:$M$100000,G$5,실적_원본!$J$5:$J$100000,$A13)) | H13: =IF(H$5>설정!$C$7,"",SUMIFS(실적_원본!$N$5:$N$100000,실적_원본!$L$5:$L$100000,설정!$C$6,실적_원본!$M$5:$M$100000,H$5,실적_원본!$J$5:$J$100000,$A13)) | I13: =IF(I$5>설정!$C$7,"",SUMIFS(실적_원본!$N$5:$N$100000,실적_원본!$L$5:$L$100000,설정!$C$6,실적_원본!$M$5:$M$100000,I$5,실적_원본!$J$5:$J$100000,$A13)) | J13: =IF(J$5>설정!$C$7,"",SUMIFS(실적_원본!$N$5:$N$100000,실적_원본!$L$5:$L$100000,설정!$C$6,실적_원본!$M$5:$M$100000,J$5,실적_원본!$J$5:$J$100000,$A13)) | K13: =IF(K$5>설정!$C$7,"",SUMIFS(실적_원본!$N$5:$N$100000,실적_원본!$L$5:$L$100000,설정!$C$6,실적_원본!$M$5:$M$100000,K$5,실적_원본!$J$5:$J$100000,$A13)) | ... O13: =IF(O$5>설정!$C$7,"",SUMIFS(실적_원본!$N$5:$N$100000,실적_원본!$L$5:$L$100000,설정!$C$6,실적_원본!$M$5:$M$100000,O$5,실적_원본!$J$5:$J$100000,$A13)) | P13: =SUM(D13:O13)
A14: D200 | B14: =IFERROR(INDEX(부서매핑!$D$5:$D$504,MATCH($A14,부서매핑!$C$5:$C$504,0)),"") | C14: 전년실적 | D14: =SUMIFS(실적_원본!$N$5:$N$100000,실적_원본!$L$5:$L$100000,설정!$C$6-1,실적_원본!$M$5:$M$100000,D$5,실적_원본!$J$5:$J$100000,$A14) | E14: =SUMIFS(실적_원본!$N$5:$N$100000,실적_원본!$L$5:$L$100000,설정!$C$6-1,실적_원본!$M$5:$M$100000,E$5,실적_원본!$J$5:$J$100000,$A14) | F14: =SUMIFS(실적_원본!$N$5:$N$100000,실적_원본!$L$5:$L$100000,설정!$C$6-1,실적_원본!$M$5:$M$100000,F$5,실적_원본!$J$5:$J$100000,$A14) | G14: =SUMIFS(실적_원본!$N$5:$N$100000,실적_원본!$L$5:$L$100000,설정!$C$6-1,실적_원본!$M$5:$M$100000,G$5,실적_원본!$J$5:$J$100000,$A14) | H14: =SUMIFS(실적_원본!$N$5:$N$100000,실적_원본!$L$5:$L$100000,설정!$C$6-1,실적_원본!$M$5:$M$100000,H$5,실적_원본!$J$5:$J$100000,$A14) | I14: =SUMIFS(실적_원본!$N$5:$N$100000,실적_원본!$L$5:$L$100000,설정!$C$6-1,실적_원본!$M$5:$M$100000,I$5,실적_원본!$J$5:$J$100000,$A14) | J14: =SUMIFS(실적_원본!$N$5:$N$100000,실적_원본!$L$5:$L$100000,설정!$C$6-1,실적_원본!$M$5:$M$100000,J$5,실적_원본!$J$5:$J$100000,$A14) | K14: =SUMIFS(실적_원본!$N$5:$N$100000,실적_원본!$L$5:$L$100000,설정!$C$6-1,실적_원본!$M$5:$M$100000,K$5,실적_원본!$J$5:$J$100000,$A14) | ... O14: =SUMIFS(실적_원본!$N$5:$N$100000,실적_원본!$L$5:$L$100000,설정!$C$6-1,실적_원본!$M$5:$M$100000,O$5,실적_원본!$J$5:$J$100000,$A14) | P14: =SUM(D14:O14)
A15: D300 | B15: =IFERROR(INDEX(부서매핑!$D$5:$D$504,MATCH($A15,부서매핑!$C$5:$C$504,0)),"") | C15: 예산 | D15: =SUMIFS(예산_원본!$G$5:$G$3004,예산_원본!$B$5:$B$3004,설정!$C$8,예산_원본!$U$5:$U$3004,설정!$C$6,예산_원본!$C$5:$C$3004,$A15)*설정!$C$14 | E15: =SUMIFS(예산_원본!$H$5:$H$3004,예산_원본!$B$5:$B$3004,설정!$C$8,예산_원본!$U$5:$U$3004,설정!$C$6,예산_원본!$C$5:$C$3004,$A15)*설정!$C$14 | F15: =SUMIFS(예산_원본!$I$5:$I$3004,예산_원본!$B$5:$B$3004,설정!$C$8,예산_원본!$U$5:$U$3004,설정!$C$6,예산_원본!$C$5:$C$3004,$A15)*설정!$C$14 | G15: =SUMIFS(예산_원본!$J$5:$J$3004,예산_원본!$B$5:$B$3004,설정!$C$8,예산_원본!$U$5:$U$3004,설정!$C$6,예산_원본!$C$5:$C$3004,$A15)*설정!$C$14 | H15: =SUMIFS(예산_원본!$K$5:$K$3004,예산_원본!$B$5:$B$3004,설정!$C$8,예산_원본!$U$5:$U$3004,설정!$C$6,예산_원본!$C$5:$C$3004,$A15)*설정!$C$14 | I15: =SUMIFS(예산_원본!$L$5:$L$3004,예산_원본!$B$5:$B$3004,설정!$C$8,예산_원본!$U$5:$U$3004,설정!$C$6,예산_원본!$C$5:$C$3004,$A15)*설정!$C$14 | J15: =SUMIFS(예산_원본!$M$5:$M$3004,예산_원본!$B$5:$B$3004,설정!$C$8,예산_원본!$U$5:$U$3004,설정!$C$6,예산_원본!$C$5:$C$3004,$A15)*설정!$C$14 | K15: =SUMIFS(예산_원본!$N$5:$N$3004,예산_원본!$B$5:$B$3004,설정!$C$8,예산_원본!$U$5:$U$3004,설정!$C$6,예산_원본!$C$5:$C$3004,$A15)*설정!$C$14 | L15: =SUMIFS(예산_원본!$O$5:$O$3004,예산_원본!$B$5:$B$3004,설정!$C$8,예산_원본!$U$5:$U$3004,설정!$C$6,예산_원본!$C$5:$C$3004,$A15)*설정!$C$14 | M15: =SUMIFS(예산_원본!$P$5:$P$3004,예산_원본!$B$5:$B$3004,설정!$C$8,예산_원본!$U$5:$U$3004,설정!$C$6,예산_원본!$C$5:$C$3004,$A15)*설정!$C$14 | N15: =SUMIFS(예산_원본!$Q$5:$Q$3004,예산_원본!$B$5:$B$3004,설정!$C$8,예산_원본!$U$5:$U$3004,설정!$C$6,예산_원본!$C$5:$C$3004,$A15)*설정!$C$14 | O15: =SUMIFS(예산_원본!$R$5:$R$3004,예산_원본!$B$5:$B$3004,설정!$C$8,예산_원본!$U$5:$U$3004,설정!$C$6,예산_원본!$C$5:$C$3004,$A15)*설정!$C$14 | P15: =SUM(D15:O15)
A16: D300 | B16: =IFERROR(INDEX(부서매핑!$D$5:$D$504,MATCH($A16,부서매핑!$C$5:$C$504,0)),"") | C16: 실적 | D16: =IF(D$5>설정!$C$7,"",SUMIFS(실적_원본!$N$5:$N$100000,실적_원본!$L$5:$L$100000,설정!$C$6,실적_원본!$M$5:$M$100000,D$5,실적_원본!$J$5:$J$100000,$A16)) | E16: =IF(E$5>설정!$C$7,"",SUMIFS(실적_원본!$N$5:$N$100000,실적_원본!$L$5:$L$100000,설정!$C$6,실적_원본!$M$5:$M$100000,E$5,실적_원본!$J$5:$J$100000,$A16)) | F16: =IF(F$5>설정!$C$7,"",SUMIFS(실적_원본!$N$5:$N$100000,실적_원본!$L$5:$L$100000,설정!$C$6,실적_원본!$M$5:$M$100000,F$5,실적_원본!$J$5:$J$100000,$A16)) | G16: =IF(G$5>설정!$C$7,"",SUMIFS(실적_원본!$N$5:$N$100000,실적_원본!$L$5:$L$100000,설정!$C$6,실적_원본!$M$5:$M$100000,G$5,실적_원본!$J$5:$J$100000,$A16)) | H16: =IF(H$5>설정!$C$7,"",SUMIFS(실적_원본!$N$5:$N$100000,실적_원본!$L$5:$L$100000,설정!$C$6,실적_원본!$M$5:$M$100000,H$5,실적_원본!$J$5:$J$100000,$A16)) | I16: =IF(I$5>설정!$C$7,"",SUMIFS(실적_원본!$N$5:$N$100000,실적_원본!$L$5:$L$100000,설정!$C$6,실적_원본!$M$5:$M$100000,I$5,실적_원본!$J$5:$J$100000,$A16)) | J16: =IF(J$5>설정!$C$7,"",SUMIFS(실적_원본!$N$5:$N$100000,실적_원본!$L$5:$L$100000,설정!$C$6,실적_원본!$M$5:$M$100000,J$5,실적_원본!$J$5:$J$100000,$A16)) | K16: =IF(K$5>설정!$C$7,"",SUMIFS(실적_원본!$N$5:$N$100000,실적_원본!$L$5:$L$100000,설정!$C$6,실적_원본!$M$5:$M$100000,K$5,실적_원본!$J$5:$J$100000,$A16)) | ... O16: =IF(O$5>설정!$C$7,"",SUMIFS(실적_원본!$N$5:$N$100000,실적_원본!$L$5:$L$100000,설정!$C$6,실적_원본!$M$5:$M$100000,O$5,실적_원본!$J$5:$J$100000,$A16)) | P16: =SUM(D16:O16)
A17: D300 | B17: =IFERROR(INDEX(부서매핑!$D$5:$D$504,MATCH($A17,부서매핑!$C$5:$C$504,0)),"") | C17: 전년실적 | D17: =SUMIFS(실적_원본!$N$5:$N$100000,실적_원본!$L$5:$L$100000,설정!$C$6-1,실적_원본!$M$5:$M$100000,D$5,실적_원본!$J$5:$J$100000,$A17) | E17: =SUMIFS(실적_원본!$N$5:$N$100000,실적_원본!$L$5:$L$100000,설정!$C$6-1,실적_원본!$M$5:$M$100000,E$5,실적_원본!$J$5:$J$100000,$A17) | F17: =SUMIFS(실적_원본!$N$5:$N$100000,실적_원본!$L$5:$L$100000,설정!$C$6-1,실적_원본!$M$5:$M$100000,F$5,실적_원본!$J$5:$J$100000,$A17) | G17: =SUMIFS(실적_원본!$N$5:$N$100000,실적_원본!$L$5:$L$100000,설정!$C$6-1,실적_원본!$M$5:$M$100000,G$5,실적_원본!$J$5:$J$100000,$A17) | H17: =SUMIFS(실적_원본!$N$5:$N$100000,실적_원본!$L$5:$L$100000,설정!$C$6-1,실적_원본!$M$5:$M$100000,H$5,실적_원본!$J$5:$J$100000,$A17) | I17: =SUMIFS(실적_원본!$N$5:$N$100000,실적_원본!$L$5:$L$100000,설정!$C$6-1,실적_원본!$M$5:$M$100000,I$5,실적_원본!$J$5:$J$100000,$A17) | J17: =SUMIFS(실적_원본!$N$5:$N$100000,실적_원본!$L$5:$L$100000,설정!$C$6-1,실적_원본!$M$5:$M$100000,J$5,실적_원본!$J$5:$J$100000,$A17) | K17: =SUMIFS(실적_원본!$N$5:$N$100000,실적_원본!$L$5:$L$100000,설정!$C$6-1,실적_원본!$M$5:$M$100000,K$5,실적_원본!$J$5:$J$100000,$A17) | ... O17: =SUMIFS(실적_원본!$N$5:$N$100000,실적_원본!$L$5:$L$100000,설정!$C$6-1,실적_원본!$M$5:$M$100000,O$5,실적_원본!$J$5:$J$100000,$A17) | P17: =SUM(D17:O17)
A18: D400 | B18: =IFERROR(INDEX(부서매핑!$D$5:$D$504,MATCH($A18,부서매핑!$C$5:$C$504,0)),"") | C18: 예산 | D18: =SUMIFS(예산_원본!$G$5:$G$3004,예산_원본!$B$5:$B$3004,설정!$C$8,예산_원본!$U$5:$U$3004,설정!$C$6,예산_원본!$C$5:$C$3004,$A18)*설정!$C$14 | E18: =SUMIFS(예산_원본!$H$5:$H$3004,예산_원본!$B$5:$B$3004,설정!$C$8,예산_원본!$U$5:$U$3004,설정!$C$6,예산_원본!$C$5:$C$3004,$A18)*설정!$C$14 | F18: =SUMIFS(예산_원본!$I$5:$I$3004,예산_원본!$B$5:$B$3004,설정!$C$8,예산_원본!$U$5:$U$3004,설정!$C$6,예산_원본!$C$5:$C$3004,$A18)*설정!$C$14 | G18: =SUMIFS(예산_원본!$J$5:$J$3004,예산_원본!$B$5:$B$3004,설정!$C$8,예산_원본!$U$5:$U$3004,설정!$C$6,예산_원본!$C$5:$C$3004,$A18)*설정!$C$14 | H18: =SUMIFS(예산_원본!$K$5:$K$3004,예산_원본!$B$5:$B$3004,설정!$C$8,예산_원본!$U$5:$U$3004,설정!$C$6,예산_원본!$C$5:$C$3004,$A18)*설정!$C$14 | I18: =SUMIFS(예산_원본!$L$5:$L$3004,예산_원본!$B$5:$B$3004,설정!$C$8,예산_원본!$U$5:$U$3004,설정!$C$6,예산_원본!$C$5:$C$3004,$A18)*설정!$C$14 | J18: =SUMIFS(예산_원본!$M$5:$M$3004,예산_원본!$B$5:$B$3004,설정!$C$8,예산_원본!$U$5:$U$3004,설정!$C$6,예산_원본!$C$5:$C$3004,$A18)*설정!$C$14 | K18: =SUMIFS(예산_원본!$N$5:$N$3004,예산_원본!$B$5:$B$3004,설정!$C$8,예산_원본!$U$5:$U$3004,설정!$C$6,예산_원본!$C$5:$C$3004,$A18)*설정!$C$14 | L18: =SUMIFS(예산_원본!$O$5:$O$3004,예산_원본!$B$5:$B$3004,설정!$C$8,예산_원본!$U$5:$U$3004,설정!$C$6,예산_원본!$C$5:$C$3004,$A18)*설정!$C$14 | M18: =SUMIFS(예산_원본!$P$5:$P$3004,예산_원본!$B$5:$B$3004,설정!$C$8,예산_원본!$U$5:$U$3004,설정!$C$6,예산_원본!$C$5:$C$3004,$A18)*설정!$C$14 | N18: =SUMIFS(예산_원본!$Q$5:$Q$3004,예산_원본!$B$5:$B$3004,설정!$C$8,예산_원본!$U$5:$U$3004,설정!$C$6,예산_원본!$C$5:$C$3004,$A18)*설정!$C$14 | O18: =SUMIFS(예산_원본!$R$5:$R$3004,예산_원본!$B$5:$B$3004,설정!$C$8,예산_원본!$U$5:$U$3004,설정!$C$6,예산_원본!$C$5:$C$3004,$A18)*설정!$C$14 | P18: =SUM(D18:O18)
A19: D400 | B19: =IFERROR(INDEX(부서매핑!$D$5:$D$504,MATCH($A19,부서매핑!$C$5:$C$504,0)),"") | C19: 실적 | D19: =IF(D$5>설정!$C$7,"",SUMIFS(실적_원본!$N$5:$N$100000,실적_원본!$L$5:$L$100000,설정!$C$6,실적_원본!$M$5:$M$100000,D$5,실적_원본!$J$5:$J$100000,$A19)) | E19: =IF(E$5>설정!$C$7,"",SUMIFS(실적_원본!$N$5:$N$100000,실적_원본!$L$5:$L$100000,설정!$C$6,실적_원본!$M$5:$M$100000,E$5,실적_원본!$J$5:$J$100000,$A19)) | F19: =IF(F$5>설정!$C$7,"",SUMIFS(실적_원본!$N$5:$N$100000,실적_원본!$L$5:$L$100000,설정!$C$6,실적_원본!$M$5:$M$100000,F$5,실적_원본!$J$5:$J$100000,$A19)) | G19: =IF(G$5>설정!$C$7,"",SUMIFS(실적_원본!$N$5:$N$100000,실적_원본!$L$5:$L$100000,설정!$C$6,실적_원본!$M$5:$M$100000,G$5,실적_원본!$J$5:$J$100000,$A19)) | H19: =IF(H$5>설정!$C$7,"",SUMIFS(실적_원본!$N$5:$N$100000,실적_원본!$L$5:$L$100000,설정!$C$6,실적_원본!$M$5:$M$100000,H$5,실적_원본!$J$5:$J$100000,$A19)) | I19: =IF(I$5>설정!$C$7,"",SUMIFS(실적_원본!$N$5:$N$100000,실적_원본!$L$5:$L$100000,설정!$C$6,실적_원본!$M$5:$M$100000,I$5,실적_원본!$J$5:$J$100000,$A19)) | J19: =IF(J$5>설정!$C$7,"",SUMIFS(실적_원본!$N$5:$N$100000,실적_원본!$L$5:$L$100000,설정!$C$6,실적_원본!$M$5:$M$100000,J$5,실적_원본!$J$5:$J$100000,$A19)) | K19: =IF(K$5>설정!$C$7,"",SUMIFS(실적_원본!$N$5:$N$100000,실적_원본!$L$5:$L$100000,설정!$C$6,실적_원본!$M$5:$M$100000,K$5,실적_원본!$J$5:$J$100000,$A19)) | ... O19: =IF(O$5>설정!$C$7,"",SUMIFS(실적_원본!$N$5:$N$100000,실적_원본!$L$5:$L$100000,설정!$C$6,실적_원본!$M$5:$M$100000,O$5,실적_원본!$J$5:$J$100000,$A19)) | P19: =SUM(D19:O19)
A20: D400 | B20: =IFERROR(INDEX(부서매핑!$D$5:$D$504,MATCH($A20,부서매핑!$C$5:$C$504,0)),"") | C20: 전년실적 | D20: =SUMIFS(실적_원본!$N$5:$N$100000,실적_원본!$L$5:$L$100000,설정!$C$6-1,실적_원본!$M$5:$M$100000,D$5,실적_원본!$J$5:$J$100000,$A20) | E20: =SUMIFS(실적_원본!$N$5:$N$100000,실적_원본!$L$5:$L$100000,설정!$C$6-1,실적_원본!$M$5:$M$100000,E$5,실적_원본!$J$5:$J$100000,$A20) | F20: =SUMIFS(실적_원본!$N$5:$N$100000,실적_원본!$L$5:$L$100000,설정!$C$6-1,실적_원본!$M$5:$M$100000,F$5,실적_원본!$J$5:$J$100000,$A20) | G20: =SUMIFS(실적_원본!$N$5:$N$100000,실적_원본!$L$5:$L$100000,설정!$C$6-1,실적_원본!$M$5:$M$100000,G$5,실적_원본!$J$5:$J$100000,$A20) | H20: =SUMIFS(실적_원본!$N$5:$N$100000,실적_원본!$L$5:$L$100000,설정!$C$6-1,실적_원본!$M$5:$M$100000,H$5,실적_원본!$J$5:$J$100000,$A20) | I20: =SUMIFS(실적_원본!$N$5:$N$100000,실적_원본!$L$5:$L$100000,설정!$C$6-1,실적_원본!$M$5:$M$100000,I$5,실적_원본!$J$5:$J$100000,$A20) | J20: =SUMIFS(실적_원본!$N$5:$N$100000,실적_원본!$L$5:$L$100000,설정!$C$6-1,실적_원본!$M$5:$M$100000,J$5,실적_원본!$J$5:$J$100000,$A20) | K20: =SUMIFS(실적_원본!$N$5:$N$100000,실적_원본!$L$5:$L$100000,설정!$C$6-1,실적_원본!$M$5:$M$100000,K$5,실적_원본!$J$5:$J$100000,$A20) | ... O20: =SUMIFS(실적_원본!$N$5:$N$100000,실적_원본!$L$5:$L$100000,설정!$C$6-1,실적_원본!$M$5:$M$100000,O$5,실적_원본!$J$5:$J$100000,$A20) | P20: =SUM(D20:O20)
A21: D500 | B21: =IFERROR(INDEX(부서매핑!$D$5:$D$504,MATCH($A21,부서매핑!$C$5:$C$504,0)),"") | C21: 예산 | D21: =SUMIFS(예산_원본!$G$5:$G$3004,예산_원본!$B$5:$B$3004,설정!$C$8,예산_원본!$U$5:$U$3004,설정!$C$6,예산_원본!$C$5:$C$3004,$A21)*설정!$C$14 | E21: =SUMIFS(예산_원본!$H$5:$H$3004,예산_원본!$B$5:$B$3004,설정!$C$8,예산_원본!$U$5:$U$3004,설정!$C$6,예산_원본!$C$5:$C$3004,$A21)*설정!$C$14 | F21: =SUMIFS(예산_원본!$I$5:$I$3004,예산_원본!$B$5:$B$3004,설정!$C$8,예산_원본!$U$5:$U$3004,설정!$C$6,예산_원본!$C$5:$C$3004,$A21)*설정!$C$14 | G21: =SUMIFS(예산_원본!$J$5:$J$3004,예산_원본!$B$5:$B$3004,설정!$C$8,예산_원본!$U$5:$U$3004,설정!$C$6,예산_원본!$C$5:$C$3004,$A21)*설정!$C$14 | H21: =SUMIFS(예산_원본!$K$5:$K$3004,예산_원본!$B$5:$B$3004,설정!$C$8,예산_원본!$U$5:$U$3004,설정!$C$6,예산_원본!$C$5:$C$3004,$A21)*설정!$C$14 | I21: =SUMIFS(예산_원본!$L$5:$L$3004,예산_원본!$B$5:$B$3004,설정!$C$8,예산_원본!$U$5:$U$3004,설정!$C$6,예산_원본!$C$5:$C$3004,$A21)*설정!$C$14 | J21: =SUMIFS(예산_원본!$M$5:$M$3004,예산_원본!$B$5:$B$3004,설정!$C$8,예산_원본!$U$5:$U$3004,설정!$C$6,예산_원본!$C$5:$C$3004,$A21)*설정!$C$14 | K21: =SUMIFS(예산_원본!$N$5:$N$3004,예산_원본!$B$5:$B$3004,설정!$C$8,예산_원본!$U$5:$U$3004,설정!$C$6,예산_원본!$C$5:$C$3004,$A21)*설정!$C$14 | L21: =SUMIFS(예산_원본!$O$5:$O$3004,예산_원본!$B$5:$B$3004,설정!$C$8,예산_원본!$U$5:$U$3004,설정!$C$6,예산_원본!$C$5:$C$3004,$A21)*설정!$C$14 | M21: =SUMIFS(예산_원본!$P$5:$P$3004,예산_원본!$B$5:$B$3004,설정!$C$8,예산_원본!$U$5:$U$3004,설정!$C$6,예산_원본!$C$5:$C$3004,$A21)*설정!$C$14 | N21: =SUMIFS(예산_원본!$Q$5:$Q$3004,예산_원본!$B$5:$B$3004,설정!$C$8,예산_원본!$U$5:$U$3004,설정!$C$6,예산_원본!$C$5:$C$3004,$A21)*설정!$C$14 | O21: =SUMIFS(예산_원본!$R$5:$R$3004,예산_원본!$B$5:$B$3004,설정!$C$8,예산_원본!$U$5:$U$3004,설정!$C$6,예산_원본!$C$5:$C$3004,$A21)*설정!$C$14 | P21: =SUM(D21:O21)
A22: D500 | B22: =IFERROR(INDEX(부서매핑!$D$5:$D$504,MATCH($A22,부서매핑!$C$5:$C$504,0)),"") | C22: 실적 | D22: =IF(D$5>설정!$C$7,"",SUMIFS(실적_원본!$N$5:$N$100000,실적_원본!$L$5:$L$100000,설정!$C$6,실적_원본!$M$5:$M$100000,D$5,실적_원본!$J$5:$J$100000,$A22)) | E22: =IF(E$5>설정!$C$7,"",SUMIFS(실적_원본!$N$5:$N$100000,실적_원본!$L$5:$L$100000,설정!$C$6,실적_원본!$M$5:$M$100000,E$5,실적_원본!$J$5:$J$100000,$A22)) | F22: =IF(F$5>설정!$C$7,"",SUMIFS(실적_원본!$N$5:$N$100000,실적_원본!$L$5:$L$100000,설정!$C$6,실적_원본!$M$5:$M$100000,F$5,실적_원본!$J$5:$J$100000,$A22)) | G22: =IF(G$5>설정!$C$7,"",SUMIFS(실적_원본!$N$5:$N$100000,실적_원본!$L$5:$L$100000,설정!$C$6,실적_원본!$M$5:$M$100000,G$5,실적_원본!$J$5:$J$100000,$A22)) | H22: =IF(H$5>설정!$C$7,"",SUMIFS(실적_원본!$N$5:$N$100000,실적_원본!$L$5:$L$100000,설정!$C$6,실적_원본!$M$5:$M$100000,H$5,실적_원본!$J$5:$J$100000,$A22)) | I22: =IF(I$5>설정!$C$7,"",SUMIFS(실적_원본!$N$5:$N$100000,실적_원본!$L$5:$L$100000,설정!$C$6,실적_원본!$M$5:$M$100000,I$5,실적_원본!$J$5:$J$100000,$A22)) | J22: =IF(J$5>설정!$C$7,"",SUMIFS(실적_원본!$N$5:$N$100000,실적_원본!$L$5:$L$100000,설정!$C$6,실적_원본!$M$5:$M$100000,J$5,실적_원본!$J$5:$J$100000,$A22)) | K22: =IF(K$5>설정!$C$7,"",SUMIFS(실적_원본!$N$5:$N$100000,실적_원본!$L$5:$L$100000,설정!$C$6,실적_원본!$M$5:$M$100000,K$5,실적_원본!$J$5:$J$100000,$A22)) | ... O22: =IF(O$5>설정!$C$7,"",SUMIFS(실적_원본!$N$5:$N$100000,실적_원본!$L$5:$L$100000,설정!$C$6,실적_원본!$M$5:$M$100000,O$5,실적_원본!$J$5:$J$100000,$A22)) | P22: =SUM(D22:O22)
A23: D500 | B23: =IFERROR(INDEX(부서매핑!$D$5:$D$504,MATCH($A23,부서매핑!$C$5:$C$504,0)),"") | C23: 전년실적 | D23: =SUMIFS(실적_원본!$N$5:$N$100000,실적_원본!$L$5:$L$100000,설정!$C$6-1,실적_원본!$M$5:$M$100000,D$5,실적_원본!$J$5:$J$100000,$A23) | E23: =SUMIFS(실적_원본!$N$5:$N$100000,실적_원본!$L$5:$L$100000,설정!$C$6-1,실적_원본!$M$5:$M$100000,E$5,실적_원본!$J$5:$J$100000,$A23) | F23: =SUMIFS(실적_원본!$N$5:$N$100000,실적_원본!$L$5:$L$100000,설정!$C$6-1,실적_원본!$M$5:$M$100000,F$5,실적_원본!$J$5:$J$100000,$A23) | G23: =SUMIFS(실적_원본!$N$5:$N$100000,실적_원본!$L$5:$L$100000,설정!$C$6-1,실적_원본!$M$5:$M$100000,G$5,실적_원본!$J$5:$J$100000,$A23) | H23: =SUMIFS(실적_원본!$N$5:$N$100000,실적_원본!$L$5:$L$100000,설정!$C$6-1,실적_원본!$M$5:$M$100000,H$5,실적_원본!$J$5:$J$100000,$A23) | I23: =SUMIFS(실적_원본!$N$5:$N$100000,실적_원본!$L$5:$L$100000,설정!$C$6-1,실적_원본!$M$5:$M$100000,I$5,실적_원본!$J$5:$J$100000,$A23) | J23: =SUMIFS(실적_원본!$N$5:$N$100000,실적_원본!$L$5:$L$100000,설정!$C$6-1,실적_원본!$M$5:$M$100000,J$5,실적_원본!$J$5:$J$100000,$A23) | K23: =SUMIFS(실적_원본!$N$5:$N$100000,실적_원본!$L$5:$L$100000,설정!$C$6-1,실적_원본!$M$5:$M$100000,K$5,실적_원본!$J$5:$J$100000,$A23) | ... O23: =SUMIFS(실적_원본!$N$5:$N$100000,실적_원본!$L$5:$L$100000,설정!$C$6-1,실적_원본!$M$5:$M$100000,O$5,실적_원본!$J$5:$J$100000,$A23) | P23: =SUM(D23:O23)
A24: D600 | B24: =IFERROR(INDEX(부서매핑!$D$5:$D$504,MATCH($A24,부서매핑!$C$5:$C$504,0)),"") | C24: 예산 | D24: =SUMIFS(예산_원본!$G$5:$G$3004,예산_원본!$B$5:$B$3004,설정!$C$8,예산_원본!$U$5:$U$3004,설정!$C$6,예산_원본!$C$5:$C$3004,$A24)*설정!$C$14 | E24: =SUMIFS(예산_원본!$H$5:$H$3004,예산_원본!$B$5:$B$3004,설정!$C$8,예산_원본!$U$5:$U$3004,설정!$C$6,예산_원본!$C$5:$C$3004,$A24)*설정!$C$14 | F24: =SUMIFS(예산_원본!$I$5:$I$3004,예산_원본!$B$5:$B$3004,설정!$C$8,예산_원본!$U$5:$U$3004,설정!$C$6,예산_원본!$C$5:$C$3004,$A24)*설정!$C$14 | G24: =SUMIFS(예산_원본!$J$5:$J$3004,예산_원본!$B$5:$B$3004,설정!$C$8,예산_원본!$U$5:$U$3004,설정!$C$6,예산_원본!$C$5:$C$3004,$A24)*설정!$C$14 | H24: =SUMIFS(예산_원본!$K$5:$K$3004,예산_원본!$B$5:$B$3004,설정!$C$8,예산_원본!$U$5:$U$3004,설정!$C$6,예산_원본!$C$5:$C$3004,$A24)*설정!$C$14 | I24: =SUMIFS(예산_원본!$L$5:$L$3004,예산_원본!$B$5:$B$3004,설정!$C$8,예산_원본!$U$5:$U$3004,설정!$C$6,예산_원본!$C$5:$C$3004,$A24)*설정!$C$14 | J24: =SUMIFS(예산_원본!$M$5:$M$3004,예산_원본!$B$5:$B$3004,설정!$C$8,예산_원본!$U$5:$U$3004,설정!$C$6,예산_원본!$C$5:$C$3004,$A24)*설정!$C$14 | K24: =SUMIFS(예산_원본!$N$5:$N$3004,예산_원본!$B$5:$B$3004,설정!$C$8,예산_원본!$U$5:$U$3004,설정!$C$6,예산_원본!$C$5:$C$3004,$A24)*설정!$C$14 | L24: =SUMIFS(예산_원본!$O$5:$O$3004,예산_원본!$B$5:$B$3004,설정!$C$8,예산_원본!$U$5:$U$3004,설정!$C$6,예산_원본!$C$5:$C$3004,$A24)*설정!$C$14 | M24: =SUMIFS(예산_원본!$P$5:$P$3004,예산_원본!$B$5:$B$3004,설정!$C$8,예산_원본!$U$5:$U$3004,설정!$C$6,예산_원본!$C$5:$C$3004,$A24)*설정!$C$14 | N24: =SUMIFS(예산_원본!$Q$5:$Q$3004,예산_원본!$B$5:$B$3004,설정!$C$8,예산_원본!$U$5:$U$3004,설정!$C$6,예산_원본!$C$5:$C$3004,$A24)*설정!$C$14 | O24: =SUMIFS(예산_원본!$R$5:$R$3004,예산_원본!$B$5:$B$3004,설정!$C$8,예산_원본!$U$5:$U$3004,설정!$C$6,예산_원본!$C$5:$C$3004,$A24)*설정!$C$14 | P24: =SUM(D24:O24)
A25: D600 | B25: =IFERROR(INDEX(부서매핑!$D$5:$D$504,MATCH($A25,부서매핑!$C$5:$C$504,0)),"") | C25: 실적 | D25: =IF(D$5>설정!$C$7,"",SUMIFS(실적_원본!$N$5:$N$100000,실적_원본!$L$5:$L$100000,설정!$C$6,실적_원본!$M$5:$M$100000,D$5,실적_원본!$J$5:$J$100000,$A25)) | E25: =IF(E$5>설정!$C$7,"",SUMIFS(실적_원본!$N$5:$N$100000,실적_원본!$L$5:$L$100000,설정!$C$6,실적_원본!$M$5:$M$100000,E$5,실적_원본!$J$5:$J$100000,$A25)) | F25: =IF(F$5>설정!$C$7,"",SUMIFS(실적_원본!$N$5:$N$100000,실적_원본!$L$5:$L$100000,설정!$C$6,실적_원본!$M$5:$M$100000,F$5,실적_원본!$J$5:$J$100000,$A25)) | G25: =IF(G$5>설정!$C$7,"",SUMIFS(실적_원본!$N$5:$N$100000,실적_원본!$L$5:$L$100000,설정!$C$6,실적_원본!$M$5:$M$100000,G$5,실적_원본!$J$5:$J$100000,$A25)) | H25: =IF(H$5>설정!$C$7,"",SUMIFS(실적_원본!$N$5:$N$100000,실적_원본!$L$5:$L$100000,설정!$C$6,실적_원본!$M$5:$M$100000,H$5,실적_원본!$J$5:$J$100000,$A25)) | I25: =IF(I$5>설정!$C$7,"",SUMIFS(실적_원본!$N$5:$N$100000,실적_원본!$L$5:$L$100000,설정!$C$6,실적_원본!$M$5:$M$100000,I$5,실적_원본!$J$5:$J$100000,$A25)) | J25: =IF(J$5>설정!$C$7,"",SUMIFS(실적_원본!$N$5:$N$100000,실적_원본!$L$5:$L$100000,설정!$C$6,실적_원본!$M$5:$M$100000,J$5,실적_원본!$J$5:$J$100000,$A25)) | K25: =IF(K$5>설정!$C$7,"",SUMIFS(실적_원본!$N$5:$N$100000,실적_원본!$L$5:$L$100000,설정!$C$6,실적_원본!$M$5:$M$100000,K$5,실적_원본!$J$5:$J$100000,$A25)) | ... O25: =IF(O$5>설정!$C$7,"",SUMIFS(실적_원본!$N$5:$N$100000,실적_원본!$L$5:$L$100000,설정!$C$6,실적_원본!$M$5:$M$100000,O$5,실적_원본!$J$5:$J$100000,$A25)) | P25: =SUM(D25:O25)
A26: D600 | B26: =IFERROR(INDEX(부서매핑!$D$5:$D$504,MATCH($A26,부서매핑!$C$5:$C$504,0)),"") | C26: 전년실적 | D26: =SUMIFS(실적_원본!$N$5:$N$100000,실적_원본!$L$5:$L$100000,설정!$C$6-1,실적_원본!$M$5:$M$100000,D$5,실적_원본!$J$5:$J$100000,$A26) | E26: =SUMIFS(실적_원본!$N$5:$N$100000,실적_원본!$L$5:$L$100000,설정!$C$6-1,실적_원본!$M$5:$M$100000,E$5,실적_원본!$J$5:$J$100000,$A26) | F26: =SUMIFS(실적_원본!$N$5:$N$100000,실적_원본!$L$5:$L$100000,설정!$C$6-1,실적_원본!$M$5:$M$100000,F$5,실적_원본!$J$5:$J$100000,$A26) | G26: =SUMIFS(실적_원본!$N$5:$N$100000,실적_원본!$L$5:$L$100000,설정!$C$6-1,실적_원본!$M$5:$M$100000,G$5,실적_원본!$J$5:$J$100000,$A26) | H26: =SUMIFS(실적_원본!$N$5:$N$100000,실적_원본!$L$5:$L$100000,설정!$C$6-1,실적_원본!$M$5:$M$100000,H$5,실적_원본!$J$5:$J$100000,$A26) | I26: =SUMIFS(실적_원본!$N$5:$N$100000,실적_원본!$L$5:$L$100000,설정!$C$6-1,실적_원본!$M$5:$M$100000,I$5,실적_원본!$J$5:$J$100000,$A26) | J26: =SUMIFS(실적_원본!$N$5:$N$100000,실적_원본!$L$5:$L$100000,설정!$C$6-1,실적_원본!$M$5:$M$100000,J$5,실적_원본!$J$5:$J$100000,$A26) | K26: =SUMIFS(실적_원본!$N$5:$N$100000,실적_원본!$L$5:$L$100000,설정!$C$6-1,실적_원본!$M$5:$M$100000,K$5,실적_원본!$J$5:$J$100000,$A26) | ... O26: =SUMIFS(실적_원본!$N$5:$N$100000,실적_원본!$L$5:$L$100000,설정!$C$6-1,실적_원본!$M$5:$M$100000,O$5,실적_원본!$J$5:$J$100000,$A26) | P26: =SUM(D26:O26)
